<<<<<<< HEAD
[2018-10-13 22:57:33,242] [INFO] "GET /api/jingqulist HTTP/1.1" 200 3058
[2018-10-13 22:58:04,643] [INFO] "GET /api/jingqulist HTTP/1.1" 200 3058
[2018-10-14 17:19:50,513] [INFO] "GET /api/jingqulist HTTP/1.1" 200 3324
[2018-10-14 17:28:38,097] [INFO] "GET /api/jingdianlist/1 HTTP/1.1" 200 3883
[2018-10-14 17:33:11,584] [INFO] "GET /api/jingqucount/1 HTTP/1.1" 200 72
[2018-10-14 17:33:54,285] [INFO] "GET /api/jingqucount/1 HTTP/1.1" 200 76
[2018-10-14 17:33:59,910] [INFO] "GET /api/jingqucount/2 HTTP/1.1" 200 77
[2018-10-14 17:34:21,414] [INFO] "GET /api/jingqucount/18 HTTP/1.1" 200 75
[2018-10-14 17:34:29,214] [INFO] "GET /api/jingqucount/17 HTTP/1.1" 200 76
[2018-10-14 17:34:35,536] [INFO] "GET /api/jingqucount/11 HTTP/1.1" 200 76
[2018-10-14 18:19:55,587] [ERROR] Internal Server Error: /api/jingqudetail/1
Traceback (most recent call last):
  File "E:\Anaconda\envs\en1\lib\site-packages\django\core\handlers\exception.py", line 35, in inner
    response = get_response(request)
  File "E:\Anaconda\envs\en1\lib\site-packages\django\core\handlers\base.py", line 128, in _get_response
    response = self.process_exception_by_middleware(e, request)
  File "E:\Anaconda\envs\en1\lib\site-packages\django\core\handlers\base.py", line 126, in _get_response
    response = wrapped_callback(request, *callback_args, **callback_kwargs)
  File "E:\Anaconda\envs\en1\lib\site-packages\django\views\decorators\csrf.py", line 54, in wrapped_view
    return view_func(*args, **kwargs)
  File "E:\Anaconda\envs\en1\lib\site-packages\django\views\generic\base.py", line 69, in view
    return self.dispatch(request, *args, **kwargs)
  File "E:\Anaconda\envs\en1\lib\site-packages\rest_framework\views.py", line 483, in dispatch
    response = self.handle_exception(exc)
  File "E:\Anaconda\envs\en1\lib\site-packages\rest_framework\views.py", line 443, in handle_exception
    self.raise_uncaught_exception(exc)
  File "E:\Anaconda\envs\en1\lib\site-packages\rest_framework\views.py", line 480, in dispatch
    response = handler(request, *args, **kwargs)
  File "D:\资料\GitHub\TourCommentApiPro\TourCommentApi\TourCommentApi\Views\jingquDetailView.py", line 60, in get
    return get_jingqu_detail(request,id);
  File "D:\资料\GitHub\TourCommentApiPro\TourCommentApi\TourCommentApi\Views\jingquDetailView.py", line 19, in get_jingqu_detail
    this_year_comments = comment.objects(data_region__contains = search_key,comment_time__contains = str(datetime.datetime().year));
TypeError: Required argument 'year' (pos 1) not found
[2018-10-14 18:19:56,457] [ERROR] "GET /api/jingqudetail/1 HTTP/1.1" 500 96017
[2018-10-14 18:23:19,354] [ERROR] Internal Server Error: /api/jingqudetail/1
Traceback (most recent call last):
  File "E:\Anaconda\envs\en1\lib\site-packages\django\core\handlers\exception.py", line 35, in inner
    response = get_response(request)
  File "E:\Anaconda\envs\en1\lib\site-packages\django\core\handlers\base.py", line 128, in _get_response
    response = self.process_exception_by_middleware(e, request)
  File "E:\Anaconda\envs\en1\lib\site-packages\django\core\handlers\base.py", line 126, in _get_response
    response = wrapped_callback(request, *callback_args, **callback_kwargs)
  File "E:\Anaconda\envs\en1\lib\site-packages\django\views\decorators\csrf.py", line 54, in wrapped_view
    return view_func(*args, **kwargs)
  File "E:\Anaconda\envs\en1\lib\site-packages\django\views\generic\base.py", line 69, in view
    return self.dispatch(request, *args, **kwargs)
  File "E:\Anaconda\envs\en1\lib\site-packages\rest_framework\views.py", line 483, in dispatch
    response = self.handle_exception(exc)
  File "E:\Anaconda\envs\en1\lib\site-packages\rest_framework\views.py", line 443, in handle_exception
    self.raise_uncaught_exception(exc)
  File "E:\Anaconda\envs\en1\lib\site-packages\rest_framework\views.py", line 480, in dispatch
    response = handler(request, *args, **kwargs)
  File "D:\资料\GitHub\TourCommentApiPro\TourCommentApi\TourCommentApi\Views\jingquDetailView.py", line 60, in get
    return get_jingqu_detail(request,id);
  File "D:\资料\GitHub\TourCommentApiPro\TourCommentApi\TourCommentApi\Views\jingquDetailView.py", line 44, in get_jingqu_detail
    res['thisMonthCommentNumber'] = this_year_month_comments.average('comment_score').count();
AttributeError: 'float' object has no attribute 'count'
[2018-10-14 18:23:37,456] [ERROR] "GET /api/jingqudetail/1 HTTP/1.1" 500 100176
[2018-10-14 18:24:12,886] [INFO] "GET /api/jingqudetail/1 HTTP/1.1" 200 236
[2018-10-14 18:27:43,292] [INFO] "GET /api/jingqudetail/2 HTTP/1.1" 200 237
[2018-10-14 20:17:15,698] [INFO] "POST /api/login HTTP/1.1" 200 229
[2018-10-14 20:18:02,709] [INFO] "POST /api/login HTTP/1.1" 200 229
[2018-10-14 20:18:04,641] [INFO] "OPTIONS /api/getAllTour HTTP/1.1" 200 0
[2018-10-14 20:18:04,705] [WARNING] Not Found: /api/getAllTour
[2018-10-14 20:18:04,710] [WARNING] "POST /api/getAllTour HTTP/1.1" 404 2882
[2018-10-14 20:20:29,291] [INFO] "POST /api/login HTTP/1.1" 200 229
[2018-10-14 20:20:43,092] [INFO] "OPTIONS /api/jingqulist HTTP/1.1" 200 0
[2018-10-14 20:20:43,155] [WARNING] "POST /api/jingqulist HTTP/1.1" 405 41
[2018-10-14 20:21:01,434] [INFO] "POST /api/login HTTP/1.1" 200 229
[2018-10-14 20:21:23,469] [INFO] "GET /api/jingqulist HTTP/1.1" 200 3324
[2018-10-15 13:41:36,653] [ERROR] Internal Server Error: /api/spotnumcompared
Traceback (most recent call last):
  File "E:\Anaconda\envs\en1\lib\site-packages\django\core\handlers\exception.py", line 35, in inner
    response = get_response(request)
  File "E:\Anaconda\envs\en1\lib\site-packages\django\core\handlers\base.py", line 128, in _get_response
    response = self.process_exception_by_middleware(e, request)
  File "E:\Anaconda\envs\en1\lib\site-packages\django\core\handlers\base.py", line 126, in _get_response
    response = wrapped_callback(request, *callback_args, **callback_kwargs)
  File "E:\Anaconda\envs\en1\lib\site-packages\django\views\decorators\csrf.py", line 54, in wrapped_view
    return view_func(*args, **kwargs)
  File "E:\Anaconda\envs\en1\lib\site-packages\django\views\generic\base.py", line 69, in view
    return self.dispatch(request, *args, **kwargs)
  File "E:\Anaconda\envs\en1\lib\site-packages\rest_framework\views.py", line 483, in dispatch
    response = self.handle_exception(exc)
  File "E:\Anaconda\envs\en1\lib\site-packages\rest_framework\views.py", line 443, in handle_exception
    self.raise_uncaught_exception(exc)
  File "E:\Anaconda\envs\en1\lib\site-packages\rest_framework\views.py", line 480, in dispatch
    response = handler(request, *args, **kwargs)
  File "D:\资料\GitHub\TourCommentApiPro\TourCommentApi\TourCommentApi\Views\JingquDymanicCommentView.py", line 53, in post
    return get_jingqu_dymanic_comment(request);
TypeError: get_jingqu_dymanic_comment() missing 1 required positional argument: 'id'
[2018-10-15 13:41:37,482] [ERROR] "POST /api/spotnumcompared HTTP/1.1" 500 17230
[2018-10-15 13:42:37,958] [ERROR] Internal Server Error: /api/spotnumcompared
Traceback (most recent call last):
  File "E:\Anaconda\envs\en1\lib\site-packages\django\core\handlers\exception.py", line 35, in inner
    response = get_response(request)
  File "E:\Anaconda\envs\en1\lib\site-packages\django\core\handlers\base.py", line 128, in _get_response
    response = self.process_exception_by_middleware(e, request)
  File "E:\Anaconda\envs\en1\lib\site-packages\django\core\handlers\base.py", line 126, in _get_response
    response = wrapped_callback(request, *callback_args, **callback_kwargs)
  File "E:\Anaconda\envs\en1\lib\site-packages\django\views\decorators\csrf.py", line 54, in wrapped_view
    return view_func(*args, **kwargs)
  File "E:\Anaconda\envs\en1\lib\site-packages\django\views\generic\base.py", line 69, in view
    return self.dispatch(request, *args, **kwargs)
  File "E:\Anaconda\envs\en1\lib\site-packages\rest_framework\views.py", line 483, in dispatch
    response = self.handle_exception(exc)
  File "E:\Anaconda\envs\en1\lib\site-packages\rest_framework\views.py", line 443, in handle_exception
    self.raise_uncaught_exception(exc)
  File "E:\Anaconda\envs\en1\lib\site-packages\rest_framework\views.py", line 480, in dispatch
    response = handler(request, *args, **kwargs)
  File "D:\资料\GitHub\TourCommentApiPro\TourCommentApi\TourCommentApi\Views\SpotNumComparedView.py", line 63, in post
    return get_spot_num_compard(request);
TypeError: get_spot_num_compard() missing 1 required positional argument: 'id'
[2018-10-15 13:42:38,206] [ERROR] "POST /api/spotnumcompared HTTP/1.1" 500 17207
[2018-10-15 13:43:10,935] [INFO] This is an errormsg
[2018-10-15 13:43:10,961] [INFO] "POST /api/spotnumcompared HTTP/1.1" 200 52
[2018-10-15 13:44:02,763] [INFO] This is an errormsg
[2018-10-15 13:44:02,773] [INFO] "POST /api/spotnumcompared HTTP/1.1" 200 52
[2018-10-15 13:44:42,636] [ERROR] Internal Server Error: /api/spotnumcompared
Traceback (most recent call last):
  File "E:\Anaconda\envs\en1\lib\site-packages\mongoengine\queryset\transform.py", line 61, in query
    fields = _doc_cls._lookup_field(parts)
  File "E:\Anaconda\envs\en1\lib\site-packages\mongoengine\base\document.py", line 1009, in _lookup_field
    raise LookUpError('Cannot resolve field "%s"' % field_name)
mongoengine.errors.LookUpError: Cannot resolve field "comment_month"

During handling of the above exception, another exception occurred:

Traceback (most recent call last):
  File "E:\Anaconda\envs\en1\lib\site-packages\django\core\handlers\exception.py", line 35, in inner
    response = get_response(request)
  File "E:\Anaconda\envs\en1\lib\site-packages\django\core\handlers\base.py", line 128, in _get_response
    response = self.process_exception_by_middleware(e, request)
  File "E:\Anaconda\envs\en1\lib\site-packages\django\core\handlers\base.py", line 126, in _get_response
    response = wrapped_callback(request, *callback_args, **callback_kwargs)
  File "E:\Anaconda\envs\en1\lib\site-packages\django\views\decorators\csrf.py", line 54, in wrapped_view
    return view_func(*args, **kwargs)
  File "E:\Anaconda\envs\en1\lib\site-packages\django\views\generic\base.py", line 69, in view
    return self.dispatch(request, *args, **kwargs)
  File "E:\Anaconda\envs\en1\lib\site-packages\rest_framework\views.py", line 483, in dispatch
    response = self.handle_exception(exc)
  File "E:\Anaconda\envs\en1\lib\site-packages\rest_framework\views.py", line 443, in handle_exception
    self.raise_uncaught_exception(exc)
  File "E:\Anaconda\envs\en1\lib\site-packages\rest_framework\views.py", line 480, in dispatch
    response = handler(request, *args, **kwargs)
  File "D:\资料\GitHub\TourCommentApiPro\TourCommentApi\TourCommentApi\Views\SpotNumComparedView.py", line 63, in post
    return get_spot_num_compard(request);
  File "D:\资料\GitHub\TourCommentApiPro\TourCommentApi\TourCommentApi\Views\SpotNumComparedView.py", line 36, in get_spot_num_compard
    cnts.append(comments.count());
  File "E:\Anaconda\envs\en1\lib\site-packages\mongoengine\queryset\queryset.py", line 133, in count
    return super(QuerySet, self).count(with_limit_and_skip)
  File "E:\Anaconda\envs\en1\lib\site-packages\mongoengine\queryset\base.py", line 401, in count
    return self._cursor.count(with_limit_and_skip=with_limit_and_skip)
  File "E:\Anaconda\envs\en1\lib\site-packages\mongoengine\queryset\base.py", line 1567, in _cursor
    self._cursor_obj = self._collection.find(self._query,
  File "E:\Anaconda\envs\en1\lib\site-packages\mongoengine\queryset\base.py", line 1613, in _query
    self._mongo_query = self._query_obj.to_query(self._document)
  File "E:\Anaconda\envs\en1\lib\site-packages\mongoengine\queryset\visitor.py", line 89, in to_query
    query = query.accept(QueryCompilerVisitor(document))
  File "E:\Anaconda\envs\en1\lib\site-packages\mongoengine\queryset\visitor.py", line 155, in accept
    return visitor.visit_query(self)
  File "E:\Anaconda\envs\en1\lib\site-packages\mongoengine\queryset\visitor.py", line 78, in visit_query
    return transform.query(self.document, **query.query)
  File "E:\Anaconda\envs\en1\lib\site-packages\mongoengine\queryset\transform.py", line 63, in query
    raise InvalidQueryError(e)
mongoengine.errors.InvalidQueryError: Cannot resolve field "comment_month"
[2018-10-15 13:44:43,090] [ERROR] "POST /api/spotnumcompared HTTP/1.1" 500 19034
[2018-10-15 14:25:41,191] [ERROR] Internal Server Error: /api/spotnumcompared
Traceback (most recent call last):
  File "E:\Anaconda\envs\en1\lib\site-packages\django\core\handlers\exception.py", line 35, in inner
    response = get_response(request)
  File "E:\Anaconda\envs\en1\lib\site-packages\django\core\handlers\base.py", line 128, in _get_response
    response = self.process_exception_by_middleware(e, request)
  File "E:\Anaconda\envs\en1\lib\site-packages\django\core\handlers\base.py", line 126, in _get_response
    response = wrapped_callback(request, *callback_args, **callback_kwargs)
  File "E:\Anaconda\envs\en1\lib\site-packages\django\views\decorators\csrf.py", line 54, in wrapped_view
    return view_func(*args, **kwargs)
  File "E:\Anaconda\envs\en1\lib\site-packages\django\views\generic\base.py", line 69, in view
    return self.dispatch(request, *args, **kwargs)
  File "E:\Anaconda\envs\en1\lib\site-packages\rest_framework\views.py", line 483, in dispatch
    response = self.handle_exception(exc)
  File "E:\Anaconda\envs\en1\lib\site-packages\rest_framework\views.py", line 443, in handle_exception
    self.raise_uncaught_exception(exc)
  File "E:\Anaconda\envs\en1\lib\site-packages\rest_framework\views.py", line 480, in dispatch
    response = handler(request, *args, **kwargs)
  File "D:\资料\GitHub\TourCommentApiPro\TourCommentApi\TourCommentApi\Views\SpotNumComparedView.py", line 73, in post
    return get_spot_num_compard(request);
  File "D:\资料\GitHub\TourCommentApiPro\TourCommentApi\TourCommentApi\Views\SpotNumComparedView.py", line 19, in get_spot_num_compard
    search_keys.append('千岛湖');
AttributeError: 'str' object has no attribute 'append'
[2018-10-15 14:25:41,454] [ERROR] "POST /api/spotnumcompared HTTP/1.1" 500 17308
[2018-10-15 14:26:15,742] [ERROR] Internal Server Error: /api/spotnumcompared
Traceback (most recent call last):
  File "E:\Anaconda\envs\en1\lib\site-packages\django\core\handlers\exception.py", line 35, in inner
    response = get_response(request)
  File "E:\Anaconda\envs\en1\lib\site-packages\django\core\handlers\base.py", line 128, in _get_response
    response = self.process_exception_by_middleware(e, request)
  File "E:\Anaconda\envs\en1\lib\site-packages\django\core\handlers\base.py", line 126, in _get_response
    response = wrapped_callback(request, *callback_args, **callback_kwargs)
  File "E:\Anaconda\envs\en1\lib\site-packages\django\views\decorators\csrf.py", line 54, in wrapped_view
    return view_func(*args, **kwargs)
  File "E:\Anaconda\envs\en1\lib\site-packages\django\views\generic\base.py", line 69, in view
    return self.dispatch(request, *args, **kwargs)
  File "E:\Anaconda\envs\en1\lib\site-packages\rest_framework\views.py", line 483, in dispatch
    response = self.handle_exception(exc)
  File "E:\Anaconda\envs\en1\lib\site-packages\rest_framework\views.py", line 443, in handle_exception
    self.raise_uncaught_exception(exc)
  File "E:\Anaconda\envs\en1\lib\site-packages\rest_framework\views.py", line 480, in dispatch
    response = handler(request, *args, **kwargs)
  File "D:\资料\GitHub\TourCommentApiPro\TourCommentApi\TourCommentApi\Views\SpotNumComparedView.py", line 73, in post
    return get_spot_num_compard(request);
  File "D:\资料\GitHub\TourCommentApiPro\TourCommentApi\TourCommentApi\Views\SpotNumComparedView.py", line 12, in get_spot_num_compard
    search_keys = list(request.POST['regions']);
UnboundLocalError: local variable 'list' referenced before assignment
[2018-10-15 14:26:16,258] [ERROR] "POST /api/spotnumcompared HTTP/1.1" 500 17351
[2018-10-15 14:31:24,998] [ERROR] Internal Server Error: /api/spotnumcompared
Traceback (most recent call last):
  File "E:\Anaconda\envs\en1\lib\site-packages\django\core\handlers\exception.py", line 35, in inner
    response = get_response(request)
  File "E:\Anaconda\envs\en1\lib\site-packages\django\core\handlers\base.py", line 128, in _get_response
    response = self.process_exception_by_middleware(e, request)
  File "E:\Anaconda\envs\en1\lib\site-packages\django\core\handlers\base.py", line 126, in _get_response
    response = wrapped_callback(request, *callback_args, **callback_kwargs)
  File "E:\Anaconda\envs\en1\lib\site-packages\django\views\decorators\csrf.py", line 54, in wrapped_view
    return view_func(*args, **kwargs)
  File "E:\Anaconda\envs\en1\lib\site-packages\django\views\generic\base.py", line 69, in view
    return self.dispatch(request, *args, **kwargs)
  File "E:\Anaconda\envs\en1\lib\site-packages\rest_framework\views.py", line 483, in dispatch
    response = self.handle_exception(exc)
  File "E:\Anaconda\envs\en1\lib\site-packages\rest_framework\views.py", line 443, in handle_exception
    self.raise_uncaught_exception(exc)
  File "E:\Anaconda\envs\en1\lib\site-packages\rest_framework\views.py", line 480, in dispatch
    response = handler(request, *args, **kwargs)
  File "D:\资料\GitHub\TourCommentApiPro\TourCommentApi\TourCommentApi\Views\SpotNumComparedView.py", line 73, in post
    return get_spot_num_compard(request);
  File "D:\资料\GitHub\TourCommentApiPro\TourCommentApi\TourCommentApi\Views\SpotNumComparedView.py", line 15, in get_spot_num_compard
    websites = eval((request.POST.getlist('websites'))[0]);
  File "<string>", line 1
    ['携程'']
          ^
SyntaxError: EOL while scanning string literal
[2018-10-15 14:31:25,451] [ERROR] "POST /api/spotnumcompared HTTP/1.1" 500 17349
[2018-10-15 14:31:43,377] [INFO] "POST /api/spotnumcompared HTTP/1.1" 200 196
[2018-10-15 14:33:52,400] [ERROR] Internal Server Error: /api/spotnumcompared
Traceback (most recent call last):
  File "E:\Anaconda\envs\en1\lib\site-packages\django\core\handlers\exception.py", line 35, in inner
    response = get_response(request)
  File "E:\Anaconda\envs\en1\lib\site-packages\django\core\handlers\base.py", line 128, in _get_response
    response = self.process_exception_by_middleware(e, request)
  File "E:\Anaconda\envs\en1\lib\site-packages\django\core\handlers\base.py", line 126, in _get_response
    response = wrapped_callback(request, *callback_args, **callback_kwargs)
  File "E:\Anaconda\envs\en1\lib\site-packages\django\views\decorators\csrf.py", line 54, in wrapped_view
    return view_func(*args, **kwargs)
  File "E:\Anaconda\envs\en1\lib\site-packages\django\views\generic\base.py", line 69, in view
    return self.dispatch(request, *args, **kwargs)
  File "E:\Anaconda\envs\en1\lib\site-packages\rest_framework\views.py", line 483, in dispatch
    response = self.handle_exception(exc)
  File "E:\Anaconda\envs\en1\lib\site-packages\rest_framework\views.py", line 443, in handle_exception
    self.raise_uncaught_exception(exc)
  File "E:\Anaconda\envs\en1\lib\site-packages\rest_framework\views.py", line 480, in dispatch
    response = handler(request, *args, **kwargs)
  File "D:\资料\GitHub\TourCommentApiPro\TourCommentApi\TourCommentApi\Views\SpotNumComparedView.py", line 73, in post
    return get_spot_num_compard(request);
  File "D:\资料\GitHub\TourCommentApiPro\TourCommentApi\TourCommentApi\Views\SpotNumComparedView.py", line 15, in get_spot_num_compard
    websites = eval((request.POST.getlist('websites'))[0]);
  File "<string>", line 1
    ['携程','去哪儿','大众点评'']
                       ^
SyntaxError: EOL while scanning string literal
[2018-10-15 14:33:52,684] [ERROR] "POST /api/spotnumcompared HTTP/1.1" 500 17385
[2018-10-15 14:34:19,093] [INFO] "POST /api/spotnumcompared HTTP/1.1" 200 615
[2018-10-15 14:36:04,035] [INFO] "POST /api/spotnumcompared HTTP/1.1" 200 1515
[2018-10-15 14:40:13,898] [INFO] "POST /api/spotnumcompared HTTP/1.1" 200 1997
[2018-10-15 14:43:30,487] [INFO] "POST /api/spotnumcompared HTTP/1.1" 200 1997
[2018-10-15 15:34:37,103] [ERROR] Internal Server Error: /api/spotnumcompared
Traceback (most recent call last):
  File "E:\Anaconda\envs\en1\lib\site-packages\django\core\handlers\exception.py", line 35, in inner
    response = get_response(request)
  File "E:\Anaconda\envs\en1\lib\site-packages\django\core\handlers\base.py", line 128, in _get_response
    response = self.process_exception_by_middleware(e, request)
  File "E:\Anaconda\envs\en1\lib\site-packages\django\core\handlers\base.py", line 126, in _get_response
    response = wrapped_callback(request, *callback_args, **callback_kwargs)
  File "E:\Anaconda\envs\en1\lib\site-packages\django\views\decorators\csrf.py", line 54, in wrapped_view
    return view_func(*args, **kwargs)
  File "E:\Anaconda\envs\en1\lib\site-packages\django\views\generic\base.py", line 69, in view
    return self.dispatch(request, *args, **kwargs)
  File "E:\Anaconda\envs\en1\lib\site-packages\rest_framework\views.py", line 483, in dispatch
    response = self.handle_exception(exc)
  File "E:\Anaconda\envs\en1\lib\site-packages\rest_framework\views.py", line 443, in handle_exception
    self.raise_uncaught_exception(exc)
  File "E:\Anaconda\envs\en1\lib\site-packages\rest_framework\views.py", line 480, in dispatch
    response = handler(request, *args, **kwargs)
  File "D:\资料\GitHub\TourCommentApiPro\TourCommentApi\TourCommentApi\Views\SpotNumComparedView.py", line 71, in post
    return get_spot_num_compard(request);
  File "D:\资料\GitHub\TourCommentApiPro\TourCommentApi\TourCommentApi\Views\SpotNumComparedView.py", line 37, in get_spot_num_compard
    comments = comment.objects(data_website=website, data_region__contains=region, comment_month=time);
  File "E:\Anaconda\envs\en1\lib\site-packages\mongoengine\queryset\manager.py", line 37, in __get__
    queryset = queryset_class(owner, owner._get_collection())
  File "E:\Anaconda\envs\en1\lib\site-packages\mongoengine\document.py", line 190, in _get_collection
    db = cls._get_db()
  File "E:\Anaconda\envs\en1\lib\site-packages\mongoengine\document.py", line 179, in _get_db
    return get_db(cls._meta.get('db_alias', DEFAULT_CONNECTION_NAME))
  File "E:\Anaconda\envs\en1\lib\site-packages\mongoengine\connection.py", line 236, in get_db
    db.authenticate(conn_settings['username'], conn_settings['password'], **auth_kwargs)
  File "E:\Anaconda\envs\en1\lib\site-packages\pymongo\database.py", line 1048, in authenticate
    connect=True)
  File "E:\Anaconda\envs\en1\lib\site-packages\pymongo\mongo_client.py", line 500, in _cache_credentials
    writable_preferred_server_selector)
  File "E:\Anaconda\envs\en1\lib\site-packages\pymongo\topology.py", line 214, in select_server
    address))
  File "E:\Anaconda\envs\en1\lib\site-packages\pymongo\topology.py", line 189, in select_servers
    self._error_message(selector))
pymongo.errors.ServerSelectionTimeoutError: 120.55.59.187:28117: [WinError 10065] 套接字操作尝试一个无法连接的主机。
[2018-10-15 15:34:37,694] [ERROR] "POST /api/spotnumcompared HTTP/1.1" 500 18772
[2018-10-15 15:56:45,533] [ERROR] Internal Server Error: /api/spotnumcompared
Traceback (most recent call last):
  File "E:\Anaconda\envs\en1\lib\site-packages\django\core\handlers\exception.py", line 35, in inner
    response = get_response(request)
  File "E:\Anaconda\envs\en1\lib\site-packages\django\core\handlers\base.py", line 128, in _get_response
    response = self.process_exception_by_middleware(e, request)
  File "E:\Anaconda\envs\en1\lib\site-packages\django\core\handlers\base.py", line 126, in _get_response
    response = wrapped_callback(request, *callback_args, **callback_kwargs)
  File "E:\Anaconda\envs\en1\lib\site-packages\django\views\decorators\csrf.py", line 54, in wrapped_view
    return view_func(*args, **kwargs)
  File "E:\Anaconda\envs\en1\lib\site-packages\django\views\generic\base.py", line 69, in view
    return self.dispatch(request, *args, **kwargs)
  File "E:\Anaconda\envs\en1\lib\site-packages\rest_framework\views.py", line 483, in dispatch
    response = self.handle_exception(exc)
  File "E:\Anaconda\envs\en1\lib\site-packages\rest_framework\views.py", line 443, in handle_exception
    self.raise_uncaught_exception(exc)
  File "E:\Anaconda\envs\en1\lib\site-packages\rest_framework\views.py", line 480, in dispatch
    response = handler(request, *args, **kwargs)
  File "D:\资料\GitHub\TourCommentApiPro\TourCommentApi\TourCommentApi\Views\SpotNumComparedView.py", line 72, in post
    return get_spot_num_compard(request);
  File "D:\资料\GitHub\TourCommentApiPro\TourCommentApi\TourCommentApi\Views\SpotNumComparedView.py", line 38, in get_spot_num_compard
    rcomments = comments.objects(data_website=website, data_region__contains=region, comment_month=time);
AttributeError: 'function' object has no attribute 'objects'
[2018-10-15 15:56:53,392] [ERROR] "POST /api/spotnumcompared HTTP/1.1" 500 17448
[2018-10-15 15:57:20,348] [ERROR] Internal Server Error: /api/spotnumcompared
Traceback (most recent call last):
  File "E:\Anaconda\envs\en1\lib\site-packages\django\core\handlers\exception.py", line 35, in inner
    response = get_response(request)
  File "E:\Anaconda\envs\en1\lib\site-packages\django\core\handlers\base.py", line 128, in _get_response
    response = self.process_exception_by_middleware(e, request)
  File "E:\Anaconda\envs\en1\lib\site-packages\django\core\handlers\base.py", line 126, in _get_response
    response = wrapped_callback(request, *callback_args, **callback_kwargs)
  File "E:\Anaconda\envs\en1\lib\site-packages\django\views\decorators\csrf.py", line 54, in wrapped_view
    return view_func(*args, **kwargs)
  File "E:\Anaconda\envs\en1\lib\site-packages\django\views\generic\base.py", line 69, in view
    return self.dispatch(request, *args, **kwargs)
  File "E:\Anaconda\envs\en1\lib\site-packages\rest_framework\views.py", line 483, in dispatch
    response = self.handle_exception(exc)
  File "E:\Anaconda\envs\en1\lib\site-packages\rest_framework\views.py", line 443, in handle_exception
    self.raise_uncaught_exception(exc)
  File "E:\Anaconda\envs\en1\lib\site-packages\rest_framework\views.py", line 480, in dispatch
    response = handler(request, *args, **kwargs)
  File "D:\资料\GitHub\TourCommentApiPro\TourCommentApi\TourCommentApi\Views\SpotNumComparedView.py", line 72, in post
    return get_spot_num_compard(request);
  File "D:\资料\GitHub\TourCommentApiPro\TourCommentApi\TourCommentApi\Views\SpotNumComparedView.py", line 38, in get_spot_num_compard
    rcomments = comments.objects(data_website=website, data_region__contains=region, comment_month=time);
AttributeError: 'QuerySet' object has no attribute 'objects'
[2018-10-15 15:57:28,241] [ERROR] "POST /api/spotnumcompared HTTP/1.1" 500 17447
[2018-10-15 16:00:28,158] [ERROR] Internal Server Error: /api/spotnumcompared
Traceback (most recent call last):
  File "E:\Anaconda\envs\en1\lib\site-packages\django\core\handlers\exception.py", line 35, in inner
    response = get_response(request)
  File "E:\Anaconda\envs\en1\lib\site-packages\django\core\handlers\base.py", line 128, in _get_response
    response = self.process_exception_by_middleware(e, request)
  File "E:\Anaconda\envs\en1\lib\site-packages\django\core\handlers\base.py", line 126, in _get_response
    response = wrapped_callback(request, *callback_args, **callback_kwargs)
  File "E:\Anaconda\envs\en1\lib\site-packages\django\views\decorators\csrf.py", line 54, in wrapped_view
    return view_func(*args, **kwargs)
  File "E:\Anaconda\envs\en1\lib\site-packages\django\views\generic\base.py", line 69, in view
    return self.dispatch(request, *args, **kwargs)
  File "E:\Anaconda\envs\en1\lib\site-packages\rest_framework\views.py", line 483, in dispatch
    response = self.handle_exception(exc)
  File "E:\Anaconda\envs\en1\lib\site-packages\rest_framework\views.py", line 443, in handle_exception
    self.raise_uncaught_exception(exc)
  File "E:\Anaconda\envs\en1\lib\site-packages\rest_framework\views.py", line 480, in dispatch
    response = handler(request, *args, **kwargs)
  File "D:\资料\GitHub\TourCommentApiPro\TourCommentApi\TourCommentApi\Views\SpotNumComparedView.py", line 72, in post
    return get_spot_num_compard(request);
  File "D:\资料\GitHub\TourCommentApiPro\TourCommentApi\TourCommentApi\Views\SpotNumComparedView.py", line 12, in get_spot_num_compard
    search_keys = eval((request.POST.getlist('spots'))[0]);
  File "<string>", line 1
    ['西湖‘]
         ^
SyntaxError: EOL while scanning string literal
[2018-10-15 16:00:28,451] [ERROR] "POST /api/spotnumcompared HTTP/1.1" 500 17392
[2018-10-15 16:00:46,820] [ERROR] Internal Server Error: /api/spotnumcompared
Traceback (most recent call last):
  File "E:\Anaconda\envs\en1\lib\site-packages\django\core\handlers\exception.py", line 35, in inner
    response = get_response(request)
  File "E:\Anaconda\envs\en1\lib\site-packages\django\core\handlers\base.py", line 128, in _get_response
    response = self.process_exception_by_middleware(e, request)
  File "E:\Anaconda\envs\en1\lib\site-packages\django\core\handlers\base.py", line 126, in _get_response
    response = wrapped_callback(request, *callback_args, **callback_kwargs)
  File "E:\Anaconda\envs\en1\lib\site-packages\django\views\decorators\csrf.py", line 54, in wrapped_view
    return view_func(*args, **kwargs)
  File "E:\Anaconda\envs\en1\lib\site-packages\django\views\generic\base.py", line 69, in view
    return self.dispatch(request, *args, **kwargs)
  File "E:\Anaconda\envs\en1\lib\site-packages\rest_framework\views.py", line 483, in dispatch
    response = self.handle_exception(exc)
  File "E:\Anaconda\envs\en1\lib\site-packages\rest_framework\views.py", line 443, in handle_exception
    self.raise_uncaught_exception(exc)
  File "E:\Anaconda\envs\en1\lib\site-packages\rest_framework\views.py", line 480, in dispatch
    response = handler(request, *args, **kwargs)
  File "D:\资料\GitHub\TourCommentApiPro\TourCommentApi\TourCommentApi\Views\SpotNumComparedView.py", line 72, in post
    return get_spot_num_compard(request);
  File "D:\资料\GitHub\TourCommentApiPro\TourCommentApi\TourCommentApi\Views\SpotNumComparedView.py", line 38, in get_spot_num_compard
    rcomments = comments.objects( data_region__contains=region, comment_month=time);
AttributeError: 'QuerySet' object has no attribute 'objects'
[2018-10-15 16:00:54,644] [ERROR] "POST /api/spotnumcompared HTTP/1.1" 500 17418
[2018-10-15 16:02:06,097] [ERROR] Internal Server Error: /api/spotnumcompared
Traceback (most recent call last):
  File "E:\Anaconda\envs\en1\lib\site-packages\django\core\handlers\exception.py", line 35, in inner
    response = get_response(request)
  File "E:\Anaconda\envs\en1\lib\site-packages\django\core\handlers\base.py", line 128, in _get_response
    response = self.process_exception_by_middleware(e, request)
  File "E:\Anaconda\envs\en1\lib\site-packages\django\core\handlers\base.py", line 126, in _get_response
    response = wrapped_callback(request, *callback_args, **callback_kwargs)
  File "E:\Anaconda\envs\en1\lib\site-packages\django\views\decorators\csrf.py", line 54, in wrapped_view
    return view_func(*args, **kwargs)
  File "E:\Anaconda\envs\en1\lib\site-packages\django\views\generic\base.py", line 69, in view
    return self.dispatch(request, *args, **kwargs)
  File "E:\Anaconda\envs\en1\lib\site-packages\rest_framework\views.py", line 483, in dispatch
    response = self.handle_exception(exc)
  File "E:\Anaconda\envs\en1\lib\site-packages\rest_framework\views.py", line 443, in handle_exception
    self.raise_uncaught_exception(exc)
  File "E:\Anaconda\envs\en1\lib\site-packages\rest_framework\views.py", line 480, in dispatch
    response = handler(request, *args, **kwargs)
  File "D:\资料\GitHub\TourCommentApiPro\TourCommentApi\TourCommentApi\Views\SpotNumComparedView.py", line 73, in post
    return get_spot_num_compard(request);
  File "D:\资料\GitHub\TourCommentApiPro\TourCommentApi\TourCommentApi\Views\SpotNumComparedView.py", line 39, in get_spot_num_compard
    rcomments = comments.objects( data_region__contains=region, comment_month=time);
AttributeError: 'QuerySet' object has no attribute 'objects'
[2018-10-15 16:02:14,195] [ERROR] "POST /api/spotnumcompared HTTP/1.1" 500 17418
[2018-10-15 16:02:58,607] [ERROR] Internal Server Error: /api/spotnumcompared
Traceback (most recent call last):
  File "E:\Anaconda\envs\en1\lib\site-packages\django\core\handlers\exception.py", line 35, in inner
    response = get_response(request)
  File "E:\Anaconda\envs\en1\lib\site-packages\django\core\handlers\base.py", line 128, in _get_response
    response = self.process_exception_by_middleware(e, request)
  File "E:\Anaconda\envs\en1\lib\site-packages\django\core\handlers\base.py", line 126, in _get_response
    response = wrapped_callback(request, *callback_args, **callback_kwargs)
  File "E:\Anaconda\envs\en1\lib\site-packages\django\views\decorators\csrf.py", line 54, in wrapped_view
    return view_func(*args, **kwargs)
  File "E:\Anaconda\envs\en1\lib\site-packages\django\views\generic\base.py", line 69, in view
    return self.dispatch(request, *args, **kwargs)
  File "E:\Anaconda\envs\en1\lib\site-packages\rest_framework\views.py", line 483, in dispatch
    response = self.handle_exception(exc)
  File "E:\Anaconda\envs\en1\lib\site-packages\rest_framework\views.py", line 443, in handle_exception
    self.raise_uncaught_exception(exc)
  File "E:\Anaconda\envs\en1\lib\site-packages\rest_framework\views.py", line 480, in dispatch
    response = handler(request, *args, **kwargs)
  File "D:\资料\GitHub\TourCommentApiPro\TourCommentApi\TourCommentApi\Views\SpotNumComparedView.py", line 73, in post
    return get_spot_num_compard(request);
  File "D:\资料\GitHub\TourCommentApiPro\TourCommentApi\TourCommentApi\Views\SpotNumComparedView.py", line 39, in get_spot_num_compard
    rcomments = rrcomments.objects(data_region__contains=region, comment_month=time);
AttributeError: 'QuerySet' object has no attribute 'objects'
[2018-10-15 16:03:06,618] [ERROR] "POST /api/spotnumcompared HTTP/1.1" 500 17419
[2018-10-15 16:03:55,722] [INFO] "POST /api/spotnumcompared HTTP/1.1" 200 686
[2018-10-15 16:07:37,000] [INFO] "POST /api/spotnumcompared HTTP/1.1" 200 1676
[2018-10-15 18:00:30,508] [INFO] "GET /api/jingqulist HTTP/1.1" 200 3324
[2018-10-15 18:00:31,625] [WARNING] Not Found: /favicon.ico
[2018-10-15 18:00:31,630] [WARNING] "GET /favicon.ico HTTP/1.1" 404 2867
[2018-10-15 18:01:00,580] [INFO] "GET /api/jingqulist HTTP/1.1" 200 3324
[2018-10-15 18:01:44,793] [INFO] "GET /api/jingqulist HTTP/1.1" 200 3324
[2018-10-15 18:03:48,750] [INFO] "GET /api/jingqulist HTTP/1.1" 200 3324
[2018-10-15 18:06:26,226] [INFO] "GET /api/jingqulist HTTP/1.1" 200 3324
[2018-10-15 18:11:40,829] [INFO] "GET /api/jingqulist HTTP/1.1" 200 3324
[2018-10-15 18:15:53,747] [INFO] "GET /api/jingqulist HTTP/1.1" 200 3324
[2018-10-15 18:17:38,423] [INFO] "GET /api/jingqulist HTTP/1.1" 200 3324
[2018-10-15 18:23:46,598] [INFO] "GET /api/jingqulist HTTP/1.1" 200 3324
[2018-10-15 18:28:13,627] [INFO] "GET /api/jingqulist HTTP/1.1" 200 3324
[2018-10-15 18:28:37,393] [INFO] "GET /api/jingqulist HTTP/1.1" 200 3324
[2018-10-15 18:32:12,294] [INFO] "GET /api/jingqulist HTTP/1.1" 200 3324
[2018-10-15 18:32:35,255] [INFO] "GET /api/jingqulist HTTP/1.1" 200 3324
[2018-10-15 18:45:56,703] [INFO] "GET /api/jingqulist HTTP/1.1" 200 3324
[2018-10-15 18:46:19,883] [INFO] "GET /api/jingqulist HTTP/1.1" 200 3324
[2018-10-15 18:47:20,267] [INFO] "GET /api/jingqulist HTTP/1.1" 200 3324
[2018-10-15 18:48:11,459] [INFO] "GET /api/jingqulist HTTP/1.1" 200 3324
[2018-10-15 19:01:41,412] [INFO] "GET /api/jingqulist HTTP/1.1" 200 48
[2018-10-15 19:01:51,461] [INFO] "GET /api/jingqulist HTTP/1.1" 200 48
[2018-10-15 19:01:53,189] [INFO] "GET /api/jingqulist HTTP/1.1" 200 48
[2018-10-15 19:02:19,624] [INFO] "GET /api/jingqulist HTTP/1.1" 200 48
[2018-10-15 19:02:30,699] [INFO] "GET /api/jingqulist HTTP/1.1" 200 48
[2018-10-15 19:04:12,967] [INFO] This is an errormsg
[2018-10-15 19:04:12,972] [INFO] "GET /api/jingqulist HTTP/1.1" 200 57
[2018-10-15 19:16:46,555] [INFO] "GET /api/jingqulist HTTP/1.1" 200 59086
[2018-10-15 19:17:45,017] [INFO] "GET /api/jingqulist HTTP/1.1" 200 3324
[2018-10-15 19:19:34,213] [INFO] "GET /api/jingqulist HTTP/1.1" 200 2644
[2018-10-15 19:27:18,648] [INFO] "GET /api/jingqulist HTTP/1.1" 200 3220
[2018-10-15 19:33:02,725] [INFO] This is an errormsg
[2018-10-15 19:33:02,728] [INFO] "GET /api/jingqulist HTTP/1.1" 200 57
[2018-10-15 19:34:35,422] [INFO] This is an errormsg
[2018-10-15 19:34:35,428] [INFO] "GET /api/jingqulist HTTP/1.1" 200 57
[2018-10-15 19:36:06,860] [INFO] "GET /api/jingqulist HTTP/1.1" 200 3094
[2018-10-15 19:36:39,435] [INFO] "GET /api/jingqulist HTTP/1.1" 200 3094
[2018-10-15 19:36:41,572] [INFO] "GET /api/jingqulist HTTP/1.1" 200 3094
[2018-10-15 19:36:53,784] [INFO] "GET /api/jingqulist HTTP/1.1" 200 3094
[2018-10-15 19:36:54,890] [INFO] "GET /api/jingqulist HTTP/1.1" 200 3094
[2018-10-15 19:36:55,720] [INFO] "GET /api/jingqulist HTTP/1.1" 200 3094
[2018-10-15 19:36:56,490] [INFO] "GET /api/jingqulist HTTP/1.1" 200 3094
[2018-10-15 19:50:15,882] [INFO] This is an errormsg
[2018-10-15 19:50:15,884] [INFO] "GET /api/jingqulist HTTP/1.1" 200 57
[2018-10-15 19:58:30,914] [INFO] This is an errormsg
[2018-10-15 19:58:30,917] [INFO] "GET /api/jingqulist HTTP/1.1" 200 57
[2018-10-15 20:00:38,177] [INFO] This is an errormsg
[2018-10-15 20:00:38,179] [INFO] "GET /api/jingqulist HTTP/1.1" 200 57
[2018-10-15 20:03:33,637] [INFO] This is an errormsg
[2018-10-15 20:03:33,641] [INFO] "GET /api/jingqulist HTTP/1.1" 200 57
[2018-10-15 20:04:35,355] [INFO] This is an errormsg
[2018-10-15 20:04:35,360] [INFO] "GET /api/jingqulist HTTP/1.1" 200 57
[2018-10-15 20:06:15,952] [INFO] "GET /api/jingqulist HTTP/1.1" 200 2644
[2018-10-15 20:11:32,361] [INFO] This is an errormsg
[2018-10-15 20:11:32,364] [INFO] "GET /api/jingqulist HTTP/1.1" 200 57
[2018-10-15 20:14:55,790] [INFO] "GET /api/jingqulist HTTP/1.1" 200 3094
[2018-10-15 20:19:00,455] [INFO] "GET /api/jingqulist HTTP/1.1" 200 3076
[2018-10-15 20:21:40,770] [INFO] This is an errormsg
[2018-10-15 20:21:40,795] [INFO] "GET /api/jingqulist HTTP/1.1" 200 57
[2018-10-15 20:22:55,563] [INFO] "GET /api/jingqulist HTTP/1.1" 200 3076
[2018-10-15 20:23:15,109] [INFO] "GET /api/jingqulist HTTP/1.1" 200 3076
[2018-10-15 20:23:31,065] [INFO] "GET /api/jingqulist HTTP/1.1" 200 3076
=======
[2018-10-13 22:57:33,242] [INFO] "GET /api/jingqulist HTTP/1.1" 200 3058
[2018-10-13 22:58:04,643] [INFO] "GET /api/jingqulist HTTP/1.1" 200 3058
[2018-10-14 17:19:50,513] [INFO] "GET /api/jingqulist HTTP/1.1" 200 3324
[2018-10-14 17:28:38,097] [INFO] "GET /api/jingdianlist/1 HTTP/1.1" 200 3883
[2018-10-14 17:33:11,584] [INFO] "GET /api/jingqucount/1 HTTP/1.1" 200 72
[2018-10-14 17:33:54,285] [INFO] "GET /api/jingqucount/1 HTTP/1.1" 200 76
[2018-10-14 17:33:59,910] [INFO] "GET /api/jingqucount/2 HTTP/1.1" 200 77
[2018-10-14 17:34:21,414] [INFO] "GET /api/jingqucount/18 HTTP/1.1" 200 75
[2018-10-14 17:34:29,214] [INFO] "GET /api/jingqucount/17 HTTP/1.1" 200 76
[2018-10-14 17:34:35,536] [INFO] "GET /api/jingqucount/11 HTTP/1.1" 200 76
[2018-10-14 18:19:55,587] [ERROR] Internal Server Error: /api/jingqudetail/1
Traceback (most recent call last):
  File "E:\Anaconda\envs\en1\lib\site-packages\django\core\handlers\exception.py", line 35, in inner
    response = get_response(request)
  File "E:\Anaconda\envs\en1\lib\site-packages\django\core\handlers\base.py", line 128, in _get_response
    response = self.process_exception_by_middleware(e, request)
  File "E:\Anaconda\envs\en1\lib\site-packages\django\core\handlers\base.py", line 126, in _get_response
    response = wrapped_callback(request, *callback_args, **callback_kwargs)
  File "E:\Anaconda\envs\en1\lib\site-packages\django\views\decorators\csrf.py", line 54, in wrapped_view
    return view_func(*args, **kwargs)
  File "E:\Anaconda\envs\en1\lib\site-packages\django\views\generic\base.py", line 69, in view
    return self.dispatch(request, *args, **kwargs)
  File "E:\Anaconda\envs\en1\lib\site-packages\rest_framework\views.py", line 483, in dispatch
    response = self.handle_exception(exc)
  File "E:\Anaconda\envs\en1\lib\site-packages\rest_framework\views.py", line 443, in handle_exception
    self.raise_uncaught_exception(exc)
  File "E:\Anaconda\envs\en1\lib\site-packages\rest_framework\views.py", line 480, in dispatch
    response = handler(request, *args, **kwargs)
  File "D:\资料\GitHub\TourCommentApiPro\TourCommentApi\TourCommentApi\Views\jingquDetailView.py", line 60, in get
    return get_jingqu_detail(request,id);
  File "D:\资料\GitHub\TourCommentApiPro\TourCommentApi\TourCommentApi\Views\jingquDetailView.py", line 19, in get_jingqu_detail
    this_year_comments = comment.objects(data_region__contains = search_key,comment_time__contains = str(datetime.datetime().year));
TypeError: Required argument 'year' (pos 1) not found
[2018-10-14 18:19:56,457] [ERROR] "GET /api/jingqudetail/1 HTTP/1.1" 500 96017
[2018-10-14 18:23:19,354] [ERROR] Internal Server Error: /api/jingqudetail/1
Traceback (most recent call last):
  File "E:\Anaconda\envs\en1\lib\site-packages\django\core\handlers\exception.py", line 35, in inner
    response = get_response(request)
  File "E:\Anaconda\envs\en1\lib\site-packages\django\core\handlers\base.py", line 128, in _get_response
    response = self.process_exception_by_middleware(e, request)
  File "E:\Anaconda\envs\en1\lib\site-packages\django\core\handlers\base.py", line 126, in _get_response
    response = wrapped_callback(request, *callback_args, **callback_kwargs)
  File "E:\Anaconda\envs\en1\lib\site-packages\django\views\decorators\csrf.py", line 54, in wrapped_view
    return view_func(*args, **kwargs)
  File "E:\Anaconda\envs\en1\lib\site-packages\django\views\generic\base.py", line 69, in view
    return self.dispatch(request, *args, **kwargs)
  File "E:\Anaconda\envs\en1\lib\site-packages\rest_framework\views.py", line 483, in dispatch
    response = self.handle_exception(exc)
  File "E:\Anaconda\envs\en1\lib\site-packages\rest_framework\views.py", line 443, in handle_exception
    self.raise_uncaught_exception(exc)
  File "E:\Anaconda\envs\en1\lib\site-packages\rest_framework\views.py", line 480, in dispatch
    response = handler(request, *args, **kwargs)
  File "D:\资料\GitHub\TourCommentApiPro\TourCommentApi\TourCommentApi\Views\jingquDetailView.py", line 60, in get
    return get_jingqu_detail(request,id);
  File "D:\资料\GitHub\TourCommentApiPro\TourCommentApi\TourCommentApi\Views\jingquDetailView.py", line 44, in get_jingqu_detail
    res['thisMonthCommentNumber'] = this_year_month_comments.average('comment_score').count();
AttributeError: 'float' object has no attribute 'count'
[2018-10-14 18:23:37,456] [ERROR] "GET /api/jingqudetail/1 HTTP/1.1" 500 100176
[2018-10-14 18:24:12,886] [INFO] "GET /api/jingqudetail/1 HTTP/1.1" 200 236
[2018-10-14 18:27:43,292] [INFO] "GET /api/jingqudetail/2 HTTP/1.1" 200 237
[2018-10-14 20:17:15,698] [INFO] "POST /api/login HTTP/1.1" 200 229
[2018-10-14 20:18:02,709] [INFO] "POST /api/login HTTP/1.1" 200 229
[2018-10-14 20:18:04,641] [INFO] "OPTIONS /api/getAllTour HTTP/1.1" 200 0
[2018-10-14 20:18:04,705] [WARNING] Not Found: /api/getAllTour
[2018-10-14 20:18:04,710] [WARNING] "POST /api/getAllTour HTTP/1.1" 404 2882
[2018-10-14 20:20:29,291] [INFO] "POST /api/login HTTP/1.1" 200 229
[2018-10-14 20:20:43,092] [INFO] "OPTIONS /api/jingqulist HTTP/1.1" 200 0
[2018-10-14 20:20:43,155] [WARNING] "POST /api/jingqulist HTTP/1.1" 405 41
[2018-10-14 20:21:01,434] [INFO] "POST /api/login HTTP/1.1" 200 229
[2018-10-14 20:21:23,469] [INFO] "GET /api/jingqulist HTTP/1.1" 200 3324
[2018-10-15 13:41:36,653] [ERROR] Internal Server Error: /api/spotnumcompared
Traceback (most recent call last):
  File "E:\Anaconda\envs\en1\lib\site-packages\django\core\handlers\exception.py", line 35, in inner
    response = get_response(request)
  File "E:\Anaconda\envs\en1\lib\site-packages\django\core\handlers\base.py", line 128, in _get_response
    response = self.process_exception_by_middleware(e, request)
  File "E:\Anaconda\envs\en1\lib\site-packages\django\core\handlers\base.py", line 126, in _get_response
    response = wrapped_callback(request, *callback_args, **callback_kwargs)
  File "E:\Anaconda\envs\en1\lib\site-packages\django\views\decorators\csrf.py", line 54, in wrapped_view
    return view_func(*args, **kwargs)
  File "E:\Anaconda\envs\en1\lib\site-packages\django\views\generic\base.py", line 69, in view
    return self.dispatch(request, *args, **kwargs)
  File "E:\Anaconda\envs\en1\lib\site-packages\rest_framework\views.py", line 483, in dispatch
    response = self.handle_exception(exc)
  File "E:\Anaconda\envs\en1\lib\site-packages\rest_framework\views.py", line 443, in handle_exception
    self.raise_uncaught_exception(exc)
  File "E:\Anaconda\envs\en1\lib\site-packages\rest_framework\views.py", line 480, in dispatch
    response = handler(request, *args, **kwargs)
  File "D:\资料\GitHub\TourCommentApiPro\TourCommentApi\TourCommentApi\Views\JingquDymanicCommentView.py", line 53, in post
    return get_jingqu_dymanic_comment(request);
TypeError: get_jingqu_dymanic_comment() missing 1 required positional argument: 'id'
[2018-10-15 13:41:37,482] [ERROR] "POST /api/spotnumcompared HTTP/1.1" 500 17230
[2018-10-15 13:42:37,958] [ERROR] Internal Server Error: /api/spotnumcompared
Traceback (most recent call last):
  File "E:\Anaconda\envs\en1\lib\site-packages\django\core\handlers\exception.py", line 35, in inner
    response = get_response(request)
  File "E:\Anaconda\envs\en1\lib\site-packages\django\core\handlers\base.py", line 128, in _get_response
    response = self.process_exception_by_middleware(e, request)
  File "E:\Anaconda\envs\en1\lib\site-packages\django\core\handlers\base.py", line 126, in _get_response
    response = wrapped_callback(request, *callback_args, **callback_kwargs)
  File "E:\Anaconda\envs\en1\lib\site-packages\django\views\decorators\csrf.py", line 54, in wrapped_view
    return view_func(*args, **kwargs)
  File "E:\Anaconda\envs\en1\lib\site-packages\django\views\generic\base.py", line 69, in view
    return self.dispatch(request, *args, **kwargs)
  File "E:\Anaconda\envs\en1\lib\site-packages\rest_framework\views.py", line 483, in dispatch
    response = self.handle_exception(exc)
  File "E:\Anaconda\envs\en1\lib\site-packages\rest_framework\views.py", line 443, in handle_exception
    self.raise_uncaught_exception(exc)
  File "E:\Anaconda\envs\en1\lib\site-packages\rest_framework\views.py", line 480, in dispatch
    response = handler(request, *args, **kwargs)
  File "D:\资料\GitHub\TourCommentApiPro\TourCommentApi\TourCommentApi\Views\SpotNumComparedView.py", line 63, in post
    return get_spot_num_compard(request);
TypeError: get_spot_num_compard() missing 1 required positional argument: 'id'
[2018-10-15 13:42:38,206] [ERROR] "POST /api/spotnumcompared HTTP/1.1" 500 17207
[2018-10-15 13:43:10,935] [INFO] This is an errormsg
[2018-10-15 13:43:10,961] [INFO] "POST /api/spotnumcompared HTTP/1.1" 200 52
[2018-10-15 13:44:02,763] [INFO] This is an errormsg
[2018-10-15 13:44:02,773] [INFO] "POST /api/spotnumcompared HTTP/1.1" 200 52
[2018-10-15 13:44:42,636] [ERROR] Internal Server Error: /api/spotnumcompared
Traceback (most recent call last):
  File "E:\Anaconda\envs\en1\lib\site-packages\mongoengine\queryset\transform.py", line 61, in query
    fields = _doc_cls._lookup_field(parts)
  File "E:\Anaconda\envs\en1\lib\site-packages\mongoengine\base\document.py", line 1009, in _lookup_field
    raise LookUpError('Cannot resolve field "%s"' % field_name)
mongoengine.errors.LookUpError: Cannot resolve field "comment_month"

During handling of the above exception, another exception occurred:

Traceback (most recent call last):
  File "E:\Anaconda\envs\en1\lib\site-packages\django\core\handlers\exception.py", line 35, in inner
    response = get_response(request)
  File "E:\Anaconda\envs\en1\lib\site-packages\django\core\handlers\base.py", line 128, in _get_response
    response = self.process_exception_by_middleware(e, request)
  File "E:\Anaconda\envs\en1\lib\site-packages\django\core\handlers\base.py", line 126, in _get_response
    response = wrapped_callback(request, *callback_args, **callback_kwargs)
  File "E:\Anaconda\envs\en1\lib\site-packages\django\views\decorators\csrf.py", line 54, in wrapped_view
    return view_func(*args, **kwargs)
  File "E:\Anaconda\envs\en1\lib\site-packages\django\views\generic\base.py", line 69, in view
    return self.dispatch(request, *args, **kwargs)
  File "E:\Anaconda\envs\en1\lib\site-packages\rest_framework\views.py", line 483, in dispatch
    response = self.handle_exception(exc)
  File "E:\Anaconda\envs\en1\lib\site-packages\rest_framework\views.py", line 443, in handle_exception
    self.raise_uncaught_exception(exc)
  File "E:\Anaconda\envs\en1\lib\site-packages\rest_framework\views.py", line 480, in dispatch
    response = handler(request, *args, **kwargs)
  File "D:\资料\GitHub\TourCommentApiPro\TourCommentApi\TourCommentApi\Views\SpotNumComparedView.py", line 63, in post
    return get_spot_num_compard(request);
  File "D:\资料\GitHub\TourCommentApiPro\TourCommentApi\TourCommentApi\Views\SpotNumComparedView.py", line 36, in get_spot_num_compard
    cnts.append(comments.count());
  File "E:\Anaconda\envs\en1\lib\site-packages\mongoengine\queryset\queryset.py", line 133, in count
    return super(QuerySet, self).count(with_limit_and_skip)
  File "E:\Anaconda\envs\en1\lib\site-packages\mongoengine\queryset\base.py", line 401, in count
    return self._cursor.count(with_limit_and_skip=with_limit_and_skip)
  File "E:\Anaconda\envs\en1\lib\site-packages\mongoengine\queryset\base.py", line 1567, in _cursor
    self._cursor_obj = self._collection.find(self._query,
  File "E:\Anaconda\envs\en1\lib\site-packages\mongoengine\queryset\base.py", line 1613, in _query
    self._mongo_query = self._query_obj.to_query(self._document)
  File "E:\Anaconda\envs\en1\lib\site-packages\mongoengine\queryset\visitor.py", line 89, in to_query
    query = query.accept(QueryCompilerVisitor(document))
  File "E:\Anaconda\envs\en1\lib\site-packages\mongoengine\queryset\visitor.py", line 155, in accept
    return visitor.visit_query(self)
  File "E:\Anaconda\envs\en1\lib\site-packages\mongoengine\queryset\visitor.py", line 78, in visit_query
    return transform.query(self.document, **query.query)
  File "E:\Anaconda\envs\en1\lib\site-packages\mongoengine\queryset\transform.py", line 63, in query
    raise InvalidQueryError(e)
mongoengine.errors.InvalidQueryError: Cannot resolve field "comment_month"
[2018-10-15 13:44:43,090] [ERROR] "POST /api/spotnumcompared HTTP/1.1" 500 19034
[2018-10-15 14:25:41,191] [ERROR] Internal Server Error: /api/spotnumcompared
Traceback (most recent call last):
  File "E:\Anaconda\envs\en1\lib\site-packages\django\core\handlers\exception.py", line 35, in inner
    response = get_response(request)
  File "E:\Anaconda\envs\en1\lib\site-packages\django\core\handlers\base.py", line 128, in _get_response
    response = self.process_exception_by_middleware(e, request)
  File "E:\Anaconda\envs\en1\lib\site-packages\django\core\handlers\base.py", line 126, in _get_response
    response = wrapped_callback(request, *callback_args, **callback_kwargs)
  File "E:\Anaconda\envs\en1\lib\site-packages\django\views\decorators\csrf.py", line 54, in wrapped_view
    return view_func(*args, **kwargs)
  File "E:\Anaconda\envs\en1\lib\site-packages\django\views\generic\base.py", line 69, in view
    return self.dispatch(request, *args, **kwargs)
  File "E:\Anaconda\envs\en1\lib\site-packages\rest_framework\views.py", line 483, in dispatch
    response = self.handle_exception(exc)
  File "E:\Anaconda\envs\en1\lib\site-packages\rest_framework\views.py", line 443, in handle_exception
    self.raise_uncaught_exception(exc)
  File "E:\Anaconda\envs\en1\lib\site-packages\rest_framework\views.py", line 480, in dispatch
    response = handler(request, *args, **kwargs)
  File "D:\资料\GitHub\TourCommentApiPro\TourCommentApi\TourCommentApi\Views\SpotNumComparedView.py", line 73, in post
    return get_spot_num_compard(request);
  File "D:\资料\GitHub\TourCommentApiPro\TourCommentApi\TourCommentApi\Views\SpotNumComparedView.py", line 19, in get_spot_num_compard
    search_keys.append('千岛湖');
AttributeError: 'str' object has no attribute 'append'
[2018-10-15 14:25:41,454] [ERROR] "POST /api/spotnumcompared HTTP/1.1" 500 17308
[2018-10-15 14:26:15,742] [ERROR] Internal Server Error: /api/spotnumcompared
Traceback (most recent call last):
  File "E:\Anaconda\envs\en1\lib\site-packages\django\core\handlers\exception.py", line 35, in inner
    response = get_response(request)
  File "E:\Anaconda\envs\en1\lib\site-packages\django\core\handlers\base.py", line 128, in _get_response
    response = self.process_exception_by_middleware(e, request)
  File "E:\Anaconda\envs\en1\lib\site-packages\django\core\handlers\base.py", line 126, in _get_response
    response = wrapped_callback(request, *callback_args, **callback_kwargs)
  File "E:\Anaconda\envs\en1\lib\site-packages\django\views\decorators\csrf.py", line 54, in wrapped_view
    return view_func(*args, **kwargs)
  File "E:\Anaconda\envs\en1\lib\site-packages\django\views\generic\base.py", line 69, in view
    return self.dispatch(request, *args, **kwargs)
  File "E:\Anaconda\envs\en1\lib\site-packages\rest_framework\views.py", line 483, in dispatch
    response = self.handle_exception(exc)
  File "E:\Anaconda\envs\en1\lib\site-packages\rest_framework\views.py", line 443, in handle_exception
    self.raise_uncaught_exception(exc)
  File "E:\Anaconda\envs\en1\lib\site-packages\rest_framework\views.py", line 480, in dispatch
    response = handler(request, *args, **kwargs)
  File "D:\资料\GitHub\TourCommentApiPro\TourCommentApi\TourCommentApi\Views\SpotNumComparedView.py", line 73, in post
    return get_spot_num_compard(request);
  File "D:\资料\GitHub\TourCommentApiPro\TourCommentApi\TourCommentApi\Views\SpotNumComparedView.py", line 12, in get_spot_num_compard
    search_keys = list(request.POST['regions']);
UnboundLocalError: local variable 'list' referenced before assignment
[2018-10-15 14:26:16,258] [ERROR] "POST /api/spotnumcompared HTTP/1.1" 500 17351
[2018-10-15 14:31:24,998] [ERROR] Internal Server Error: /api/spotnumcompared
Traceback (most recent call last):
  File "E:\Anaconda\envs\en1\lib\site-packages\django\core\handlers\exception.py", line 35, in inner
    response = get_response(request)
  File "E:\Anaconda\envs\en1\lib\site-packages\django\core\handlers\base.py", line 128, in _get_response
    response = self.process_exception_by_middleware(e, request)
  File "E:\Anaconda\envs\en1\lib\site-packages\django\core\handlers\base.py", line 126, in _get_response
    response = wrapped_callback(request, *callback_args, **callback_kwargs)
  File "E:\Anaconda\envs\en1\lib\site-packages\django\views\decorators\csrf.py", line 54, in wrapped_view
    return view_func(*args, **kwargs)
  File "E:\Anaconda\envs\en1\lib\site-packages\django\views\generic\base.py", line 69, in view
    return self.dispatch(request, *args, **kwargs)
  File "E:\Anaconda\envs\en1\lib\site-packages\rest_framework\views.py", line 483, in dispatch
    response = self.handle_exception(exc)
  File "E:\Anaconda\envs\en1\lib\site-packages\rest_framework\views.py", line 443, in handle_exception
    self.raise_uncaught_exception(exc)
  File "E:\Anaconda\envs\en1\lib\site-packages\rest_framework\views.py", line 480, in dispatch
    response = handler(request, *args, **kwargs)
  File "D:\资料\GitHub\TourCommentApiPro\TourCommentApi\TourCommentApi\Views\SpotNumComparedView.py", line 73, in post
    return get_spot_num_compard(request);
  File "D:\资料\GitHub\TourCommentApiPro\TourCommentApi\TourCommentApi\Views\SpotNumComparedView.py", line 15, in get_spot_num_compard
    websites = eval((request.POST.getlist('websites'))[0]);
  File "<string>", line 1
    ['携程'']
          ^
SyntaxError: EOL while scanning string literal
[2018-10-15 14:31:25,451] [ERROR] "POST /api/spotnumcompared HTTP/1.1" 500 17349
[2018-10-15 14:31:43,377] [INFO] "POST /api/spotnumcompared HTTP/1.1" 200 196
[2018-10-15 14:33:52,400] [ERROR] Internal Server Error: /api/spotnumcompared
Traceback (most recent call last):
  File "E:\Anaconda\envs\en1\lib\site-packages\django\core\handlers\exception.py", line 35, in inner
    response = get_response(request)
  File "E:\Anaconda\envs\en1\lib\site-packages\django\core\handlers\base.py", line 128, in _get_response
    response = self.process_exception_by_middleware(e, request)
  File "E:\Anaconda\envs\en1\lib\site-packages\django\core\handlers\base.py", line 126, in _get_response
    response = wrapped_callback(request, *callback_args, **callback_kwargs)
  File "E:\Anaconda\envs\en1\lib\site-packages\django\views\decorators\csrf.py", line 54, in wrapped_view
    return view_func(*args, **kwargs)
  File "E:\Anaconda\envs\en1\lib\site-packages\django\views\generic\base.py", line 69, in view
    return self.dispatch(request, *args, **kwargs)
  File "E:\Anaconda\envs\en1\lib\site-packages\rest_framework\views.py", line 483, in dispatch
    response = self.handle_exception(exc)
  File "E:\Anaconda\envs\en1\lib\site-packages\rest_framework\views.py", line 443, in handle_exception
    self.raise_uncaught_exception(exc)
  File "E:\Anaconda\envs\en1\lib\site-packages\rest_framework\views.py", line 480, in dispatch
    response = handler(request, *args, **kwargs)
  File "D:\资料\GitHub\TourCommentApiPro\TourCommentApi\TourCommentApi\Views\SpotNumComparedView.py", line 73, in post
    return get_spot_num_compard(request);
  File "D:\资料\GitHub\TourCommentApiPro\TourCommentApi\TourCommentApi\Views\SpotNumComparedView.py", line 15, in get_spot_num_compard
    websites = eval((request.POST.getlist('websites'))[0]);
  File "<string>", line 1
    ['携程','去哪儿','大众点评'']
                       ^
SyntaxError: EOL while scanning string literal
[2018-10-15 14:33:52,684] [ERROR] "POST /api/spotnumcompared HTTP/1.1" 500 17385
[2018-10-15 14:34:19,093] [INFO] "POST /api/spotnumcompared HTTP/1.1" 200 615
[2018-10-15 14:36:04,035] [INFO] "POST /api/spotnumcompared HTTP/1.1" 200 1515
[2018-10-15 14:40:13,898] [INFO] "POST /api/spotnumcompared HTTP/1.1" 200 1997
[2018-10-15 14:43:30,487] [INFO] "POST /api/spotnumcompared HTTP/1.1" 200 1997
[2018-10-15 15:34:37,103] [ERROR] Internal Server Error: /api/spotnumcompared
Traceback (most recent call last):
  File "E:\Anaconda\envs\en1\lib\site-packages\django\core\handlers\exception.py", line 35, in inner
    response = get_response(request)
  File "E:\Anaconda\envs\en1\lib\site-packages\django\core\handlers\base.py", line 128, in _get_response
    response = self.process_exception_by_middleware(e, request)
  File "E:\Anaconda\envs\en1\lib\site-packages\django\core\handlers\base.py", line 126, in _get_response
    response = wrapped_callback(request, *callback_args, **callback_kwargs)
  File "E:\Anaconda\envs\en1\lib\site-packages\django\views\decorators\csrf.py", line 54, in wrapped_view
    return view_func(*args, **kwargs)
  File "E:\Anaconda\envs\en1\lib\site-packages\django\views\generic\base.py", line 69, in view
    return self.dispatch(request, *args, **kwargs)
  File "E:\Anaconda\envs\en1\lib\site-packages\rest_framework\views.py", line 483, in dispatch
    response = self.handle_exception(exc)
  File "E:\Anaconda\envs\en1\lib\site-packages\rest_framework\views.py", line 443, in handle_exception
    self.raise_uncaught_exception(exc)
  File "E:\Anaconda\envs\en1\lib\site-packages\rest_framework\views.py", line 480, in dispatch
    response = handler(request, *args, **kwargs)
  File "D:\资料\GitHub\TourCommentApiPro\TourCommentApi\TourCommentApi\Views\SpotNumComparedView.py", line 71, in post
    return get_spot_num_compard(request);
  File "D:\资料\GitHub\TourCommentApiPro\TourCommentApi\TourCommentApi\Views\SpotNumComparedView.py", line 37, in get_spot_num_compard
    comments = comment.objects(data_website=website, data_region__contains=region, comment_month=time);
  File "E:\Anaconda\envs\en1\lib\site-packages\mongoengine\queryset\manager.py", line 37, in __get__
    queryset = queryset_class(owner, owner._get_collection())
  File "E:\Anaconda\envs\en1\lib\site-packages\mongoengine\document.py", line 190, in _get_collection
    db = cls._get_db()
  File "E:\Anaconda\envs\en1\lib\site-packages\mongoengine\document.py", line 179, in _get_db
    return get_db(cls._meta.get('db_alias', DEFAULT_CONNECTION_NAME))
  File "E:\Anaconda\envs\en1\lib\site-packages\mongoengine\connection.py", line 236, in get_db
    db.authenticate(conn_settings['username'], conn_settings['password'], **auth_kwargs)
  File "E:\Anaconda\envs\en1\lib\site-packages\pymongo\database.py", line 1048, in authenticate
    connect=True)
  File "E:\Anaconda\envs\en1\lib\site-packages\pymongo\mongo_client.py", line 500, in _cache_credentials
    writable_preferred_server_selector)
  File "E:\Anaconda\envs\en1\lib\site-packages\pymongo\topology.py", line 214, in select_server
    address))
  File "E:\Anaconda\envs\en1\lib\site-packages\pymongo\topology.py", line 189, in select_servers
    self._error_message(selector))
pymongo.errors.ServerSelectionTimeoutError: 120.55.59.187:28117: [WinError 10065] 套接字操作尝试一个无法连接的主机。
[2018-10-15 15:34:37,694] [ERROR] "POST /api/spotnumcompared HTTP/1.1" 500 18772
[2018-10-15 15:56:45,533] [ERROR] Internal Server Error: /api/spotnumcompared
Traceback (most recent call last):
  File "E:\Anaconda\envs\en1\lib\site-packages\django\core\handlers\exception.py", line 35, in inner
    response = get_response(request)
  File "E:\Anaconda\envs\en1\lib\site-packages\django\core\handlers\base.py", line 128, in _get_response
    response = self.process_exception_by_middleware(e, request)
  File "E:\Anaconda\envs\en1\lib\site-packages\django\core\handlers\base.py", line 126, in _get_response
    response = wrapped_callback(request, *callback_args, **callback_kwargs)
  File "E:\Anaconda\envs\en1\lib\site-packages\django\views\decorators\csrf.py", line 54, in wrapped_view
    return view_func(*args, **kwargs)
  File "E:\Anaconda\envs\en1\lib\site-packages\django\views\generic\base.py", line 69, in view
    return self.dispatch(request, *args, **kwargs)
  File "E:\Anaconda\envs\en1\lib\site-packages\rest_framework\views.py", line 483, in dispatch
    response = self.handle_exception(exc)
  File "E:\Anaconda\envs\en1\lib\site-packages\rest_framework\views.py", line 443, in handle_exception
    self.raise_uncaught_exception(exc)
  File "E:\Anaconda\envs\en1\lib\site-packages\rest_framework\views.py", line 480, in dispatch
    response = handler(request, *args, **kwargs)
  File "D:\资料\GitHub\TourCommentApiPro\TourCommentApi\TourCommentApi\Views\SpotNumComparedView.py", line 72, in post
    return get_spot_num_compard(request);
  File "D:\资料\GitHub\TourCommentApiPro\TourCommentApi\TourCommentApi\Views\SpotNumComparedView.py", line 38, in get_spot_num_compard
    rcomments = comments.objects(data_website=website, data_region__contains=region, comment_month=time);
AttributeError: 'function' object has no attribute 'objects'
[2018-10-15 15:56:53,392] [ERROR] "POST /api/spotnumcompared HTTP/1.1" 500 17448
[2018-10-15 15:57:20,348] [ERROR] Internal Server Error: /api/spotnumcompared
Traceback (most recent call last):
  File "E:\Anaconda\envs\en1\lib\site-packages\django\core\handlers\exception.py", line 35, in inner
    response = get_response(request)
  File "E:\Anaconda\envs\en1\lib\site-packages\django\core\handlers\base.py", line 128, in _get_response
    response = self.process_exception_by_middleware(e, request)
  File "E:\Anaconda\envs\en1\lib\site-packages\django\core\handlers\base.py", line 126, in _get_response
    response = wrapped_callback(request, *callback_args, **callback_kwargs)
  File "E:\Anaconda\envs\en1\lib\site-packages\django\views\decorators\csrf.py", line 54, in wrapped_view
    return view_func(*args, **kwargs)
  File "E:\Anaconda\envs\en1\lib\site-packages\django\views\generic\base.py", line 69, in view
    return self.dispatch(request, *args, **kwargs)
  File "E:\Anaconda\envs\en1\lib\site-packages\rest_framework\views.py", line 483, in dispatch
    response = self.handle_exception(exc)
  File "E:\Anaconda\envs\en1\lib\site-packages\rest_framework\views.py", line 443, in handle_exception
    self.raise_uncaught_exception(exc)
  File "E:\Anaconda\envs\en1\lib\site-packages\rest_framework\views.py", line 480, in dispatch
    response = handler(request, *args, **kwargs)
  File "D:\资料\GitHub\TourCommentApiPro\TourCommentApi\TourCommentApi\Views\SpotNumComparedView.py", line 72, in post
    return get_spot_num_compard(request);
  File "D:\资料\GitHub\TourCommentApiPro\TourCommentApi\TourCommentApi\Views\SpotNumComparedView.py", line 38, in get_spot_num_compard
    rcomments = comments.objects(data_website=website, data_region__contains=region, comment_month=time);
AttributeError: 'QuerySet' object has no attribute 'objects'
[2018-10-15 15:57:28,241] [ERROR] "POST /api/spotnumcompared HTTP/1.1" 500 17447
[2018-10-15 16:00:28,158] [ERROR] Internal Server Error: /api/spotnumcompared
Traceback (most recent call last):
  File "E:\Anaconda\envs\en1\lib\site-packages\django\core\handlers\exception.py", line 35, in inner
    response = get_response(request)
  File "E:\Anaconda\envs\en1\lib\site-packages\django\core\handlers\base.py", line 128, in _get_response
    response = self.process_exception_by_middleware(e, request)
  File "E:\Anaconda\envs\en1\lib\site-packages\django\core\handlers\base.py", line 126, in _get_response
    response = wrapped_callback(request, *callback_args, **callback_kwargs)
  File "E:\Anaconda\envs\en1\lib\site-packages\django\views\decorators\csrf.py", line 54, in wrapped_view
    return view_func(*args, **kwargs)
  File "E:\Anaconda\envs\en1\lib\site-packages\django\views\generic\base.py", line 69, in view
    return self.dispatch(request, *args, **kwargs)
  File "E:\Anaconda\envs\en1\lib\site-packages\rest_framework\views.py", line 483, in dispatch
    response = self.handle_exception(exc)
  File "E:\Anaconda\envs\en1\lib\site-packages\rest_framework\views.py", line 443, in handle_exception
    self.raise_uncaught_exception(exc)
  File "E:\Anaconda\envs\en1\lib\site-packages\rest_framework\views.py", line 480, in dispatch
    response = handler(request, *args, **kwargs)
  File "D:\资料\GitHub\TourCommentApiPro\TourCommentApi\TourCommentApi\Views\SpotNumComparedView.py", line 72, in post
    return get_spot_num_compard(request);
  File "D:\资料\GitHub\TourCommentApiPro\TourCommentApi\TourCommentApi\Views\SpotNumComparedView.py", line 12, in get_spot_num_compard
    search_keys = eval((request.POST.getlist('spots'))[0]);
  File "<string>", line 1
    ['西湖‘]
         ^
SyntaxError: EOL while scanning string literal
[2018-10-15 16:00:28,451] [ERROR] "POST /api/spotnumcompared HTTP/1.1" 500 17392
[2018-10-15 16:00:46,820] [ERROR] Internal Server Error: /api/spotnumcompared
Traceback (most recent call last):
  File "E:\Anaconda\envs\en1\lib\site-packages\django\core\handlers\exception.py", line 35, in inner
    response = get_response(request)
  File "E:\Anaconda\envs\en1\lib\site-packages\django\core\handlers\base.py", line 128, in _get_response
    response = self.process_exception_by_middleware(e, request)
  File "E:\Anaconda\envs\en1\lib\site-packages\django\core\handlers\base.py", line 126, in _get_response
    response = wrapped_callback(request, *callback_args, **callback_kwargs)
  File "E:\Anaconda\envs\en1\lib\site-packages\django\views\decorators\csrf.py", line 54, in wrapped_view
    return view_func(*args, **kwargs)
  File "E:\Anaconda\envs\en1\lib\site-packages\django\views\generic\base.py", line 69, in view
    return self.dispatch(request, *args, **kwargs)
  File "E:\Anaconda\envs\en1\lib\site-packages\rest_framework\views.py", line 483, in dispatch
    response = self.handle_exception(exc)
  File "E:\Anaconda\envs\en1\lib\site-packages\rest_framework\views.py", line 443, in handle_exception
    self.raise_uncaught_exception(exc)
  File "E:\Anaconda\envs\en1\lib\site-packages\rest_framework\views.py", line 480, in dispatch
    response = handler(request, *args, **kwargs)
  File "D:\资料\GitHub\TourCommentApiPro\TourCommentApi\TourCommentApi\Views\SpotNumComparedView.py", line 72, in post
    return get_spot_num_compard(request);
  File "D:\资料\GitHub\TourCommentApiPro\TourCommentApi\TourCommentApi\Views\SpotNumComparedView.py", line 38, in get_spot_num_compard
    rcomments = comments.objects( data_region__contains=region, comment_month=time);
AttributeError: 'QuerySet' object has no attribute 'objects'
[2018-10-15 16:00:54,644] [ERROR] "POST /api/spotnumcompared HTTP/1.1" 500 17418
[2018-10-15 16:02:06,097] [ERROR] Internal Server Error: /api/spotnumcompared
Traceback (most recent call last):
  File "E:\Anaconda\envs\en1\lib\site-packages\django\core\handlers\exception.py", line 35, in inner
    response = get_response(request)
  File "E:\Anaconda\envs\en1\lib\site-packages\django\core\handlers\base.py", line 128, in _get_response
    response = self.process_exception_by_middleware(e, request)
  File "E:\Anaconda\envs\en1\lib\site-packages\django\core\handlers\base.py", line 126, in _get_response
    response = wrapped_callback(request, *callback_args, **callback_kwargs)
  File "E:\Anaconda\envs\en1\lib\site-packages\django\views\decorators\csrf.py", line 54, in wrapped_view
    return view_func(*args, **kwargs)
  File "E:\Anaconda\envs\en1\lib\site-packages\django\views\generic\base.py", line 69, in view
    return self.dispatch(request, *args, **kwargs)
  File "E:\Anaconda\envs\en1\lib\site-packages\rest_framework\views.py", line 483, in dispatch
    response = self.handle_exception(exc)
  File "E:\Anaconda\envs\en1\lib\site-packages\rest_framework\views.py", line 443, in handle_exception
    self.raise_uncaught_exception(exc)
  File "E:\Anaconda\envs\en1\lib\site-packages\rest_framework\views.py", line 480, in dispatch
    response = handler(request, *args, **kwargs)
  File "D:\资料\GitHub\TourCommentApiPro\TourCommentApi\TourCommentApi\Views\SpotNumComparedView.py", line 73, in post
    return get_spot_num_compard(request);
  File "D:\资料\GitHub\TourCommentApiPro\TourCommentApi\TourCommentApi\Views\SpotNumComparedView.py", line 39, in get_spot_num_compard
    rcomments = comments.objects( data_region__contains=region, comment_month=time);
AttributeError: 'QuerySet' object has no attribute 'objects'
[2018-10-15 16:02:14,195] [ERROR] "POST /api/spotnumcompared HTTP/1.1" 500 17418
[2018-10-15 16:02:58,607] [ERROR] Internal Server Error: /api/spotnumcompared
Traceback (most recent call last):
  File "E:\Anaconda\envs\en1\lib\site-packages\django\core\handlers\exception.py", line 35, in inner
    response = get_response(request)
  File "E:\Anaconda\envs\en1\lib\site-packages\django\core\handlers\base.py", line 128, in _get_response
    response = self.process_exception_by_middleware(e, request)
  File "E:\Anaconda\envs\en1\lib\site-packages\django\core\handlers\base.py", line 126, in _get_response
    response = wrapped_callback(request, *callback_args, **callback_kwargs)
  File "E:\Anaconda\envs\en1\lib\site-packages\django\views\decorators\csrf.py", line 54, in wrapped_view
    return view_func(*args, **kwargs)
  File "E:\Anaconda\envs\en1\lib\site-packages\django\views\generic\base.py", line 69, in view
    return self.dispatch(request, *args, **kwargs)
  File "E:\Anaconda\envs\en1\lib\site-packages\rest_framework\views.py", line 483, in dispatch
    response = self.handle_exception(exc)
  File "E:\Anaconda\envs\en1\lib\site-packages\rest_framework\views.py", line 443, in handle_exception
    self.raise_uncaught_exception(exc)
  File "E:\Anaconda\envs\en1\lib\site-packages\rest_framework\views.py", line 480, in dispatch
    response = handler(request, *args, **kwargs)
  File "D:\资料\GitHub\TourCommentApiPro\TourCommentApi\TourCommentApi\Views\SpotNumComparedView.py", line 73, in post
    return get_spot_num_compard(request);
  File "D:\资料\GitHub\TourCommentApiPro\TourCommentApi\TourCommentApi\Views\SpotNumComparedView.py", line 39, in get_spot_num_compard
    rcomments = rrcomments.objects(data_region__contains=region, comment_month=time);
AttributeError: 'QuerySet' object has no attribute 'objects'
[2018-10-15 16:03:06,618] [ERROR] "POST /api/spotnumcompared HTTP/1.1" 500 17419
[2018-10-15 16:03:55,722] [INFO] "POST /api/spotnumcompared HTTP/1.1" 200 686
[2018-10-15 16:07:37,000] [INFO] "POST /api/spotnumcompared HTTP/1.1" 200 1676
[2018-10-15 18:00:30,508] [INFO] "GET /api/jingqulist HTTP/1.1" 200 3324
[2018-10-15 18:00:31,625] [WARNING] Not Found: /favicon.ico
[2018-10-15 18:00:31,630] [WARNING] "GET /favicon.ico HTTP/1.1" 404 2867
[2018-10-15 18:01:00,580] [INFO] "GET /api/jingqulist HTTP/1.1" 200 3324
[2018-10-15 18:01:44,793] [INFO] "GET /api/jingqulist HTTP/1.1" 200 3324
[2018-10-15 18:03:48,750] [INFO] "GET /api/jingqulist HTTP/1.1" 200 3324
[2018-10-15 18:06:26,226] [INFO] "GET /api/jingqulist HTTP/1.1" 200 3324
[2018-10-15 18:11:40,829] [INFO] "GET /api/jingqulist HTTP/1.1" 200 3324
[2018-10-15 18:15:53,747] [INFO] "GET /api/jingqulist HTTP/1.1" 200 3324
[2018-10-15 18:17:38,423] [INFO] "GET /api/jingqulist HTTP/1.1" 200 3324
[2018-10-15 18:23:46,598] [INFO] "GET /api/jingqulist HTTP/1.1" 200 3324
[2018-10-15 18:28:13,627] [INFO] "GET /api/jingqulist HTTP/1.1" 200 3324
[2018-10-15 18:28:37,393] [INFO] "GET /api/jingqulist HTTP/1.1" 200 3324
[2018-10-15 18:32:12,294] [INFO] "GET /api/jingqulist HTTP/1.1" 200 3324
[2018-10-15 18:32:35,255] [INFO] "GET /api/jingqulist HTTP/1.1" 200 3324
[2018-10-15 18:45:56,703] [INFO] "GET /api/jingqulist HTTP/1.1" 200 3324
[2018-10-15 18:46:19,883] [INFO] "GET /api/jingqulist HTTP/1.1" 200 3324
[2018-10-15 18:47:20,267] [INFO] "GET /api/jingqulist HTTP/1.1" 200 3324
[2018-10-15 18:48:11,459] [INFO] "GET /api/jingqulist HTTP/1.1" 200 3324
[2018-10-15 19:01:41,412] [INFO] "GET /api/jingqulist HTTP/1.1" 200 48
[2018-10-15 19:01:51,461] [INFO] "GET /api/jingqulist HTTP/1.1" 200 48
[2018-10-15 19:01:53,189] [INFO] "GET /api/jingqulist HTTP/1.1" 200 48
[2018-10-15 19:02:19,624] [INFO] "GET /api/jingqulist HTTP/1.1" 200 48
[2018-10-15 19:02:30,699] [INFO] "GET /api/jingqulist HTTP/1.1" 200 48
[2018-10-15 19:04:12,967] [INFO] This is an errormsg
[2018-10-15 19:04:12,972] [INFO] "GET /api/jingqulist HTTP/1.1" 200 57
[2018-10-15 19:16:46,555] [INFO] "GET /api/jingqulist HTTP/1.1" 200 59086
[2018-10-15 19:17:45,017] [INFO] "GET /api/jingqulist HTTP/1.1" 200 3324
[2018-10-15 19:19:34,213] [INFO] "GET /api/jingqulist HTTP/1.1" 200 2644
[2018-10-15 19:27:18,648] [INFO] "GET /api/jingqulist HTTP/1.1" 200 3220
[2018-10-15 19:33:02,725] [INFO] This is an errormsg
[2018-10-15 19:33:02,728] [INFO] "GET /api/jingqulist HTTP/1.1" 200 57
[2018-10-15 19:34:35,422] [INFO] This is an errormsg
[2018-10-15 19:34:35,428] [INFO] "GET /api/jingqulist HTTP/1.1" 200 57
[2018-10-15 19:36:06,860] [INFO] "GET /api/jingqulist HTTP/1.1" 200 3094
[2018-10-15 19:36:39,435] [INFO] "GET /api/jingqulist HTTP/1.1" 200 3094
[2018-10-15 19:36:41,572] [INFO] "GET /api/jingqulist HTTP/1.1" 200 3094
[2018-10-15 19:36:53,784] [INFO] "GET /api/jingqulist HTTP/1.1" 200 3094
[2018-10-15 19:36:54,890] [INFO] "GET /api/jingqulist HTTP/1.1" 200 3094
[2018-10-15 19:36:55,720] [INFO] "GET /api/jingqulist HTTP/1.1" 200 3094
[2018-10-15 19:36:56,490] [INFO] "GET /api/jingqulist HTTP/1.1" 200 3094
[2018-10-15 19:50:15,882] [INFO] This is an errormsg
[2018-10-15 19:50:15,884] [INFO] "GET /api/jingqulist HTTP/1.1" 200 57
[2018-10-15 19:58:30,914] [INFO] This is an errormsg
[2018-10-15 19:58:30,917] [INFO] "GET /api/jingqulist HTTP/1.1" 200 57
[2018-10-15 20:00:38,177] [INFO] This is an errormsg
[2018-10-15 20:00:38,179] [INFO] "GET /api/jingqulist HTTP/1.1" 200 57
[2018-10-15 20:03:33,637] [INFO] This is an errormsg
[2018-10-15 20:03:33,641] [INFO] "GET /api/jingqulist HTTP/1.1" 200 57
[2018-10-15 20:04:35,355] [INFO] This is an errormsg
[2018-10-15 20:04:35,360] [INFO] "GET /api/jingqulist HTTP/1.1" 200 57
[2018-10-15 20:06:15,952] [INFO] "GET /api/jingqulist HTTP/1.1" 200 2644
[2018-10-15 20:11:32,361] [INFO] This is an errormsg
[2018-10-15 20:11:32,364] [INFO] "GET /api/jingqulist HTTP/1.1" 200 57
[2018-10-15 20:14:55,790] [INFO] "GET /api/jingqulist HTTP/1.1" 200 3094
[2018-10-15 20:19:00,455] [INFO] "GET /api/jingqulist HTTP/1.1" 200 3076
[2018-10-15 20:21:40,770] [INFO] This is an errormsg
[2018-10-15 20:21:40,795] [INFO] "GET /api/jingqulist HTTP/1.1" 200 57
[2018-10-15 20:22:55,563] [INFO] "GET /api/jingqulist HTTP/1.1" 200 3076
[2018-10-15 20:23:15,109] [INFO] "GET /api/jingqulist HTTP/1.1" 200 3076
[2018-10-15 20:23:31,065] [INFO] "GET /api/jingqulist HTTP/1.1" 200 3076
[2018-10-15 12:39:42,064] [INFO] "GET /api/jingqulist HTTP/1.1" 200 3076
[2018-10-15 12:39:42,197] [WARNING] Not Found: /favicon.ico
[2018-10-15 12:39:42,197] [WARNING] "GET /favicon.ico HTTP/1.1" 404 2867
[2018-10-15 13:04:44,653] [INFO] "GET /api/jingqulist HTTP/1.1" 200 3076
[2018-10-15 13:18:41,721] [INFO] "GET /api/jingqulist HTTP/1.1" 200 3076
[2018-10-15 13:24:48,629] [INFO] "GET /api/jingqulist HTTP/1.1" 200 3076
[2018-10-15 14:58:01,271] [INFO] This is an errormsg
[2018-10-15 14:58:01,289] [INFO] "GET /api/jingqulist HTTP/1.1" 200 57
[2018-10-15 14:58:01,367] [WARNING] Not Found: /favicon.ico
[2018-10-15 14:58:01,368] [WARNING] "GET /favicon.ico HTTP/1.1" 404 2867
[2018-10-15 14:59:50,915] [INFO] This is an errormsg
[2018-10-15 14:59:50,916] [INFO] "GET /api/jingqulist HTTP/1.1" 200 57
>>>>>>> 7e6f8e4230555896acacc7a72ae975759fb7d685
[2018-10-17 08:41:09,953] [WARNING] "GET /api/spotlist HTTP/1.1" 401 9379
[2018-10-17 08:41:10,494] [INFO] "GET /static/rest_framework/css/bootstrap-tweaks.css HTTP/1.1" 200 3385
[2018-10-17 08:41:10,644] [INFO] "GET /static/rest_framework/css/bootstrap.min.css HTTP/1.1" 200 121200
[2018-10-17 08:41:10,792] [INFO] "GET /static/rest_framework/css/prettify.css HTTP/1.1" 200 817
[2018-10-17 08:41:10,802] [INFO] "GET /static/rest_framework/js/ajax-form.js HTTP/1.1" 200 3597
[2018-10-17 08:41:10,807] [INFO] "GET /static/rest_framework/css/default.css HTTP/1.1" 200 1131
[2018-10-17 08:41:10,934] [INFO] "GET /static/rest_framework/js/jquery-3.3.1.min.js HTTP/1.1" 200 86927
[2018-10-17 08:41:11,105] [INFO] "GET /static/rest_framework/js/bootstrap.min.js HTTP/1.1" 200 37045
[2018-10-17 08:41:11,166] [INFO] "GET /static/rest_framework/js/prettify-min.js HTTP/1.1" 200 13632
[2018-10-17 08:41:11,689] [INFO] "GET /static/rest_framework/img/grid.png HTTP/1.1" 200 1458
[2018-10-17 08:41:11,704] [INFO] "GET /static/rest_framework/js/default.js HTTP/1.1" 200 1262
[2018-10-17 08:41:11,705] [INFO] "GET /static/rest_framework/js/csrf.js HTTP/1.1" 200 1735
[2018-10-17 08:41:12,732] [WARNING] Not Found: /favicon.ico
[2018-10-17 08:41:12,735] [WARNING] "GET /favicon.ico HTTP/1.1" 404 2912
[2018-10-17 08:41:18,797] [WARNING] "GET /api/spotlist HTTP/1.1" 401 9379
[2018-10-17 08:41:21,699] [WARNING] "GET /api/spotlist?format=json HTTP/1.1" 401 58
[2018-10-17 08:41:23,985] [WARNING] "GET /api/spotlist HTTP/1.1" 401 9379
[2018-10-17 09:32:27,188] [INFO] This is an errormsg
[2018-10-17 09:32:27,193] [INFO] "GET /api/qdhspotlist HTTP/1.1" 200 52
[2018-10-17 09:34:06,985] [INFO] This is an errormsg
[2018-10-17 09:34:06,991] [INFO] "GET /api/qdhspotlist HTTP/1.1" 200 52
[2018-10-17 09:36:21,341] [INFO] This is an errormsg
[2018-10-17 09:36:21,346] [INFO] "GET /api/qdhspotlist HTTP/1.1" 200 52
[2018-10-17 09:38:17,730] [INFO] This is an errormsg
[2018-10-17 09:38:17,735] [INFO] "GET /api/qdhspotlist HTTP/1.1" 200 52
[2018-10-17 09:39:42,405] [INFO] This is an errormsg
[2018-10-17 09:39:42,413] [INFO] "GET /api/qdhspotlist HTTP/1.1" 200 52
[2018-10-17 09:41:42,517] [INFO] "GET /api/qdhspotlist HTTP/1.1" 200 3677
[2018-10-17 09:41:58,568] [INFO] "GET /api/qdhspotlist HTTP/1.1" 200 3677
[2018-10-17 09:55:36,739] [INFO] "GET /api/spotlist HTTP/1.1" 200 3193
[2018-10-17 09:55:46,542] [INFO] "GET /api/qdhspotlist HTTP/1.1" 200 3677
[2018-10-17 10:20:35,816] [WARNING] Not Found: /api/spotnumcompared
[2018-10-17 10:20:35,822] [WARNING] "POST /api/spotnumcompared HTTP/1.1" 404 2937
[2018-10-17 10:21:42,311] [INFO] This is an errormsg
[2018-10-17 10:21:42,315] [INFO] "POST /api/spotcompared HTTP/1.1" 200 47
[2018-10-17 10:26:39,396] [INFO] This is an errormsg
[2018-10-17 10:26:39,400] [INFO] "POST /api/spotcompared HTTP/1.1" 200 47
[2018-10-17 10:29:25,366] [INFO] This is an errormsg
[2018-10-17 10:29:25,371] [INFO] "POST /api/spotcompared HTTP/1.1" 200 47
[2018-10-17 10:31:40,190] [INFO] This is an errormsg
[2018-10-17 10:31:40,195] [INFO] "POST /api/spotcompared HTTP/1.1" 200 47
[2018-10-17 10:34:17,283] [INFO] This is an errormsg
[2018-10-17 10:34:17,291] [INFO] "POST /api/spotcompared HTTP/1.1" 200 47
[2018-10-17 10:36:48,007] [ERROR] Internal Server Error: /api/spotcompared
Traceback (most recent call last):
  File "E:\Anaconda\envs\en1\lib\site-packages\django\core\handlers\exception.py", line 35, in inner
    response = get_response(request)
  File "E:\Anaconda\envs\en1\lib\site-packages\django\core\handlers\base.py", line 128, in _get_response
    response = self.process_exception_by_middleware(e, request)
  File "E:\Anaconda\envs\en1\lib\site-packages\django\core\handlers\base.py", line 126, in _get_response
    response = wrapped_callback(request, *callback_args, **callback_kwargs)
  File "E:\Anaconda\envs\en1\lib\site-packages\django\views\decorators\csrf.py", line 54, in wrapped_view
    return view_func(*args, **kwargs)
  File "E:\Anaconda\envs\en1\lib\site-packages\django\views\generic\base.py", line 69, in view
    return self.dispatch(request, *args, **kwargs)
  File "E:\Anaconda\envs\en1\lib\site-packages\rest_framework\views.py", line 483, in dispatch
    response = self.handle_exception(exc)
  File "E:\Anaconda\envs\en1\lib\site-packages\rest_framework\views.py", line 443, in handle_exception
    self.raise_uncaught_exception(exc)
  File "E:\Anaconda\envs\en1\lib\site-packages\rest_framework\views.py", line 480, in dispatch
    response = handler(request, *args, **kwargs)
  File "D:\资料\GitHub\TourCommentApiPro\TourCommentApi\TourCommentApi\Views\SpotComparedView.py", line 86, in post
    return post_spot_compard(request);
  File "D:\资料\GitHub\TourCommentApiPro\TourCommentApi\TourCommentApi\Views\SpotComparedView.py", line 15, in post_spot_compard
    print(type(search_keys));
UnboundLocalError: local variable 'type' referenced before assignment
[2018-10-17 10:36:48,281] [ERROR] "POST /api/spotcompared HTTP/1.1" 500 16934
[2018-10-17 10:39:34,623] [ERROR] Internal Server Error: /api/spotcompared
Traceback (most recent call last):
  File "E:\Anaconda\envs\en1\lib\site-packages\django\core\handlers\exception.py", line 35, in inner
    response = get_response(request)
  File "E:\Anaconda\envs\en1\lib\site-packages\django\core\handlers\base.py", line 128, in _get_response
    response = self.process_exception_by_middleware(e, request)
  File "E:\Anaconda\envs\en1\lib\site-packages\django\core\handlers\base.py", line 126, in _get_response
    response = wrapped_callback(request, *callback_args, **callback_kwargs)
  File "E:\Anaconda\envs\en1\lib\site-packages\django\views\decorators\csrf.py", line 54, in wrapped_view
    return view_func(*args, **kwargs)
  File "E:\Anaconda\envs\en1\lib\site-packages\django\views\generic\base.py", line 69, in view
    return self.dispatch(request, *args, **kwargs)
  File "E:\Anaconda\envs\en1\lib\site-packages\rest_framework\views.py", line 483, in dispatch
    response = self.handle_exception(exc)
  File "E:\Anaconda\envs\en1\lib\site-packages\rest_framework\views.py", line 443, in handle_exception
    self.raise_uncaught_exception(exc)
  File "E:\Anaconda\envs\en1\lib\site-packages\rest_framework\views.py", line 480, in dispatch
    response = handler(request, *args, **kwargs)
  File "D:\资料\GitHub\TourCommentApiPro\TourCommentApi\TourCommentApi\Views\SpotComparedView.py", line 86, in post
    return post_spot_compard(request);
  File "D:\资料\GitHub\TourCommentApiPro\TourCommentApi\TourCommentApi\Views\SpotComparedView.py", line 15, in post_spot_compard
    print(type(search_keys));
UnboundLocalError: local variable 'type' referenced before assignment
[2018-10-17 10:39:34,910] [ERROR] "POST /api/spotcompared HTTP/1.1" 500 16934
[2018-10-17 10:41:04,931] [ERROR] Internal Server Error: /api/spotcompared
Traceback (most recent call last):
  File "E:\Anaconda\envs\en1\lib\site-packages\django\core\handlers\exception.py", line 35, in inner
    response = get_response(request)
  File "E:\Anaconda\envs\en1\lib\site-packages\django\core\handlers\base.py", line 128, in _get_response
    response = self.process_exception_by_middleware(e, request)
  File "E:\Anaconda\envs\en1\lib\site-packages\django\core\handlers\base.py", line 126, in _get_response
    response = wrapped_callback(request, *callback_args, **callback_kwargs)
  File "E:\Anaconda\envs\en1\lib\site-packages\django\views\decorators\csrf.py", line 54, in wrapped_view
    return view_func(*args, **kwargs)
  File "E:\Anaconda\envs\en1\lib\site-packages\django\views\generic\base.py", line 69, in view
    return self.dispatch(request, *args, **kwargs)
  File "E:\Anaconda\envs\en1\lib\site-packages\rest_framework\views.py", line 483, in dispatch
    response = self.handle_exception(exc)
  File "E:\Anaconda\envs\en1\lib\site-packages\rest_framework\views.py", line 443, in handle_exception
    self.raise_uncaught_exception(exc)
  File "E:\Anaconda\envs\en1\lib\site-packages\rest_framework\views.py", line 480, in dispatch
    response = handler(request, *args, **kwargs)
  File "D:\资料\GitHub\TourCommentApiPro\TourCommentApi\TourCommentApi\Views\SpotComparedView.py", line 86, in post
    return post_spot_compard(request);
  File "D:\资料\GitHub\TourCommentApiPro\TourCommentApi\TourCommentApi\Views\SpotComparedView.py", line 20, in post_spot_compard
    websites =list(body['websites']);
UnboundLocalError: local variable 'list' referenced before assignment
[2018-10-17 10:41:05,235] [ERROR] "POST /api/spotcompared HTTP/1.1" 500 16941
[2018-10-17 10:44:02,601] [INFO] "POST /api/spotcompared HTTP/1.1" 200 595
[2018-10-17 10:44:47,007] [INFO] "POST /api/spotcompared HTTP/1.1" 200 595
[2018-10-17 11:16:42,347] [INFO] "POST /api/spotcompared HTTP/1.1" 200 595
[2018-10-17 11:17:32,128] [INFO] "POST /api/spotcompared HTTP/1.1" 200 595
[2018-10-17 11:19:57,056] [INFO] "POST /api/spotcompared HTTP/1.1" 200 595
[2018-10-17 11:21:40,405] [INFO] "POST /api/spotcompared HTTP/1.1" 200 732
[2018-10-17 14:22:54,004] [ERROR] Internal Server Error: /api/spotcompared
Traceback (most recent call last):
  File "E:\Anaconda\envs\en1\lib\site-packages\django\core\handlers\exception.py", line 35, in inner
    response = get_response(request)
  File "E:\Anaconda\envs\en1\lib\site-packages\django\core\handlers\base.py", line 128, in _get_response
    response = self.process_exception_by_middleware(e, request)
  File "E:\Anaconda\envs\en1\lib\site-packages\django\core\handlers\base.py", line 126, in _get_response
    response = wrapped_callback(request, *callback_args, **callback_kwargs)
  File "E:\Anaconda\envs\en1\lib\site-packages\django\views\decorators\csrf.py", line 54, in wrapped_view
    return view_func(*args, **kwargs)
  File "E:\Anaconda\envs\en1\lib\site-packages\django\views\generic\base.py", line 69, in view
    return self.dispatch(request, *args, **kwargs)
  File "E:\Anaconda\envs\en1\lib\site-packages\rest_framework\views.py", line 483, in dispatch
    response = self.handle_exception(exc)
  File "E:\Anaconda\envs\en1\lib\site-packages\rest_framework\views.py", line 443, in handle_exception
    self.raise_uncaught_exception(exc)
  File "E:\Anaconda\envs\en1\lib\site-packages\rest_framework\views.py", line 480, in dispatch
    response = handler(request, *args, **kwargs)
  File "D:\资料\GitHub\TourCommentApiPro\TourCommentApi\TourCommentApi\Views\SpotComparedView.py", line 92, in post
    return post_spot_compard(request);
  File "D:\资料\GitHub\TourCommentApiPro\TourCommentApi\TourCommentApi\Views\SpotComparedView.py", line 41, in post_spot_compard
    body = json.loads(request.body);
ValueError: Expected object or value
[2018-10-17 14:22:54,195] [ERROR] "POST /api/spotcompared HTTP/1.1" 500 16875
[2018-10-17 14:26:05,399] [ERROR] Internal Server Error: /api/spotcompared
Traceback (most recent call last):
  File "E:\Anaconda\envs\en1\lib\site-packages\django\core\handlers\exception.py", line 35, in inner
    response = get_response(request)
  File "E:\Anaconda\envs\en1\lib\site-packages\django\core\handlers\base.py", line 128, in _get_response
    response = self.process_exception_by_middleware(e, request)
  File "E:\Anaconda\envs\en1\lib\site-packages\django\core\handlers\base.py", line 126, in _get_response
    response = wrapped_callback(request, *callback_args, **callback_kwargs)
  File "E:\Anaconda\envs\en1\lib\site-packages\django\views\decorators\csrf.py", line 54, in wrapped_view
    return view_func(*args, **kwargs)
  File "E:\Anaconda\envs\en1\lib\site-packages\django\views\generic\base.py", line 69, in view
    return self.dispatch(request, *args, **kwargs)
  File "E:\Anaconda\envs\en1\lib\site-packages\rest_framework\views.py", line 483, in dispatch
    response = self.handle_exception(exc)
  File "E:\Anaconda\envs\en1\lib\site-packages\rest_framework\views.py", line 443, in handle_exception
    self.raise_uncaught_exception(exc)
  File "E:\Anaconda\envs\en1\lib\site-packages\rest_framework\views.py", line 480, in dispatch
    response = handler(request, *args, **kwargs)
  File "D:\资料\GitHub\TourCommentApiPro\TourCommentApi\TourCommentApi\Views\SpotComparedView.py", line 92, in post
    return post_spot_compard(request);
  File "D:\资料\GitHub\TourCommentApiPro\TourCommentApi\TourCommentApi\Views\SpotComparedView.py", line 41, in post_spot_compard
    body = json.loads(request.body);
ValueError: Expected object or value
[2018-10-17 14:26:05,601] [ERROR] "POST /api/spotcompared HTTP/1.1" 500 16874
[2018-10-17 14:26:44,912] [INFO] This is an errormsg
[2018-10-17 14:26:44,924] [INFO] "POST /api/spotcompared HTTP/1.1" 200 47
[2018-10-17 14:32:37,255] [INFO] "POST /api/spotcompared HTTP/1.1" 200 2492
[2018-10-17 14:33:03,071] [ERROR] Internal Server Error: /api/spotcompared
Traceback (most recent call last):
  File "E:\Anaconda\envs\en1\lib\site-packages\django\core\handlers\exception.py", line 35, in inner
    response = get_response(request)
  File "E:\Anaconda\envs\en1\lib\site-packages\django\core\handlers\base.py", line 128, in _get_response
    response = self.process_exception_by_middleware(e, request)
  File "E:\Anaconda\envs\en1\lib\site-packages\django\core\handlers\base.py", line 126, in _get_response
    response = wrapped_callback(request, *callback_args, **callback_kwargs)
  File "E:\Anaconda\envs\en1\lib\site-packages\django\views\decorators\csrf.py", line 54, in wrapped_view
    return view_func(*args, **kwargs)
  File "E:\Anaconda\envs\en1\lib\site-packages\django\views\generic\base.py", line 69, in view
    return self.dispatch(request, *args, **kwargs)
  File "E:\Anaconda\envs\en1\lib\site-packages\rest_framework\views.py", line 483, in dispatch
    response = self.handle_exception(exc)
  File "E:\Anaconda\envs\en1\lib\site-packages\rest_framework\views.py", line 443, in handle_exception
    self.raise_uncaught_exception(exc)
  File "E:\Anaconda\envs\en1\lib\site-packages\rest_framework\views.py", line 480, in dispatch
    response = handler(request, *args, **kwargs)
  File "D:\资料\GitHub\TourCommentApiPro\TourCommentApi\TourCommentApi\Views\SpotComparedView.py", line 94, in post
    return post_spot_compard(request);
  File "D:\资料\GitHub\TourCommentApiPro\TourCommentApi\TourCommentApi\Views\SpotComparedView.py", line 73, in post_spot_compard
    list = [get_website_data(website,time_search_key,time_list) for website in websites];
  File "D:\资料\GitHub\TourCommentApiPro\TourCommentApi\TourCommentApi\Views\SpotComparedView.py", line 73, in <listcomp>
    list = [get_website_data(website,time_search_key,time_list) for website in websites];
  File "D:\资料\GitHub\TourCommentApiPro\TourCommentApi\TourCommentApi\Views\SpotComparedView.py", line 32, in get_website_data
    yAxis = [get_region_data(website, region, time_search_key, time_list) for region in search_keys];
  File "D:\资料\GitHub\TourCommentApiPro\TourCommentApi\TourCommentApi\Views\SpotComparedView.py", line 32, in <listcomp>
    yAxis = [get_region_data(website, region, time_search_key, time_list) for region in search_keys];
  File "D:\资料\GitHub\TourCommentApiPro\TourCommentApi\TourCommentApi\Views\SpotComparedView.py", line 18, in get_region_data
    time_list];
  File "D:\资料\GitHub\TourCommentApiPro\TourCommentApi\TourCommentApi\Views\SpotComparedView.py", line 17, in <listcomp>
    (spot_website_comments_data[time_search_key] == time)].iloc[:, 0].size) for time in
  File "E:\Anaconda\envs\en1\lib\site-packages\pandas\core\ops.py", line 1283, in wrapper
    res = na_op(values, other)
  File "E:\Anaconda\envs\en1\lib\site-packages\pandas\core\ops.py", line 1143, in na_op
    result = _comp_method_OBJECT_ARRAY(op, x, y)
  File "E:\Anaconda\envs\en1\lib\site-packages\pandas\core\ops.py", line 1120, in _comp_method_OBJECT_ARRAY
    result = libops.vec_compare(x, y, op)
  File "pandas/_libs/ops.pyx", line 128, in pandas._libs.ops.vec_compare
ValueError: Arrays were different lengths: 3419 vs 9
[2018-10-17 14:33:04,522] [ERROR] "POST /api/spotcompared HTTP/1.1" 500 18497
[2018-10-17 14:33:18,759] [ERROR] Internal Server Error: /api/spotcompared
Traceback (most recent call last):
  File "E:\Anaconda\envs\en1\lib\site-packages\django\core\handlers\exception.py", line 35, in inner
    response = get_response(request)
  File "E:\Anaconda\envs\en1\lib\site-packages\django\core\handlers\base.py", line 128, in _get_response
    response = self.process_exception_by_middleware(e, request)
  File "E:\Anaconda\envs\en1\lib\site-packages\django\core\handlers\base.py", line 126, in _get_response
    response = wrapped_callback(request, *callback_args, **callback_kwargs)
  File "E:\Anaconda\envs\en1\lib\site-packages\django\views\decorators\csrf.py", line 54, in wrapped_view
    return view_func(*args, **kwargs)
  File "E:\Anaconda\envs\en1\lib\site-packages\django\views\generic\base.py", line 69, in view
    return self.dispatch(request, *args, **kwargs)
  File "E:\Anaconda\envs\en1\lib\site-packages\rest_framework\views.py", line 483, in dispatch
    response = self.handle_exception(exc)
  File "E:\Anaconda\envs\en1\lib\site-packages\rest_framework\views.py", line 443, in handle_exception
    self.raise_uncaught_exception(exc)
  File "E:\Anaconda\envs\en1\lib\site-packages\rest_framework\views.py", line 480, in dispatch
    response = handler(request, *args, **kwargs)
  File "D:\资料\GitHub\TourCommentApiPro\TourCommentApi\TourCommentApi\Views\SpotComparedView.py", line 94, in post
    return post_spot_compard(request);
  File "D:\资料\GitHub\TourCommentApiPro\TourCommentApi\TourCommentApi\Views\SpotComparedView.py", line 73, in post_spot_compard
    list = [get_website_data(website,time_search_key,time_list) for website in websites];
  File "D:\资料\GitHub\TourCommentApiPro\TourCommentApi\TourCommentApi\Views\SpotComparedView.py", line 73, in <listcomp>
    list = [get_website_data(website,time_search_key,time_list) for website in websites];
  File "D:\资料\GitHub\TourCommentApiPro\TourCommentApi\TourCommentApi\Views\SpotComparedView.py", line 32, in get_website_data
    yAxis = [get_region_data(website, region, time_search_key, time_list) for region in search_keys];
  File "D:\资料\GitHub\TourCommentApiPro\TourCommentApi\TourCommentApi\Views\SpotComparedView.py", line 32, in <listcomp>
    yAxis = [get_region_data(website, region, time_search_key, time_list) for region in search_keys];
  File "D:\资料\GitHub\TourCommentApiPro\TourCommentApi\TourCommentApi\Views\SpotComparedView.py", line 18, in get_region_data
    time_list];
  File "D:\资料\GitHub\TourCommentApiPro\TourCommentApi\TourCommentApi\Views\SpotComparedView.py", line 17, in <listcomp>
    (spot_website_comments_data[time_search_key] == time)].iloc[:, 0].size) for time in
  File "E:\Anaconda\envs\en1\lib\site-packages\pandas\core\ops.py", line 1283, in wrapper
    res = na_op(values, other)
  File "E:\Anaconda\envs\en1\lib\site-packages\pandas\core\ops.py", line 1143, in na_op
    result = _comp_method_OBJECT_ARRAY(op, x, y)
  File "E:\Anaconda\envs\en1\lib\site-packages\pandas\core\ops.py", line 1120, in _comp_method_OBJECT_ARRAY
    result = libops.vec_compare(x, y, op)
  File "pandas/_libs/ops.pyx", line 128, in pandas._libs.ops.vec_compare
ValueError: Arrays were different lengths: 3419 vs 9
[2018-10-17 14:33:20,307] [ERROR] "POST /api/spotcompared HTTP/1.1" 500 18497
[2018-10-17 14:33:53,128] [INFO] This is an errormsg
[2018-10-17 14:33:53,132] [INFO] "POST /api/spotcompared HTTP/1.1" 200 47
[2018-10-17 14:33:59,925] [INFO] This is an errormsg
[2018-10-17 14:33:59,933] [INFO] "POST /api/spotcompared HTTP/1.1" 200 47
[2018-10-17 14:34:10,803] [INFO] This is an errormsg
[2018-10-17 14:34:10,809] [INFO] "POST /api/spotcompared HTTP/1.1" 200 47
[2018-10-17 14:34:39,253] [ERROR] Internal Server Error: /api/spotcompared
Traceback (most recent call last):
  File "E:\Anaconda\envs\en1\lib\site-packages\django\core\handlers\exception.py", line 35, in inner
    response = get_response(request)
  File "E:\Anaconda\envs\en1\lib\site-packages\django\core\handlers\base.py", line 128, in _get_response
    response = self.process_exception_by_middleware(e, request)
  File "E:\Anaconda\envs\en1\lib\site-packages\django\core\handlers\base.py", line 126, in _get_response
    response = wrapped_callback(request, *callback_args, **callback_kwargs)
  File "E:\Anaconda\envs\en1\lib\site-packages\django\views\decorators\csrf.py", line 54, in wrapped_view
    return view_func(*args, **kwargs)
  File "E:\Anaconda\envs\en1\lib\site-packages\django\views\generic\base.py", line 69, in view
    return self.dispatch(request, *args, **kwargs)
  File "E:\Anaconda\envs\en1\lib\site-packages\rest_framework\views.py", line 483, in dispatch
    response = self.handle_exception(exc)
  File "E:\Anaconda\envs\en1\lib\site-packages\rest_framework\views.py", line 443, in handle_exception
    self.raise_uncaught_exception(exc)
  File "E:\Anaconda\envs\en1\lib\site-packages\rest_framework\views.py", line 480, in dispatch
    response = handler(request, *args, **kwargs)
  File "D:\资料\GitHub\TourCommentApiPro\TourCommentApi\TourCommentApi\Views\SpotComparedView.py", line 94, in post
    return post_spot_compard(request);
  File "D:\资料\GitHub\TourCommentApiPro\TourCommentApi\TourCommentApi\Views\SpotComparedView.py", line 43, in post_spot_compard
    body = json.loads(request.body);
ValueError: Unexpected character found when decoding object value
[2018-10-17 14:34:39,475] [ERROR] "POST /api/spotcompared HTTP/1.1" 500 16932
[2018-10-17 14:34:55,926] [ERROR] Internal Server Error: /api/spotcompared
Traceback (most recent call last):
  File "E:\Anaconda\envs\en1\lib\site-packages\django\core\handlers\exception.py", line 35, in inner
    response = get_response(request)
  File "E:\Anaconda\envs\en1\lib\site-packages\django\core\handlers\base.py", line 128, in _get_response
    response = self.process_exception_by_middleware(e, request)
  File "E:\Anaconda\envs\en1\lib\site-packages\django\core\handlers\base.py", line 126, in _get_response
    response = wrapped_callback(request, *callback_args, **callback_kwargs)
  File "E:\Anaconda\envs\en1\lib\site-packages\django\views\decorators\csrf.py", line 54, in wrapped_view
    return view_func(*args, **kwargs)
  File "E:\Anaconda\envs\en1\lib\site-packages\django\views\generic\base.py", line 69, in view
    return self.dispatch(request, *args, **kwargs)
  File "E:\Anaconda\envs\en1\lib\site-packages\rest_framework\views.py", line 483, in dispatch
    response = self.handle_exception(exc)
  File "E:\Anaconda\envs\en1\lib\site-packages\rest_framework\views.py", line 443, in handle_exception
    self.raise_uncaught_exception(exc)
  File "E:\Anaconda\envs\en1\lib\site-packages\rest_framework\views.py", line 480, in dispatch
    response = handler(request, *args, **kwargs)
  File "D:\资料\GitHub\TourCommentApiPro\TourCommentApi\TourCommentApi\Views\SpotComparedView.py", line 94, in post
    return post_spot_compard(request);
  File "D:\资料\GitHub\TourCommentApiPro\TourCommentApi\TourCommentApi\Views\SpotComparedView.py", line 43, in post_spot_compard
    body = json.loads(request.body);
ValueError: Unexpected character found when decoding object value
[2018-10-17 14:34:56,386] [ERROR] "POST /api/spotcompared HTTP/1.1" 500 16933
[2018-10-17 14:35:21,109] [INFO] "POST /api/spotcompared HTTP/1.1" 200 2492
[2018-10-17 14:35:28,293] [ERROR] Internal Server Error: /api/spotcompared
Traceback (most recent call last):
  File "E:\Anaconda\envs\en1\lib\site-packages\django\core\handlers\exception.py", line 35, in inner
    response = get_response(request)
  File "E:\Anaconda\envs\en1\lib\site-packages\django\core\handlers\base.py", line 128, in _get_response
    response = self.process_exception_by_middleware(e, request)
  File "E:\Anaconda\envs\en1\lib\site-packages\django\core\handlers\base.py", line 126, in _get_response
    response = wrapped_callback(request, *callback_args, **callback_kwargs)
  File "E:\Anaconda\envs\en1\lib\site-packages\django\views\decorators\csrf.py", line 54, in wrapped_view
    return view_func(*args, **kwargs)
  File "E:\Anaconda\envs\en1\lib\site-packages\django\views\generic\base.py", line 69, in view
    return self.dispatch(request, *args, **kwargs)
  File "E:\Anaconda\envs\en1\lib\site-packages\rest_framework\views.py", line 483, in dispatch
    response = self.handle_exception(exc)
  File "E:\Anaconda\envs\en1\lib\site-packages\rest_framework\views.py", line 443, in handle_exception
    self.raise_uncaught_exception(exc)
  File "E:\Anaconda\envs\en1\lib\site-packages\rest_framework\views.py", line 480, in dispatch
    response = handler(request, *args, **kwargs)
  File "D:\资料\GitHub\TourCommentApiPro\TourCommentApi\TourCommentApi\Views\SpotComparedView.py", line 94, in post
    return post_spot_compard(request);
  File "D:\资料\GitHub\TourCommentApiPro\TourCommentApi\TourCommentApi\Views\SpotComparedView.py", line 73, in post_spot_compard
    list = [get_website_data(website,time_search_key,time_list) for website in websites];
  File "D:\资料\GitHub\TourCommentApiPro\TourCommentApi\TourCommentApi\Views\SpotComparedView.py", line 73, in <listcomp>
    list = [get_website_data(website,time_search_key,time_list) for website in websites];
  File "D:\资料\GitHub\TourCommentApiPro\TourCommentApi\TourCommentApi\Views\SpotComparedView.py", line 32, in get_website_data
    yAxis = [get_region_data(website, region, time_search_key, time_list) for region in search_keys];
  File "D:\资料\GitHub\TourCommentApiPro\TourCommentApi\TourCommentApi\Views\SpotComparedView.py", line 32, in <listcomp>
    yAxis = [get_region_data(website, region, time_search_key, time_list) for region in search_keys];
  File "D:\资料\GitHub\TourCommentApiPro\TourCommentApi\TourCommentApi\Views\SpotComparedView.py", line 18, in get_region_data
    time_list];
  File "D:\资料\GitHub\TourCommentApiPro\TourCommentApi\TourCommentApi\Views\SpotComparedView.py", line 17, in <listcomp>
    (spot_website_comments_data[time_search_key] == time)].iloc[:, 0].size) for time in
  File "E:\Anaconda\envs\en1\lib\site-packages\pandas\core\ops.py", line 1283, in wrapper
    res = na_op(values, other)
  File "E:\Anaconda\envs\en1\lib\site-packages\pandas\core\ops.py", line 1143, in na_op
    result = _comp_method_OBJECT_ARRAY(op, x, y)
  File "E:\Anaconda\envs\en1\lib\site-packages\pandas\core\ops.py", line 1120, in _comp_method_OBJECT_ARRAY
    result = libops.vec_compare(x, y, op)
  File "pandas/_libs/ops.pyx", line 128, in pandas._libs.ops.vec_compare
ValueError: Arrays were different lengths: 3419 vs 9
[2018-10-17 14:35:29,458] [ERROR] "POST /api/spotcompared HTTP/1.1" 500 18497
[2018-10-17 14:35:43,571] [ERROR] Internal Server Error: /api/spotcompared
Traceback (most recent call last):
  File "E:\Anaconda\envs\en1\lib\site-packages\django\core\handlers\exception.py", line 35, in inner
    response = get_response(request)
  File "E:\Anaconda\envs\en1\lib\site-packages\django\core\handlers\base.py", line 128, in _get_response
    response = self.process_exception_by_middleware(e, request)
  File "E:\Anaconda\envs\en1\lib\site-packages\django\core\handlers\base.py", line 126, in _get_response
    response = wrapped_callback(request, *callback_args, **callback_kwargs)
  File "E:\Anaconda\envs\en1\lib\site-packages\django\views\decorators\csrf.py", line 54, in wrapped_view
    return view_func(*args, **kwargs)
  File "E:\Anaconda\envs\en1\lib\site-packages\django\views\generic\base.py", line 69, in view
    return self.dispatch(request, *args, **kwargs)
  File "E:\Anaconda\envs\en1\lib\site-packages\rest_framework\views.py", line 483, in dispatch
    response = self.handle_exception(exc)
  File "E:\Anaconda\envs\en1\lib\site-packages\rest_framework\views.py", line 443, in handle_exception
    self.raise_uncaught_exception(exc)
  File "E:\Anaconda\envs\en1\lib\site-packages\rest_framework\views.py", line 480, in dispatch
    response = handler(request, *args, **kwargs)
  File "D:\资料\GitHub\TourCommentApiPro\TourCommentApi\TourCommentApi\Views\SpotComparedView.py", line 94, in post
    return post_spot_compard(request);
  File "D:\资料\GitHub\TourCommentApiPro\TourCommentApi\TourCommentApi\Views\SpotComparedView.py", line 73, in post_spot_compard
    list = [get_website_data(website,time_search_key,time_list) for website in websites];
  File "D:\资料\GitHub\TourCommentApiPro\TourCommentApi\TourCommentApi\Views\SpotComparedView.py", line 73, in <listcomp>
    list = [get_website_data(website,time_search_key,time_list) for website in websites];
  File "D:\资料\GitHub\TourCommentApiPro\TourCommentApi\TourCommentApi\Views\SpotComparedView.py", line 32, in get_website_data
    yAxis = [get_region_data(website, region, time_search_key, time_list) for region in search_keys];
  File "D:\资料\GitHub\TourCommentApiPro\TourCommentApi\TourCommentApi\Views\SpotComparedView.py", line 32, in <listcomp>
    yAxis = [get_region_data(website, region, time_search_key, time_list) for region in search_keys];
  File "D:\资料\GitHub\TourCommentApiPro\TourCommentApi\TourCommentApi\Views\SpotComparedView.py", line 18, in get_region_data
    time_list];
  File "D:\资料\GitHub\TourCommentApiPro\TourCommentApi\TourCommentApi\Views\SpotComparedView.py", line 17, in <listcomp>
    (spot_website_comments_data[time_search_key] == time)].iloc[:, 0].size) for time in
  File "E:\Anaconda\envs\en1\lib\site-packages\pandas\core\ops.py", line 1283, in wrapper
    res = na_op(values, other)
  File "E:\Anaconda\envs\en1\lib\site-packages\pandas\core\ops.py", line 1143, in na_op
    result = _comp_method_OBJECT_ARRAY(op, x, y)
  File "E:\Anaconda\envs\en1\lib\site-packages\pandas\core\ops.py", line 1120, in _comp_method_OBJECT_ARRAY
    result = libops.vec_compare(x, y, op)
  File "pandas/_libs/ops.pyx", line 128, in pandas._libs.ops.vec_compare
ValueError: Arrays were different lengths: 3419 vs 9
[2018-10-17 14:35:44,980] [ERROR] "POST /api/spotcompared HTTP/1.1" 500 18497
[2018-10-17 14:36:18,052] [ERROR] Internal Server Error: /api/spotcompared
Traceback (most recent call last):
  File "E:\Anaconda\envs\en1\lib\site-packages\django\core\handlers\exception.py", line 35, in inner
    response = get_response(request)
  File "E:\Anaconda\envs\en1\lib\site-packages\django\core\handlers\base.py", line 128, in _get_response
    response = self.process_exception_by_middleware(e, request)
  File "E:\Anaconda\envs\en1\lib\site-packages\django\core\handlers\base.py", line 126, in _get_response
    response = wrapped_callback(request, *callback_args, **callback_kwargs)
  File "E:\Anaconda\envs\en1\lib\site-packages\django\views\decorators\csrf.py", line 54, in wrapped_view
    return view_func(*args, **kwargs)
  File "E:\Anaconda\envs\en1\lib\site-packages\django\views\generic\base.py", line 69, in view
    return self.dispatch(request, *args, **kwargs)
  File "E:\Anaconda\envs\en1\lib\site-packages\rest_framework\views.py", line 483, in dispatch
    response = self.handle_exception(exc)
  File "E:\Anaconda\envs\en1\lib\site-packages\rest_framework\views.py", line 443, in handle_exception
    self.raise_uncaught_exception(exc)
  File "E:\Anaconda\envs\en1\lib\site-packages\rest_framework\views.py", line 480, in dispatch
    response = handler(request, *args, **kwargs)
  File "D:\资料\GitHub\TourCommentApiPro\TourCommentApi\TourCommentApi\Views\SpotComparedView.py", line 94, in post
    return post_spot_compard(request);
  File "D:\资料\GitHub\TourCommentApiPro\TourCommentApi\TourCommentApi\Views\SpotComparedView.py", line 73, in post_spot_compard
    list = [get_website_data(website,time_search_key,time_list) for website in websites];
  File "D:\资料\GitHub\TourCommentApiPro\TourCommentApi\TourCommentApi\Views\SpotComparedView.py", line 73, in <listcomp>
    list = [get_website_data(website,time_search_key,time_list) for website in websites];
  File "D:\资料\GitHub\TourCommentApiPro\TourCommentApi\TourCommentApi\Views\SpotComparedView.py", line 32, in get_website_data
    yAxis = [get_region_data(website, region, time_search_key, time_list) for region in search_keys];
  File "D:\资料\GitHub\TourCommentApiPro\TourCommentApi\TourCommentApi\Views\SpotComparedView.py", line 32, in <listcomp>
    yAxis = [get_region_data(website, region, time_search_key, time_list) for region in search_keys];
  File "D:\资料\GitHub\TourCommentApiPro\TourCommentApi\TourCommentApi\Views\SpotComparedView.py", line 18, in get_region_data
    time_list];
  File "D:\资料\GitHub\TourCommentApiPro\TourCommentApi\TourCommentApi\Views\SpotComparedView.py", line 17, in <listcomp>
    (spot_website_comments_data[time_search_key] == time)].iloc[:, 0].size) for time in
  File "E:\Anaconda\envs\en1\lib\site-packages\pandas\core\ops.py", line 1283, in wrapper
    res = na_op(values, other)
  File "E:\Anaconda\envs\en1\lib\site-packages\pandas\core\ops.py", line 1143, in na_op
    result = _comp_method_OBJECT_ARRAY(op, x, y)
  File "E:\Anaconda\envs\en1\lib\site-packages\pandas\core\ops.py", line 1120, in _comp_method_OBJECT_ARRAY
    result = libops.vec_compare(x, y, op)
  File "pandas/_libs/ops.pyx", line 128, in pandas._libs.ops.vec_compare
ValueError: Arrays were different lengths: 4136 vs 9
[2018-10-17 14:36:19,208] [ERROR] "POST /api/spotcompared HTTP/1.1" 500 18497
[2018-10-17 14:36:27,495] [INFO] "POST /api/spotcompared HTTP/1.1" 200 1247
[2018-10-17 14:40:06,180] [INFO] "POST /api/spotcompared HTTP/1.1" 200 301
[2018-10-17 14:40:17,612] [ERROR] Internal Server Error: /api/spotcompared
Traceback (most recent call last):
  File "E:\Anaconda\envs\en1\lib\site-packages\django\core\handlers\exception.py", line 35, in inner
    response = get_response(request)
  File "E:\Anaconda\envs\en1\lib\site-packages\django\core\handlers\base.py", line 128, in _get_response
    response = self.process_exception_by_middleware(e, request)
  File "E:\Anaconda\envs\en1\lib\site-packages\django\core\handlers\base.py", line 126, in _get_response
    response = wrapped_callback(request, *callback_args, **callback_kwargs)
  File "E:\Anaconda\envs\en1\lib\site-packages\django\views\decorators\csrf.py", line 54, in wrapped_view
    return view_func(*args, **kwargs)
  File "E:\Anaconda\envs\en1\lib\site-packages\django\views\generic\base.py", line 69, in view
    return self.dispatch(request, *args, **kwargs)
  File "E:\Anaconda\envs\en1\lib\site-packages\rest_framework\views.py", line 483, in dispatch
    response = self.handle_exception(exc)
  File "E:\Anaconda\envs\en1\lib\site-packages\rest_framework\views.py", line 443, in handle_exception
    self.raise_uncaught_exception(exc)
  File "E:\Anaconda\envs\en1\lib\site-packages\rest_framework\views.py", line 480, in dispatch
    response = handler(request, *args, **kwargs)
  File "D:\资料\GitHub\TourCommentApiPro\TourCommentApi\TourCommentApi\Views\SpotComparedView.py", line 94, in post
    return post_spot_compard(request);
  File "D:\资料\GitHub\TourCommentApiPro\TourCommentApi\TourCommentApi\Views\SpotComparedView.py", line 73, in post_spot_compard
    list = [get_website_data(website,time_search_key,time_list,search_keys) for website in websites];
  File "D:\资料\GitHub\TourCommentApiPro\TourCommentApi\TourCommentApi\Views\SpotComparedView.py", line 73, in <listcomp>
    list = [get_website_data(website,time_search_key,time_list,search_keys) for website in websites];
  File "D:\资料\GitHub\TourCommentApiPro\TourCommentApi\TourCommentApi\Views\SpotComparedView.py", line 32, in get_website_data
    yAxis = [get_region_data(website, region, time_search_key, time_list) for region in search_keys];
  File "D:\资料\GitHub\TourCommentApiPro\TourCommentApi\TourCommentApi\Views\SpotComparedView.py", line 32, in <listcomp>
    yAxis = [get_region_data(website, region, time_search_key, time_list) for region in search_keys];
  File "D:\资料\GitHub\TourCommentApiPro\TourCommentApi\TourCommentApi\Views\SpotComparedView.py", line 18, in get_region_data
    time_list];
  File "D:\资料\GitHub\TourCommentApiPro\TourCommentApi\TourCommentApi\Views\SpotComparedView.py", line 17, in <listcomp>
    (spot_website_comments_data[time_search_key] == time)].iloc[:, 0].size) for time in
  File "E:\Anaconda\envs\en1\lib\site-packages\pandas\core\ops.py", line 1283, in wrapper
    res = na_op(values, other)
  File "E:\Anaconda\envs\en1\lib\site-packages\pandas\core\ops.py", line 1143, in na_op
    result = _comp_method_OBJECT_ARRAY(op, x, y)
  File "E:\Anaconda\envs\en1\lib\site-packages\pandas\core\ops.py", line 1120, in _comp_method_OBJECT_ARRAY
    result = libops.vec_compare(x, y, op)
  File "pandas/_libs/ops.pyx", line 128, in pandas._libs.ops.vec_compare
ValueError: Arrays were different lengths: 4136 vs 9
[2018-10-17 14:40:18,991] [ERROR] "POST /api/spotcompared HTTP/1.1" 500 18521
[2018-10-17 14:40:30,277] [ERROR] Internal Server Error: /api/spotcompared
Traceback (most recent call last):
  File "E:\Anaconda\envs\en1\lib\site-packages\django\core\handlers\exception.py", line 35, in inner
    response = get_response(request)
  File "E:\Anaconda\envs\en1\lib\site-packages\django\core\handlers\base.py", line 128, in _get_response
    response = self.process_exception_by_middleware(e, request)
  File "E:\Anaconda\envs\en1\lib\site-packages\django\core\handlers\base.py", line 126, in _get_response
    response = wrapped_callback(request, *callback_args, **callback_kwargs)
  File "E:\Anaconda\envs\en1\lib\site-packages\django\views\decorators\csrf.py", line 54, in wrapped_view
    return view_func(*args, **kwargs)
  File "E:\Anaconda\envs\en1\lib\site-packages\django\views\generic\base.py", line 69, in view
    return self.dispatch(request, *args, **kwargs)
  File "E:\Anaconda\envs\en1\lib\site-packages\rest_framework\views.py", line 483, in dispatch
    response = self.handle_exception(exc)
  File "E:\Anaconda\envs\en1\lib\site-packages\rest_framework\views.py", line 443, in handle_exception
    self.raise_uncaught_exception(exc)
  File "E:\Anaconda\envs\en1\lib\site-packages\rest_framework\views.py", line 480, in dispatch
    response = handler(request, *args, **kwargs)
  File "D:\资料\GitHub\TourCommentApiPro\TourCommentApi\TourCommentApi\Views\SpotComparedView.py", line 94, in post
    return post_spot_compard(request);
  File "D:\资料\GitHub\TourCommentApiPro\TourCommentApi\TourCommentApi\Views\SpotComparedView.py", line 73, in post_spot_compard
    list = [get_website_data(website,time_search_key,time_list,search_keys) for website in websites];
  File "D:\资料\GitHub\TourCommentApiPro\TourCommentApi\TourCommentApi\Views\SpotComparedView.py", line 73, in <listcomp>
    list = [get_website_data(website,time_search_key,time_list,search_keys) for website in websites];
  File "D:\资料\GitHub\TourCommentApiPro\TourCommentApi\TourCommentApi\Views\SpotComparedView.py", line 32, in get_website_data
    yAxis = [get_region_data(website, region, time_search_key, time_list) for region in search_keys];
  File "D:\资料\GitHub\TourCommentApiPro\TourCommentApi\TourCommentApi\Views\SpotComparedView.py", line 32, in <listcomp>
    yAxis = [get_region_data(website, region, time_search_key, time_list) for region in search_keys];
  File "D:\资料\GitHub\TourCommentApiPro\TourCommentApi\TourCommentApi\Views\SpotComparedView.py", line 18, in get_region_data
    time_list];
  File "D:\资料\GitHub\TourCommentApiPro\TourCommentApi\TourCommentApi\Views\SpotComparedView.py", line 17, in <listcomp>
    (spot_website_comments_data[time_search_key] == time)].iloc[:, 0].size) for time in
  File "E:\Anaconda\envs\en1\lib\site-packages\pandas\core\ops.py", line 1283, in wrapper
    res = na_op(values, other)
  File "E:\Anaconda\envs\en1\lib\site-packages\pandas\core\ops.py", line 1143, in na_op
    result = _comp_method_OBJECT_ARRAY(op, x, y)
  File "E:\Anaconda\envs\en1\lib\site-packages\pandas\core\ops.py", line 1120, in _comp_method_OBJECT_ARRAY
    result = libops.vec_compare(x, y, op)
  File "pandas/_libs/ops.pyx", line 128, in pandas._libs.ops.vec_compare
ValueError: Arrays were different lengths: 4136 vs 9
[2018-10-17 14:40:31,791] [ERROR] "POST /api/spotcompared HTTP/1.1" 500 18521
[2018-10-17 14:40:41,397] [ERROR] Internal Server Error: /api/spotcompared
Traceback (most recent call last):
  File "E:\Anaconda\envs\en1\lib\site-packages\django\core\handlers\exception.py", line 35, in inner
    response = get_response(request)
  File "E:\Anaconda\envs\en1\lib\site-packages\django\core\handlers\base.py", line 128, in _get_response
    response = self.process_exception_by_middleware(e, request)
  File "E:\Anaconda\envs\en1\lib\site-packages\django\core\handlers\base.py", line 126, in _get_response
    response = wrapped_callback(request, *callback_args, **callback_kwargs)
  File "E:\Anaconda\envs\en1\lib\site-packages\django\views\decorators\csrf.py", line 54, in wrapped_view
    return view_func(*args, **kwargs)
  File "E:\Anaconda\envs\en1\lib\site-packages\django\views\generic\base.py", line 69, in view
    return self.dispatch(request, *args, **kwargs)
  File "E:\Anaconda\envs\en1\lib\site-packages\rest_framework\views.py", line 483, in dispatch
    response = self.handle_exception(exc)
  File "E:\Anaconda\envs\en1\lib\site-packages\rest_framework\views.py", line 443, in handle_exception
    self.raise_uncaught_exception(exc)
  File "E:\Anaconda\envs\en1\lib\site-packages\rest_framework\views.py", line 480, in dispatch
    response = handler(request, *args, **kwargs)
  File "D:\资料\GitHub\TourCommentApiPro\TourCommentApi\TourCommentApi\Views\SpotComparedView.py", line 94, in post
    return post_spot_compard(request);
  File "D:\资料\GitHub\TourCommentApiPro\TourCommentApi\TourCommentApi\Views\SpotComparedView.py", line 73, in post_spot_compard
    list = [get_website_data(website,time_search_key,time_list,search_keys) for website in websites];
  File "D:\资料\GitHub\TourCommentApiPro\TourCommentApi\TourCommentApi\Views\SpotComparedView.py", line 73, in <listcomp>
    list = [get_website_data(website,time_search_key,time_list,search_keys) for website in websites];
  File "D:\资料\GitHub\TourCommentApiPro\TourCommentApi\TourCommentApi\Views\SpotComparedView.py", line 32, in get_website_data
    yAxis = [get_region_data(website, region, time_search_key, time_list) for region in search_keys];
  File "D:\资料\GitHub\TourCommentApiPro\TourCommentApi\TourCommentApi\Views\SpotComparedView.py", line 32, in <listcomp>
    yAxis = [get_region_data(website, region, time_search_key, time_list) for region in search_keys];
  File "D:\资料\GitHub\TourCommentApiPro\TourCommentApi\TourCommentApi\Views\SpotComparedView.py", line 18, in get_region_data
    time_list];
  File "D:\资料\GitHub\TourCommentApiPro\TourCommentApi\TourCommentApi\Views\SpotComparedView.py", line 17, in <listcomp>
    (spot_website_comments_data[time_search_key] == time)].iloc[:, 0].size) for time in
  File "E:\Anaconda\envs\en1\lib\site-packages\pandas\core\ops.py", line 1283, in wrapper
    res = na_op(values, other)
  File "E:\Anaconda\envs\en1\lib\site-packages\pandas\core\ops.py", line 1143, in na_op
    result = _comp_method_OBJECT_ARRAY(op, x, y)
  File "E:\Anaconda\envs\en1\lib\site-packages\pandas\core\ops.py", line 1120, in _comp_method_OBJECT_ARRAY
    result = libops.vec_compare(x, y, op)
  File "pandas/_libs/ops.pyx", line 128, in pandas._libs.ops.vec_compare
ValueError: Arrays were different lengths: 4136 vs 0
[2018-10-17 14:40:42,904] [ERROR] "POST /api/spotcompared HTTP/1.1" 500 18521
[2018-10-17 14:41:56,992] [INFO] "POST /api/spotcompared HTTP/1.1" 200 301
[2018-10-17 14:42:11,858] [ERROR] Internal Server Error: /api/spotcompared
Traceback (most recent call last):
  File "E:\Anaconda\envs\en1\lib\site-packages\django\core\handlers\exception.py", line 35, in inner
    response = get_response(request)
  File "E:\Anaconda\envs\en1\lib\site-packages\django\core\handlers\base.py", line 128, in _get_response
    response = self.process_exception_by_middleware(e, request)
  File "E:\Anaconda\envs\en1\lib\site-packages\django\core\handlers\base.py", line 126, in _get_response
    response = wrapped_callback(request, *callback_args, **callback_kwargs)
  File "E:\Anaconda\envs\en1\lib\site-packages\django\views\decorators\csrf.py", line 54, in wrapped_view
    return view_func(*args, **kwargs)
  File "E:\Anaconda\envs\en1\lib\site-packages\django\views\generic\base.py", line 69, in view
    return self.dispatch(request, *args, **kwargs)
  File "E:\Anaconda\envs\en1\lib\site-packages\rest_framework\views.py", line 483, in dispatch
    response = self.handle_exception(exc)
  File "E:\Anaconda\envs\en1\lib\site-packages\rest_framework\views.py", line 443, in handle_exception
    self.raise_uncaught_exception(exc)
  File "E:\Anaconda\envs\en1\lib\site-packages\rest_framework\views.py", line 480, in dispatch
    response = handler(request, *args, **kwargs)
  File "D:\资料\GitHub\TourCommentApiPro\TourCommentApi\TourCommentApi\Views\SpotComparedView.py", line 94, in post
    return post_spot_compard(request);
  File "D:\资料\GitHub\TourCommentApiPro\TourCommentApi\TourCommentApi\Views\SpotComparedView.py", line 73, in post_spot_compard
    list = [get_website_data(website,time_search_key,time_list,search_keys) for website in websites];
  File "D:\资料\GitHub\TourCommentApiPro\TourCommentApi\TourCommentApi\Views\SpotComparedView.py", line 73, in <listcomp>
    list = [get_website_data(website,time_search_key,time_list,search_keys) for website in websites];
  File "D:\资料\GitHub\TourCommentApiPro\TourCommentApi\TourCommentApi\Views\SpotComparedView.py", line 32, in get_website_data
    yAxis = [get_region_data(website, region, time_search_key, time_list) for region in search_keys];
  File "D:\资料\GitHub\TourCommentApiPro\TourCommentApi\TourCommentApi\Views\SpotComparedView.py", line 32, in <listcomp>
    yAxis = [get_region_data(website, region, time_search_key, time_list) for region in search_keys];
  File "D:\资料\GitHub\TourCommentApiPro\TourCommentApi\TourCommentApi\Views\SpotComparedView.py", line 18, in get_region_data
    time_list];
  File "D:\资料\GitHub\TourCommentApiPro\TourCommentApi\TourCommentApi\Views\SpotComparedView.py", line 17, in <listcomp>
    (spot_website_comments_data[time_search_key] == time)].iloc[:, 0].size) for time in
  File "E:\Anaconda\envs\en1\lib\site-packages\pandas\core\ops.py", line 1283, in wrapper
    res = na_op(values, other)
  File "E:\Anaconda\envs\en1\lib\site-packages\pandas\core\ops.py", line 1143, in na_op
    result = _comp_method_OBJECT_ARRAY(op, x, y)
  File "E:\Anaconda\envs\en1\lib\site-packages\pandas\core\ops.py", line 1120, in _comp_method_OBJECT_ARRAY
    result = libops.vec_compare(x, y, op)
  File "pandas/_libs/ops.pyx", line 128, in pandas._libs.ops.vec_compare
ValueError: Arrays were different lengths: 4136 vs 0
[2018-10-17 14:42:13,131] [ERROR] "POST /api/spotcompared HTTP/1.1" 500 18521
[2018-10-17 14:43:11,443] [ERROR] Internal Server Error: /api/spotcompared
Traceback (most recent call last):
  File "E:\Anaconda\envs\en1\lib\site-packages\django\core\handlers\exception.py", line 35, in inner
    response = get_response(request)
  File "E:\Anaconda\envs\en1\lib\site-packages\django\core\handlers\base.py", line 128, in _get_response
    response = self.process_exception_by_middleware(e, request)
  File "E:\Anaconda\envs\en1\lib\site-packages\django\core\handlers\base.py", line 126, in _get_response
    response = wrapped_callback(request, *callback_args, **callback_kwargs)
  File "E:\Anaconda\envs\en1\lib\site-packages\django\views\decorators\csrf.py", line 54, in wrapped_view
    return view_func(*args, **kwargs)
  File "E:\Anaconda\envs\en1\lib\site-packages\django\views\generic\base.py", line 69, in view
    return self.dispatch(request, *args, **kwargs)
  File "E:\Anaconda\envs\en1\lib\site-packages\rest_framework\views.py", line 483, in dispatch
    response = self.handle_exception(exc)
  File "E:\Anaconda\envs\en1\lib\site-packages\rest_framework\views.py", line 443, in handle_exception
    self.raise_uncaught_exception(exc)
  File "E:\Anaconda\envs\en1\lib\site-packages\rest_framework\views.py", line 480, in dispatch
    response = handler(request, *args, **kwargs)
  File "D:\资料\GitHub\TourCommentApiPro\TourCommentApi\TourCommentApi\Views\SpotComparedView.py", line 94, in post
    return post_spot_compard(request);
  File "D:\资料\GitHub\TourCommentApiPro\TourCommentApi\TourCommentApi\Views\SpotComparedView.py", line 73, in post_spot_compard
    list = [get_website_data(website,time_search_key,time_list,search_keys) for website in websites];
  File "D:\资料\GitHub\TourCommentApiPro\TourCommentApi\TourCommentApi\Views\SpotComparedView.py", line 73, in <listcomp>
    list = [get_website_data(website,time_search_key,time_list,search_keys) for website in websites];
  File "D:\资料\GitHub\TourCommentApiPro\TourCommentApi\TourCommentApi\Views\SpotComparedView.py", line 32, in get_website_data
    yAxis = [get_region_data(website, region, time_search_key, time_list) for region in search_keys];
  File "D:\资料\GitHub\TourCommentApiPro\TourCommentApi\TourCommentApi\Views\SpotComparedView.py", line 32, in <listcomp>
    yAxis = [get_region_data(website, region, time_search_key, time_list) for region in search_keys];
  File "D:\资料\GitHub\TourCommentApiPro\TourCommentApi\TourCommentApi\Views\SpotComparedView.py", line 18, in get_region_data
    time_list];
  File "D:\资料\GitHub\TourCommentApiPro\TourCommentApi\TourCommentApi\Views\SpotComparedView.py", line 17, in <listcomp>
    (spot_website_comments_data[time_search_key] == time)].iloc[:, 0].size) for time in
  File "E:\Anaconda\envs\en1\lib\site-packages\pandas\core\ops.py", line 1283, in wrapper
    res = na_op(values, other)
  File "E:\Anaconda\envs\en1\lib\site-packages\pandas\core\ops.py", line 1143, in na_op
    result = _comp_method_OBJECT_ARRAY(op, x, y)
  File "E:\Anaconda\envs\en1\lib\site-packages\pandas\core\ops.py", line 1120, in _comp_method_OBJECT_ARRAY
    result = libops.vec_compare(x, y, op)
  File "pandas/_libs/ops.pyx", line 128, in pandas._libs.ops.vec_compare
ValueError: Arrays were different lengths: 4136 vs 0
[2018-10-17 14:43:12,776] [ERROR] "POST /api/spotcompared HTTP/1.1" 500 18521
[2018-10-17 14:46:46,738] [INFO] "POST /api/spotcompared HTTP/1.1" 200 317
[2018-10-17 14:47:03,137] [INFO] "POST /api/spotcompared HTTP/1.1" 200 709
[2018-10-17 14:48:11,343] [INFO] "POST /api/spotcompared HTTP/1.1" 200 4476
[2018-10-17 14:49:14,961] [ERROR] Internal Server Error: /api/spotcompared
Traceback (most recent call last):
  File "E:\Anaconda\envs\en1\lib\site-packages\django\core\handlers\exception.py", line 35, in inner
    response = get_response(request)
  File "E:\Anaconda\envs\en1\lib\site-packages\django\core\handlers\base.py", line 128, in _get_response
    response = self.process_exception_by_middleware(e, request)
  File "E:\Anaconda\envs\en1\lib\site-packages\django\core\handlers\base.py", line 126, in _get_response
    response = wrapped_callback(request, *callback_args, **callback_kwargs)
  File "E:\Anaconda\envs\en1\lib\site-packages\django\views\decorators\csrf.py", line 54, in wrapped_view
    return view_func(*args, **kwargs)
  File "E:\Anaconda\envs\en1\lib\site-packages\django\views\generic\base.py", line 69, in view
    return self.dispatch(request, *args, **kwargs)
  File "E:\Anaconda\envs\en1\lib\site-packages\rest_framework\views.py", line 483, in dispatch
    response = self.handle_exception(exc)
  File "E:\Anaconda\envs\en1\lib\site-packages\rest_framework\views.py", line 443, in handle_exception
    self.raise_uncaught_exception(exc)
  File "E:\Anaconda\envs\en1\lib\site-packages\rest_framework\views.py", line 480, in dispatch
    response = handler(request, *args, **kwargs)
  File "D:\资料\GitHub\TourCommentApiPro\TourCommentApi\TourCommentApi\Views\SpotComparedView.py", line 94, in post
    return post_spot_compard(request);
  File "D:\资料\GitHub\TourCommentApiPro\TourCommentApi\TourCommentApi\Views\SpotComparedView.py", line 43, in post_spot_compard
    body = json.loads(request.body);
ValueError: Expected object or value
[2018-10-17 14:49:15,131] [ERROR] "POST /api/spotcompared HTTP/1.1" 500 16875
[2018-10-17 14:51:11,358] [INFO] "POST /api/spotcompared HTTP/1.1" 200 18458
[2018-10-17 14:52:07,498] [INFO] "POST /api/spotcompared HTTP/1.1" 200 18458
[2018-10-17 14:52:38,951] [INFO] "POST /api/spotcompared HTTP/1.1" 200 11467
[2018-10-17 14:53:00,406] [INFO] "POST /api/spotcompared HTTP/1.1" 200 7074
[2018-10-17 14:53:12,010] [INFO] "POST /api/spotcompared HTTP/1.1" 200 7074
[2018-10-17 14:53:59,502] [INFO] "POST /api/spotcompared HTTP/1.1" 200 5342
[2018-10-17 14:54:14,346] [INFO] "POST /api/spotcompared HTTP/1.1" 200 3095
[2018-10-17 14:54:24,337] [INFO] "POST /api/spotcompared HTTP/1.1" 200 1622
[2018-10-17 15:28:05,048] [INFO] "POST /api/spotcompared HTTP/1.1" 200 1186
[2018-10-17 15:41:20,913] [WARNING] "POST /api/spotcompared HTTP/1.1" 401 58
[2018-10-17 15:45:03,652] [INFO] "POST /api/spotcompared HTTP/1.1" 200 1186
[2018-10-17 15:52:40,669] [INFO] "POST /api/spotcompared HTTP/1.1" 200 1186
[2018-10-17 16:00:21,772] [INFO] "POST /api/spotcompared HTTP/1.1" 200 1198
[2018-10-17 16:05:20,433] [INFO] "POST /api/spotcompared HTTP/1.1" 200 1198
[2018-10-17 16:11:21,330] [INFO] "POST /api/spotcompared HTTP/1.1" 200 1382
[2018-10-17 16:14:39,261] [INFO] "POST /api/spotcompared HTTP/1.1" 200 1622
[2018-10-17 16:14:53,324] [INFO] "POST /api/spotcompared HTTP/1.1" 200 1778
[2018-10-17 16:15:14,837] [INFO] "POST /api/spotcompared HTTP/1.1" 200 1002
[2018-10-17 16:16:40,494] [WARNING] Not Found: /api/spodetail/1
[2018-10-17 16:16:40,498] [WARNING] "GET /api/spodetail/1 HTTP/1.1" 404 2924
[2018-10-17 16:18:00,567] [INFO] "GET /api/spotdetail/1 HTTP/1.1" 200 401
[2018-10-17 16:18:02,636] [INFO] "GET /api/spotdetail/1 HTTP/1.1" 200 401
[2018-10-17 16:18:18,132] [INFO] "GET /api/spotlist HTTP/1.1" 200 3193
[2018-10-17 16:18:21,980] [INFO] "GET /api/qdhspotlist HTTP/1.1" 200 3677
[2018-10-17 16:18:50,081] [INFO] "GET /api/spotdetail/1 HTTP/1.1" 200 401
[2018-10-17 16:19:15,405] [INFO] "GET /api/spotdetail/2 HTTP/1.1" 200 545
[2018-10-17 16:19:20,373] [INFO] "GET /api/spotdetail/2 HTTP/1.1" 200 545
[2018-10-17 16:19:52,339] [INFO] "GET /api/spotdetail/3 HTTP/1.1" 200 534
[2018-10-17 16:39:58,374] [ERROR] Internal Server Error: /api/spotdetail/2
Traceback (most recent call last):
  File "E:\Anaconda\envs\en1\lib\site-packages\django\core\handlers\exception.py", line 35, in inner
    response = get_response(request)
  File "E:\Anaconda\envs\en1\lib\site-packages\django\core\handlers\base.py", line 128, in _get_response
    response = self.process_exception_by_middleware(e, request)
  File "E:\Anaconda\envs\en1\lib\site-packages\django\core\handlers\base.py", line 126, in _get_response
    response = wrapped_callback(request, *callback_args, **callback_kwargs)
  File "E:\Anaconda\envs\en1\lib\site-packages\django\views\decorators\csrf.py", line 54, in wrapped_view
    return view_func(*args, **kwargs)
  File "E:\Anaconda\envs\en1\lib\site-packages\django\views\generic\base.py", line 69, in view
    return self.dispatch(request, *args, **kwargs)
  File "E:\Anaconda\envs\en1\lib\site-packages\rest_framework\views.py", line 483, in dispatch
    response = self.handle_exception(exc)
  File "E:\Anaconda\envs\en1\lib\site-packages\rest_framework\views.py", line 443, in handle_exception
    self.raise_uncaught_exception(exc)
  File "E:\Anaconda\envs\en1\lib\site-packages\rest_framework\views.py", line 480, in dispatch
    response = handler(request, *args, **kwargs)
  File "D:\资料\GitHub\TourCommentApiPro\TourCommentApi\TourCommentApi\Views\SpotDetailView.py", line 75, in get
    return get_spot_detail(request,id);
  File "D:\资料\GitHub\TourCommentApiPro\TourCommentApi\TourCommentApi\Views\SpotDetailView.py", line 39, in get_spot_detail
    (comments_data['search_key'] == spot) & (comments_data['comment_month'] == nowMonth)];
NameError: name 'nowMonth' is not defined
[2018-10-17 16:39:58,845] [ERROR] "GET /api/spotdetail/2 HTTP/1.1" 500 95745
[2018-10-17 16:41:15,860] [ERROR] Internal Server Error: /api/spotdetail/2
Traceback (most recent call last):
  File "E:\Anaconda\envs\en1\lib\site-packages\django\core\handlers\exception.py", line 35, in inner
    response = get_response(request)
  File "E:\Anaconda\envs\en1\lib\site-packages\django\core\handlers\base.py", line 128, in _get_response
    response = self.process_exception_by_middleware(e, request)
  File "E:\Anaconda\envs\en1\lib\site-packages\django\core\handlers\base.py", line 126, in _get_response
    response = wrapped_callback(request, *callback_args, **callback_kwargs)
  File "E:\Anaconda\envs\en1\lib\site-packages\django\views\decorators\csrf.py", line 54, in wrapped_view
    return view_func(*args, **kwargs)
  File "E:\Anaconda\envs\en1\lib\site-packages\django\views\generic\base.py", line 69, in view
    return self.dispatch(request, *args, **kwargs)
  File "E:\Anaconda\envs\en1\lib\site-packages\rest_framework\views.py", line 483, in dispatch
    response = self.handle_exception(exc)
  File "E:\Anaconda\envs\en1\lib\site-packages\rest_framework\views.py", line 443, in handle_exception
    self.raise_uncaught_exception(exc)
  File "E:\Anaconda\envs\en1\lib\site-packages\rest_framework\views.py", line 480, in dispatch
    response = handler(request, *args, **kwargs)
  File "D:\资料\GitHub\TourCommentApiPro\TourCommentApi\TourCommentApi\Views\SpotDetailView.py", line 75, in get
    return get_spot_detail(request,id);
  File "D:\资料\GitHub\TourCommentApiPro\TourCommentApi\TourCommentApi\Views\SpotDetailView.py", line 48, in get_spot_detail
    num_axis,score_axis = [get_region_data(region,time_list) for region in spot_search_keys];
  File "D:\资料\GitHub\TourCommentApiPro\TourCommentApi\TourCommentApi\Views\SpotDetailView.py", line 48, in <listcomp>
    num_axis,score_axis = [get_region_data(region,time_list) for region in spot_search_keys];
  File "D:\资料\GitHub\TourCommentApiPro\TourCommentApi\TourCommentApi\Views\SpotDetailView.py", line 19, in get_region_data
    num_cnts,score_cnts = [get_time_data(spot_comment_data,time) for time in time_list];
  File "D:\资料\GitHub\TourCommentApiPro\TourCommentApi\TourCommentApi\Views\SpotDetailView.py", line 19, in <listcomp>
    num_cnts,score_cnts = [get_time_data(spot_comment_data,time) for time in time_list];
  File "D:\资料\GitHub\TourCommentApiPro\TourCommentApi\TourCommentApi\Views\SpotDetailView.py", line 10, in get_time_data
    return spot_time_comment_data.iloc[:,0].size,get_score(spot_time_comment_data['comment_score'].mean);
  File "D:\资料\GitHub\TourCommentApiPro\TourCommentApi\TourCommentApi\Views\CommonView.py", line 100, in get_score
    return round(score,1);
TypeError: type method doesn't define __round__ method
[2018-10-17 16:41:17,382] [ERROR] "GET /api/spotdetail/2 HTTP/1.1" 500 137379
[2018-10-17 16:43:03,698] [ERROR] Internal Server Error: /api/spotdetail/2
Traceback (most recent call last):
  File "E:\Anaconda\envs\en1\lib\site-packages\django\core\handlers\exception.py", line 35, in inner
    response = get_response(request)
  File "E:\Anaconda\envs\en1\lib\site-packages\django\core\handlers\base.py", line 128, in _get_response
    response = self.process_exception_by_middleware(e, request)
  File "E:\Anaconda\envs\en1\lib\site-packages\django\core\handlers\base.py", line 126, in _get_response
    response = wrapped_callback(request, *callback_args, **callback_kwargs)
  File "E:\Anaconda\envs\en1\lib\site-packages\django\views\decorators\csrf.py", line 54, in wrapped_view
    return view_func(*args, **kwargs)
  File "E:\Anaconda\envs\en1\lib\site-packages\django\views\generic\base.py", line 69, in view
    return self.dispatch(request, *args, **kwargs)
  File "E:\Anaconda\envs\en1\lib\site-packages\rest_framework\views.py", line 483, in dispatch
    response = self.handle_exception(exc)
  File "E:\Anaconda\envs\en1\lib\site-packages\rest_framework\views.py", line 443, in handle_exception
    self.raise_uncaught_exception(exc)
  File "E:\Anaconda\envs\en1\lib\site-packages\rest_framework\views.py", line 480, in dispatch
    response = handler(request, *args, **kwargs)
  File "D:\资料\GitHub\TourCommentApiPro\TourCommentApi\TourCommentApi\Views\SpotDetailView.py", line 75, in get
    return get_spot_detail(request,id);
  File "D:\资料\GitHub\TourCommentApiPro\TourCommentApi\TourCommentApi\Views\SpotDetailView.py", line 48, in get_spot_detail
    num_axis,score_axis = [get_region_data(region,time_list) for region in spot_search_keys];
  File "D:\资料\GitHub\TourCommentApiPro\TourCommentApi\TourCommentApi\Views\SpotDetailView.py", line 48, in <listcomp>
    num_axis,score_axis = [get_region_data(region,time_list) for region in spot_search_keys];
  File "D:\资料\GitHub\TourCommentApiPro\TourCommentApi\TourCommentApi\Views\SpotDetailView.py", line 19, in get_region_data
    num_cnts,score_cnts = [get_time_data(spot_comment_data,time) for time in time_list];
ValueError: too many values to unpack (expected 2)
[2018-10-17 16:43:05,404] [ERROR] "GET /api/spotdetail/2 HTTP/1.1" 500 113381
[2018-10-17 16:48:49,492] [INFO] "GET /api/spotdetail/2 HTTP/1.1" 200 545
[2018-10-17 16:49:02,310] [INFO] "GET /api/spotdetail/1 HTTP/1.1" 200 401
[2018-10-17 16:49:19,674] [INFO] "GET /api/spotdetail/6 HTTP/1.1" 200 534
[2018-10-18 09:13:36,945] [INFO] "POST /api/spotcompared HTTP/1.1" 200 570
[2018-10-18 09:14:16,485] [INFO] This is an errormsg
[2018-10-18 09:14:16,490] [INFO] "POST /api/spotcompared HTTP/1.1" 200 47
[2018-10-18 09:14:46,302] [INFO] "POST /api/spotcompared HTTP/1.1" 200 514
[2018-10-18 09:57:08,249] [INFO] "POST /api/spotcompared HTTP/1.1" 200 522
[2018-10-18 09:57:31,880] [INFO] "POST /api/spotcompared HTTP/1.1" 200 524
[2018-10-18 10:06:09,467] [INFO] "POST /api/spotcompared HTTP/1.1" 200 524
[2018-10-18 10:07:13,085] [INFO] "POST /api/spotcompared HTTP/1.1" 200 302
[2018-10-18 10:07:36,623] [INFO] "POST /api/spotcompared HTTP/1.1" 200 300
[2018-10-18 10:15:18,445] [INFO] "POST /api/spotcompared HTTP/1.1" 200 300
[2018-10-18 10:29:34,540] [INFO] "POST /api/spotcompared HTTP/1.1" 200 291
[2018-10-18 10:30:29,929] [ERROR] Internal Server Error: /api/spotcompared
Traceback (most recent call last):
  File "E:\Anaconda\envs\en1\lib\site-packages\django\core\handlers\exception.py", line 35, in inner
    response = get_response(request)
  File "E:\Anaconda\envs\en1\lib\site-packages\django\core\handlers\base.py", line 128, in _get_response
    response = self.process_exception_by_middleware(e, request)
  File "E:\Anaconda\envs\en1\lib\site-packages\django\core\handlers\base.py", line 126, in _get_response
    response = wrapped_callback(request, *callback_args, **callback_kwargs)
  File "E:\Anaconda\envs\en1\lib\site-packages\django\views\decorators\csrf.py", line 54, in wrapped_view
    return view_func(*args, **kwargs)
  File "E:\Anaconda\envs\en1\lib\site-packages\django\views\generic\base.py", line 69, in view
    return self.dispatch(request, *args, **kwargs)
  File "E:\Anaconda\envs\en1\lib\site-packages\rest_framework\views.py", line 483, in dispatch
    response = self.handle_exception(exc)
  File "E:\Anaconda\envs\en1\lib\site-packages\rest_framework\views.py", line 443, in handle_exception
    self.raise_uncaught_exception(exc)
  File "E:\Anaconda\envs\en1\lib\site-packages\rest_framework\views.py", line 480, in dispatch
    response = handler(request, *args, **kwargs)
  File "D:\资料\GitHub\TourCommentApiPro\TourCommentApi\TourCommentApi\Views\SpotComparedView.py", line 104, in post
    return post_spot_compard(request);
  File "D:\资料\GitHub\TourCommentApiPro\TourCommentApi\TourCommentApi\Views\SpotComparedView.py", line 52, in post_spot_compard
    body = json.loads(request.body);
ValueError: Unexpected character found when decoding array value (2)
[2018-10-18 10:30:30,396] [ERROR] "POST /api/spotcompared HTTP/1.1" 500 16940
[2018-10-18 10:30:39,877] [INFO] "POST /api/spotcompared HTTP/1.1" 200 167
[2018-10-18 10:30:52,770] [INFO] "POST /api/spotcompared HTTP/1.1" 200 169
[2018-10-18 10:35:29,440] [INFO] "POST /api/spotcompared HTTP/1.1" 200 183
[2018-10-18 10:40:03,570] [INFO] "POST /api/spotcompared HTTP/1.1" 200 187
[2018-10-18 10:40:19,675] [INFO] "POST /api/spotcompared HTTP/1.1" 200 172
[2018-10-18 10:40:35,862] [INFO] "POST /api/spotcompared HTTP/1.1" 200 188
[2018-10-18 10:40:56,458] [INFO] "POST /api/spotcompared HTTP/1.1" 200 220
[2018-10-18 10:41:32,949] [ERROR] Internal Server Error: /api/spotcompared
Traceback (most recent call last):
  File "E:\Anaconda\envs\en1\lib\site-packages\django\core\handlers\exception.py", line 35, in inner
    response = get_response(request)
  File "E:\Anaconda\envs\en1\lib\site-packages\django\core\handlers\base.py", line 128, in _get_response
    response = self.process_exception_by_middleware(e, request)
  File "E:\Anaconda\envs\en1\lib\site-packages\django\core\handlers\base.py", line 126, in _get_response
    response = wrapped_callback(request, *callback_args, **callback_kwargs)
  File "E:\Anaconda\envs\en1\lib\site-packages\django\views\decorators\csrf.py", line 54, in wrapped_view
    return view_func(*args, **kwargs)
  File "E:\Anaconda\envs\en1\lib\site-packages\django\views\generic\base.py", line 69, in view
    return self.dispatch(request, *args, **kwargs)
  File "E:\Anaconda\envs\en1\lib\site-packages\rest_framework\views.py", line 483, in dispatch
    response = self.handle_exception(exc)
  File "E:\Anaconda\envs\en1\lib\site-packages\rest_framework\views.py", line 443, in handle_exception
    self.raise_uncaught_exception(exc)
  File "E:\Anaconda\envs\en1\lib\site-packages\rest_framework\views.py", line 480, in dispatch
    response = handler(request, *args, **kwargs)
  File "D:\资料\GitHub\TourCommentApiPro\TourCommentApi\TourCommentApi\Views\SpotComparedView.py", line 104, in post
    return post_spot_compard(request);
  File "D:\资料\GitHub\TourCommentApiPro\TourCommentApi\TourCommentApi\Views\SpotComparedView.py", line 76, in post_spot_compard
    time_list = get_time_list(start_time,end_time,time);
  File "D:\资料\GitHub\TourCommentApiPro\TourCommentApi\TourCommentApi\Views\CommonView.py", line 55, in get_time_list
    start_date = int(startTime.split('-')[1]);
IndexError: list index out of range
[2018-10-18 10:41:33,216] [ERROR] "POST /api/spotcompared HTTP/1.1" 500 17057
[2018-10-18 10:41:47,282] [INFO] This is an errormsg
[2018-10-18 10:41:47,285] [INFO] "POST /api/spotcompared HTTP/1.1" 200 47
[2018-10-18 10:42:02,304] [INFO] This is an errormsg
[2018-10-18 10:42:02,308] [INFO] "POST /api/spotcompared HTTP/1.1" 200 47
[2018-10-18 10:43:56,049] [INFO] This is an errormsg
[2018-10-18 10:43:56,056] [INFO] "POST /api/spotcompared HTTP/1.1" 200 47
[2018-10-18 10:46:16,810] [INFO] "POST /api/spotcompared HTTP/1.1" 200 163
[2018-10-18 10:49:24,420] [INFO] "POST /api/spotcompared HTTP/1.1" 200 173
[2018-10-18 10:49:34,413] [INFO] "POST /api/spotcompared HTTP/1.1" 200 1014
[2018-10-18 10:50:03,490] [INFO] "POST /api/spotcompared HTTP/1.1" 200 172
[2018-10-18 10:50:14,956] [INFO] "POST /api/spotcompared HTTP/1.1" 200 175
[2018-10-18 10:50:25,449] [INFO] "POST /api/spotcompared HTTP/1.1" 200 153
[2018-10-18 10:50:38,144] [INFO] "POST /api/spotcompared HTTP/1.1" 200 169
[2018-10-18 10:50:56,849] [INFO] "POST /api/spotcompared HTTP/1.1" 200 229
[2018-10-18 10:51:03,817] [INFO] "POST /api/spotcompared HTTP/1.1" 200 237
[2018-10-18 11:16:32,830] [INFO] This is an errormsg
[2018-10-18 11:16:32,833] [INFO] "POST /api/spotdetailcompared HTTP/1.1" 200 47
[2018-10-18 11:17:24,319] [INFO] This is an errormsg
[2018-10-18 11:17:24,323] [INFO] "POST /api/spotdetailcompared HTTP/1.1" 200 47
[2018-10-18 11:17:44,392] [INFO] "POST /api/spotdetailcompared HTTP/1.1" 200 416
[2018-10-18 11:19:10,781] [INFO] "POST /api/spotdetailcompared HTTP/1.1" 200 416
[2018-10-18 11:20:24,307] [INFO] "POST /api/spotdetailcompared HTTP/1.1" 200 416
[2018-10-18 11:20:37,919] [INFO] "POST /api/spotdetailcompared HTTP/1.1" 200 417
[2018-10-18 11:33:52,287] [ERROR] Internal Server Error: /api/spotdetailcompared
Traceback (most recent call last):
  File "E:\Anaconda\envs\en1\lib\site-packages\django\core\handlers\exception.py", line 35, in inner
    response = get_response(request)
  File "E:\Anaconda\envs\en1\lib\site-packages\django\core\handlers\base.py", line 128, in _get_response
    response = self.process_exception_by_middleware(e, request)
  File "E:\Anaconda\envs\en1\lib\site-packages\django\core\handlers\base.py", line 126, in _get_response
    response = wrapped_callback(request, *callback_args, **callback_kwargs)
  File "E:\Anaconda\envs\en1\lib\site-packages\django\views\decorators\csrf.py", line 54, in wrapped_view
    return view_func(*args, **kwargs)
  File "E:\Anaconda\envs\en1\lib\site-packages\django\views\generic\base.py", line 69, in view
    return self.dispatch(request, *args, **kwargs)
  File "E:\Anaconda\envs\en1\lib\site-packages\rest_framework\views.py", line 483, in dispatch
    response = self.handle_exception(exc)
  File "E:\Anaconda\envs\en1\lib\site-packages\rest_framework\views.py", line 443, in handle_exception
    self.raise_uncaught_exception(exc)
  File "E:\Anaconda\envs\en1\lib\site-packages\rest_framework\views.py", line 480, in dispatch
    response = handler(request, *args, **kwargs)
  File "D:\资料\GitHub\TourCommentApiPro\TourCommentApi\TourCommentApi\Views\SpotDetailComparedView.py", line 92, in post
    return post_spot_detail_compard(request);
  File "D:\资料\GitHub\TourCommentApiPro\TourCommentApi\TourCommentApi\Views\SpotDetailComparedView.py", line 71, in post_spot_detail_compard
    res['yAxis'] = [get_spot_data(spot,time_search_keys[time],compared_time,is_num) for spot in spots];
  File "D:\资料\GitHub\TourCommentApiPro\TourCommentApi\TourCommentApi\Views\SpotDetailComparedView.py", line 71, in <listcomp>
    res['yAxis'] = [get_spot_data(spot,time_search_keys[time],compared_time,is_num) for spot in spots];
  File "D:\资料\GitHub\TourCommentApiPro\TourCommentApi\TourCommentApi\Views\SpotDetailComparedView.py", line 38, in get_spot_data
    spot['data'] = [get_website_data(website, spot, time_search_key,compared_time,is_num) for website in websites];
TypeError: 'str' object does not support item assignment
[2018-10-18 11:33:52,464] [ERROR] "POST /api/spotdetailcompared HTTP/1.1" 500 17504
[2018-10-18 11:35:03,768] [INFO] "POST /api/spotdetailcompared HTTP/1.1" 200 196
[2018-10-18 11:35:52,289] [INFO] "POST /api/spotdetailcompared HTTP/1.1" 200 230
[2018-10-18 13:33:46,970] [INFO] "POST /api/spotdetailcompared HTTP/1.1" 200 243
[2018-10-18 13:34:52,417] [INFO] "POST /api/spotdetailcompared HTTP/1.1" 200 243
[2018-10-18 13:35:10,238] [INFO] "POST /api/spotdetailcompared HTTP/1.1" 200 248
[2018-10-18 13:39:00,115] [ERROR] Internal Server Error: /api/spotdetailcompared
Traceback (most recent call last):
  File "E:\Anaconda\envs\en1\lib\site-packages\django\core\handlers\exception.py", line 35, in inner
    response = get_response(request)
  File "E:\Anaconda\envs\en1\lib\site-packages\django\core\handlers\base.py", line 128, in _get_response
    response = self.process_exception_by_middleware(e, request)
  File "E:\Anaconda\envs\en1\lib\site-packages\django\core\handlers\base.py", line 126, in _get_response
    response = wrapped_callback(request, *callback_args, **callback_kwargs)
  File "E:\Anaconda\envs\en1\lib\site-packages\django\views\decorators\csrf.py", line 54, in wrapped_view
    return view_func(*args, **kwargs)
  File "E:\Anaconda\envs\en1\lib\site-packages\django\views\generic\base.py", line 69, in view
    return self.dispatch(request, *args, **kwargs)
  File "E:\Anaconda\envs\en1\lib\site-packages\rest_framework\views.py", line 483, in dispatch
    response = self.handle_exception(exc)
  File "E:\Anaconda\envs\en1\lib\site-packages\rest_framework\views.py", line 443, in handle_exception
    self.raise_uncaught_exception(exc)
  File "E:\Anaconda\envs\en1\lib\site-packages\rest_framework\views.py", line 480, in dispatch
    response = handler(request, *args, **kwargs)
  File "D:\资料\GitHub\TourCommentApiPro\TourCommentApi\TourCommentApi\Views\SpotDetailComparedView.py", line 95, in post
    return post_spot_detail_compard(request);
  File "D:\资料\GitHub\TourCommentApiPro\TourCommentApi\TourCommentApi\Views\SpotDetailComparedView.py", line 50, in post_spot_detail_compard
    spots = [regioninfo.objects(id = id).search_key];
AttributeError: 'QuerySet' object has no attribute 'search_key'
[2018-10-18 13:39:00,309] [ERROR] "POST /api/spotdetailcompared HTTP/1.1" 500 16995
[2018-10-18 13:39:51,556] [ERROR] Internal Server Error: /api/spotdetailcompared
Traceback (most recent call last):
  File "E:\Anaconda\envs\en1\lib\site-packages\django\core\handlers\exception.py", line 35, in inner
    response = get_response(request)
  File "E:\Anaconda\envs\en1\lib\site-packages\django\core\handlers\base.py", line 128, in _get_response
    response = self.process_exception_by_middleware(e, request)
  File "E:\Anaconda\envs\en1\lib\site-packages\django\core\handlers\base.py", line 126, in _get_response
    response = wrapped_callback(request, *callback_args, **callback_kwargs)
  File "E:\Anaconda\envs\en1\lib\site-packages\django\views\decorators\csrf.py", line 54, in wrapped_view
    return view_func(*args, **kwargs)
  File "E:\Anaconda\envs\en1\lib\site-packages\django\views\generic\base.py", line 69, in view
    return self.dispatch(request, *args, **kwargs)
  File "E:\Anaconda\envs\en1\lib\site-packages\rest_framework\views.py", line 483, in dispatch
    response = self.handle_exception(exc)
  File "E:\Anaconda\envs\en1\lib\site-packages\rest_framework\views.py", line 443, in handle_exception
    self.raise_uncaught_exception(exc)
  File "E:\Anaconda\envs\en1\lib\site-packages\rest_framework\views.py", line 480, in dispatch
    response = handler(request, *args, **kwargs)
  File "D:\资料\GitHub\TourCommentApiPro\TourCommentApi\TourCommentApi\Views\SpotDetailComparedView.py", line 95, in post
    return post_spot_detail_compard(request);
  File "D:\资料\GitHub\TourCommentApiPro\TourCommentApi\TourCommentApi\Views\SpotDetailComparedView.py", line 50, in post_spot_detail_compard
    spots = [(regioninfo.objects(id = id)).search_key];
AttributeError: 'QuerySet' object has no attribute 'search_key'
[2018-10-18 13:39:51,817] [ERROR] "POST /api/spotdetailcompared HTTP/1.1" 500 16997
[2018-10-18 13:40:25,318] [ERROR] Internal Server Error: /api/spotdetailcompared
Traceback (most recent call last):
  File "E:\Anaconda\envs\en1\lib\site-packages\django\core\handlers\exception.py", line 35, in inner
    response = get_response(request)
  File "E:\Anaconda\envs\en1\lib\site-packages\django\core\handlers\base.py", line 128, in _get_response
    response = self.process_exception_by_middleware(e, request)
  File "E:\Anaconda\envs\en1\lib\site-packages\django\core\handlers\base.py", line 126, in _get_response
    response = wrapped_callback(request, *callback_args, **callback_kwargs)
  File "E:\Anaconda\envs\en1\lib\site-packages\django\views\decorators\csrf.py", line 54, in wrapped_view
    return view_func(*args, **kwargs)
  File "E:\Anaconda\envs\en1\lib\site-packages\django\views\generic\base.py", line 69, in view
    return self.dispatch(request, *args, **kwargs)
  File "E:\Anaconda\envs\en1\lib\site-packages\rest_framework\views.py", line 483, in dispatch
    response = self.handle_exception(exc)
  File "E:\Anaconda\envs\en1\lib\site-packages\rest_framework\views.py", line 443, in handle_exception
    self.raise_uncaught_exception(exc)
  File "E:\Anaconda\envs\en1\lib\site-packages\rest_framework\views.py", line 480, in dispatch
    response = handler(request, *args, **kwargs)
  File "D:\资料\GitHub\TourCommentApiPro\TourCommentApi\TourCommentApi\Views\SpotDetailComparedView.py", line 95, in post
    return post_spot_detail_compard(request);
  File "D:\资料\GitHub\TourCommentApiPro\TourCommentApi\TourCommentApi\Views\SpotDetailComparedView.py", line 50, in post_spot_detail_compard
    spots = [(regioninfo.objects(id = id)).get('search_key')];
  File "E:\Anaconda\envs\en1\lib\site-packages\mongoengine\queryset\base.py", line 269, in get
    queryset = queryset.filter(*q_objs, **query)
  File "E:\Anaconda\envs\en1\lib\site-packages\mongoengine\queryset\base.py", line 229, in filter
    return self.__call__(*q_objs, **query)
  File "E:\Anaconda\envs\en1\lib\site-packages\mongoengine\queryset\base.py", line 111, in __call__
    raise InvalidQueryError(msg)
mongoengine.errors.InvalidQueryError: Not a query object: search_key. Did you intend to use key=value?
[2018-10-18 13:40:25,663] [ERROR] "POST /api/spotdetailcompared HTTP/1.1" 500 17467
[2018-10-18 13:41:22,513] [ERROR] Internal Server Error: /api/spotdetailcompared
Traceback (most recent call last):
  File "E:\Anaconda\envs\en1\lib\site-packages\mongoengine\queryset\base.py", line 272, in get
    result = next(queryset)
  File "E:\Anaconda\envs\en1\lib\site-packages\mongoengine\queryset\base.py", line 1486, in __next__
    raw_doc = next(self._cursor)
  File "E:\Anaconda\envs\en1\lib\site-packages\pymongo\cursor.py", line 1121, in next
    raise StopIteration
StopIteration

During handling of the above exception, another exception occurred:

Traceback (most recent call last):
  File "E:\Anaconda\envs\en1\lib\site-packages\django\core\handlers\exception.py", line 35, in inner
    response = get_response(request)
  File "E:\Anaconda\envs\en1\lib\site-packages\django\core\handlers\base.py", line 128, in _get_response
    response = self.process_exception_by_middleware(e, request)
  File "E:\Anaconda\envs\en1\lib\site-packages\django\core\handlers\base.py", line 126, in _get_response
    response = wrapped_callback(request, *callback_args, **callback_kwargs)
  File "E:\Anaconda\envs\en1\lib\site-packages\django\views\decorators\csrf.py", line 54, in wrapped_view
    return view_func(*args, **kwargs)
  File "E:\Anaconda\envs\en1\lib\site-packages\django\views\generic\base.py", line 69, in view
    return self.dispatch(request, *args, **kwargs)
  File "E:\Anaconda\envs\en1\lib\site-packages\rest_framework\views.py", line 483, in dispatch
    response = self.handle_exception(exc)
  File "E:\Anaconda\envs\en1\lib\site-packages\rest_framework\views.py", line 443, in handle_exception
    self.raise_uncaught_exception(exc)
  File "E:\Anaconda\envs\en1\lib\site-packages\rest_framework\views.py", line 480, in dispatch
    response = handler(request, *args, **kwargs)
  File "D:\资料\GitHub\TourCommentApiPro\TourCommentApi\TourCommentApi\Views\SpotDetailComparedView.py", line 95, in post
    return post_spot_detail_compard(request);
  File "D:\资料\GitHub\TourCommentApiPro\TourCommentApi\TourCommentApi\Views\SpotDetailComparedView.py", line 50, in post_spot_detail_compard
    spots = [(regioninfo.objects.get(id = id)).search_key];
  File "E:\Anaconda\envs\en1\lib\site-packages\mongoengine\queryset\base.py", line 276, in get
    raise queryset._document.DoesNotExist(msg)
TourCommentApi.Models.RegionInfoModel.DoesNotExist: regioninfo matching query does not exist.
[2018-10-18 13:41:23,091] [ERROR] "POST /api/spotdetailcompared HTTP/1.1" 500 17573
[2018-10-18 13:42:04,358] [ERROR] Internal Server Error: /api/spotdetailcompared
Traceback (most recent call last):
  File "E:\Anaconda\envs\en1\lib\site-packages\mongoengine\queryset\base.py", line 272, in get
    result = next(queryset)
  File "E:\Anaconda\envs\en1\lib\site-packages\mongoengine\queryset\base.py", line 1486, in __next__
    raw_doc = next(self._cursor)
  File "E:\Anaconda\envs\en1\lib\site-packages\pymongo\cursor.py", line 1121, in next
    raise StopIteration
StopIteration

During handling of the above exception, another exception occurred:

Traceback (most recent call last):
  File "E:\Anaconda\envs\en1\lib\site-packages\django\core\handlers\exception.py", line 35, in inner
    response = get_response(request)
  File "E:\Anaconda\envs\en1\lib\site-packages\django\core\handlers\base.py", line 128, in _get_response
    response = self.process_exception_by_middleware(e, request)
  File "E:\Anaconda\envs\en1\lib\site-packages\django\core\handlers\base.py", line 126, in _get_response
    response = wrapped_callback(request, *callback_args, **callback_kwargs)
  File "E:\Anaconda\envs\en1\lib\site-packages\django\views\decorators\csrf.py", line 54, in wrapped_view
    return view_func(*args, **kwargs)
  File "E:\Anaconda\envs\en1\lib\site-packages\django\views\generic\base.py", line 69, in view
    return self.dispatch(request, *args, **kwargs)
  File "E:\Anaconda\envs\en1\lib\site-packages\rest_framework\views.py", line 483, in dispatch
    response = self.handle_exception(exc)
  File "E:\Anaconda\envs\en1\lib\site-packages\rest_framework\views.py", line 443, in handle_exception
    self.raise_uncaught_exception(exc)
  File "E:\Anaconda\envs\en1\lib\site-packages\rest_framework\views.py", line 480, in dispatch
    response = handler(request, *args, **kwargs)
  File "D:\资料\GitHub\TourCommentApiPro\TourCommentApi\TourCommentApi\Views\SpotDetailComparedView.py", line 95, in post
  File "D:\资料\GitHub\TourCommentApiPro\TourCommentApi\TourCommentApi\Views\SpotDetailComparedView.py", line 50, in post_spot_detail_compard
    #从数据库中抽取
  File "E:\Anaconda\envs\en1\lib\site-packages\mongoengine\queryset\base.py", line 276, in get
    raise queryset._document.DoesNotExist(msg)
TourCommentApi.Models.RegionInfoModel.DoesNotExist: regioninfo matching query does not exist.
[2018-10-18 13:42:04,584] [ERROR] "POST /api/spotdetailcompared HTTP/1.1" 500 17482
[2018-10-18 13:43:05,433] [INFO] "POST /api/spotdetailcompared HTTP/1.1" 200 230
[2018-10-18 13:48:36,618] [INFO] "POST /api/spotdetailcompared HTTP/1.1" 200 255
[2018-10-18 13:49:19,355] [INFO] "POST /api/spotdetailcompared HTTP/1.1" 200 197
[2018-10-18 13:49:33,765] [INFO] "POST /api/spotdetailcompared HTTP/1.1" 200 248
[2018-10-18 13:49:57,617] [INFO] "POST /api/spotdetailcompared HTTP/1.1" 200 243
[2018-10-18 13:50:18,562] [INFO] "POST /api/spotdetailcompared HTTP/1.1" 200 243
[2018-10-18 13:53:54,605] [ERROR] Internal Server Error: /api/spotdetail/1
Traceback (most recent call last):
  File "E:\Anaconda\envs\en1\lib\site-packages\django\core\handlers\exception.py", line 35, in inner
    response = get_response(request)
  File "E:\Anaconda\envs\en1\lib\site-packages\django\core\handlers\base.py", line 128, in _get_response
    response = self.process_exception_by_middleware(e, request)
  File "E:\Anaconda\envs\en1\lib\site-packages\django\core\handlers\base.py", line 126, in _get_response
    response = wrapped_callback(request, *callback_args, **callback_kwargs)
  File "E:\Anaconda\envs\en1\lib\site-packages\django\views\decorators\csrf.py", line 54, in wrapped_view
    return view_func(*args, **kwargs)
  File "E:\Anaconda\envs\en1\lib\site-packages\django\views\generic\base.py", line 69, in view
    return self.dispatch(request, *args, **kwargs)
  File "E:\Anaconda\envs\en1\lib\site-packages\rest_framework\views.py", line 483, in dispatch
    response = self.handle_exception(exc)
  File "E:\Anaconda\envs\en1\lib\site-packages\rest_framework\views.py", line 443, in handle_exception
    self.raise_uncaught_exception(exc)
  File "E:\Anaconda\envs\en1\lib\site-packages\rest_framework\views.py", line 480, in dispatch
    response = handler(request, *args, **kwargs)
  File "D:\资料\GitHub\TourCommentApiPro\TourCommentApi\TourCommentApi\Views\SpotDetailView.py", line 85, in get
    return get_spot_detail(request,id);
  File "D:\资料\GitHub\TourCommentApiPro\TourCommentApi\TourCommentApi\Views\SpotDetailView.py", line 18, in get_spot_detail
    if(datetime.datetime.now() < 6):
TypeError: '<' not supported between instances of 'datetime.datetime' and 'int'
[2018-10-18 13:53:55,173] [ERROR] "GET /api/spotdetail/1 HTTP/1.1" 500 94833
[2018-10-18 13:53:56,646] [WARNING] Not Found: /favicon.ico
[2018-10-18 13:53:56,648] [WARNING] "GET /favicon.ico HTTP/1.1" 404 3035
[2018-10-18 13:56:56,628] [ERROR] Internal Server Error: /api/spotdetail/1
Traceback (most recent call last):
  File "E:\Anaconda\envs\en1\lib\site-packages\django\core\handlers\exception.py", line 35, in inner
    response = get_response(request)
  File "E:\Anaconda\envs\en1\lib\site-packages\django\core\handlers\base.py", line 128, in _get_response
    response = self.process_exception_by_middleware(e, request)
  File "E:\Anaconda\envs\en1\lib\site-packages\django\core\handlers\base.py", line 126, in _get_response
    response = wrapped_callback(request, *callback_args, **callback_kwargs)
  File "E:\Anaconda\envs\en1\lib\site-packages\django\views\decorators\csrf.py", line 54, in wrapped_view
    return view_func(*args, **kwargs)
  File "E:\Anaconda\envs\en1\lib\site-packages\django\views\generic\base.py", line 69, in view
    return self.dispatch(request, *args, **kwargs)
  File "E:\Anaconda\envs\en1\lib\site-packages\rest_framework\views.py", line 483, in dispatch
    response = self.handle_exception(exc)
  File "E:\Anaconda\envs\en1\lib\site-packages\rest_framework\views.py", line 443, in handle_exception
    self.raise_uncaught_exception(exc)
  File "E:\Anaconda\envs\en1\lib\site-packages\rest_framework\views.py", line 480, in dispatch
    response = handler(request, *args, **kwargs)
  File "D:\资料\GitHub\TourCommentApiPro\TourCommentApi\TourCommentApi\Views\SpotDetailView.py", line 85, in get
    return get_spot_detail(request,id);
  File "D:\资料\GitHub\TourCommentApiPro\TourCommentApi\TourCommentApi\Views\SpotDetailView.py", line 18, in get_spot_detail
    if(int(datetime.datetime.now()) < 6):
TypeError: int() argument must be a string, a bytes-like object or a number, not 'datetime.datetime'
[2018-10-18 13:56:57,172] [ERROR] "GET /api/spotdetail/1 HTTP/1.1" 500 94988
[2018-10-18 14:03:36,643] [INFO] "GET /api/spotdetail/1 HTTP/1.1" 200 434
[2018-02-18 14:04:14,411] [ERROR] Internal Server Error: /api/spotdetail/1
Traceback (most recent call last):
  File "E:\Anaconda\envs\en1\lib\site-packages\django\core\handlers\exception.py", line 35, in inner
    response = get_response(request)
  File "E:\Anaconda\envs\en1\lib\site-packages\django\core\handlers\base.py", line 128, in _get_response
    response = self.process_exception_by_middleware(e, request)
  File "E:\Anaconda\envs\en1\lib\site-packages\django\core\handlers\base.py", line 126, in _get_response
    response = wrapped_callback(request, *callback_args, **callback_kwargs)
  File "E:\Anaconda\envs\en1\lib\site-packages\django\views\decorators\csrf.py", line 54, in wrapped_view
    return view_func(*args, **kwargs)
  File "E:\Anaconda\envs\en1\lib\site-packages\django\views\generic\base.py", line 69, in view
    return self.dispatch(request, *args, **kwargs)
  File "E:\Anaconda\envs\en1\lib\site-packages\rest_framework\views.py", line 483, in dispatch
    response = self.handle_exception(exc)
  File "E:\Anaconda\envs\en1\lib\site-packages\rest_framework\views.py", line 443, in handle_exception
    self.raise_uncaught_exception(exc)
  File "E:\Anaconda\envs\en1\lib\site-packages\rest_framework\views.py", line 480, in dispatch
    response = handler(request, *args, **kwargs)
  File "D:\资料\GitHub\TourCommentApiPro\TourCommentApi\TourCommentApi\Views\SpotDetailView.py", line 85, in get
    return get_spot_detail(request,id);
  File "D:\资料\GitHub\TourCommentApiPro\TourCommentApi\TourCommentApi\Views\SpotDetailView.py", line 20, in get_spot_detail
    now_date = str(datetime.datetime.now().year)  + ('-') + str(((datetime.datetime.now().isocalendar())[1]).zfill(2));
AttributeError: 'int' object has no attribute 'zfill'
[2018-02-18 14:04:14,833] [ERROR] "GET /api/spotdetail/1 HTTP/1.1" 500 94976
[2018-02-18 14:10:08,949] [INFO] "GET /api/spotdetail/1 HTTP/1.1" 200 371
[2018-02-18 14:11:02,225] [INFO] "GET /api/spotdetail/2 HTTP/1.1" 200 488
[2018-02-18 14:11:17,312] [INFO] "GET /api/spotlist HTTP/1.1" 200 3193
[2018-02-18 14:14:42,420] [INFO] "GET /api/spotdetail/2 HTTP/1.1" 200 488
[2018-02-18 14:24:36,973] [INFO] "GET /api/spotdetail/2 HTTP/1.1" 200 488
[2018-06-18 14:28:02,613] [INFO] "GET /api/spotdetail/2 HTTP/1.1" 200 468
[2018-06-18 14:44:07,515] [INFO] "GET /api/spotdetail/5 HTTP/1.1" 200 468
[2018-06-18 14:44:42,441] [INFO] "GET /api/spotdetail/17 HTTP/1.1" 200 468
[2018-06-18 14:45:09,114] [INFO] "GET /api/spotdetail/18 HTTP/1.1" 200 466
[2018-06-18 14:47:32,430] [INFO] "GET /api/spotdetail/18 HTTP/1.1" 200 466
[2018-06-18 14:57:21,485] [INFO] "GET /api/spotdetail/18 HTTP/1.1" 200 487
[2018-06-18 14:57:37,135] [INFO] "GET /api/spotdetail/1 HTTP/1.1" 200 362
[2018-05-31 14:59:46,908] [INFO] "GET /api/spotdetail/1 HTTP/1.1" 200 644
[2018-05-31 15:00:32,625] [INFO] "GET /api/spotdetail/1 HTTP/1.1" 200 644
[2018-05-31 15:00:50,784] [INFO] "GET /api/spotdetail/2 HTTP/1.1" 200 878
[2018-05-31 15:11:08,049] [INFO] "GET /api/spotdetail/2 HTTP/1.1" 200 1670
[2018-05-31 15:18:15,146] [INFO] "GET /api/spotdetail/2 HTTP/1.1" 200 878
[2018-05-31 15:24:06,165] [ERROR] Internal Server Error: /api/spotdetail/2
Traceback (most recent call last):
  File "E:\Anaconda\envs\en1\lib\site-packages\django\core\handlers\exception.py", line 35, in inner
    response = get_response(request)
  File "E:\Anaconda\envs\en1\lib\site-packages\django\core\handlers\base.py", line 128, in _get_response
    response = self.process_exception_by_middleware(e, request)
  File "E:\Anaconda\envs\en1\lib\site-packages\django\core\handlers\base.py", line 126, in _get_response
    response = wrapped_callback(request, *callback_args, **callback_kwargs)
  File "E:\Anaconda\envs\en1\lib\site-packages\django\views\decorators\csrf.py", line 54, in wrapped_view
    return view_func(*args, **kwargs)
  File "E:\Anaconda\envs\en1\lib\site-packages\django\views\generic\base.py", line 69, in view
    return self.dispatch(request, *args, **kwargs)
  File "E:\Anaconda\envs\en1\lib\site-packages\rest_framework\views.py", line 483, in dispatch
    response = self.handle_exception(exc)
  File "E:\Anaconda\envs\en1\lib\site-packages\rest_framework\views.py", line 443, in handle_exception
    self.raise_uncaught_exception(exc)
  File "E:\Anaconda\envs\en1\lib\site-packages\rest_framework\views.py", line 480, in dispatch
    response = handler(request, *args, **kwargs)
  File "D:\资料\GitHub\TourCommentApiPro\TourCommentApi\TourCommentApi\Views\SpotDetailView.py", line 85, in get
    return get_spot_detail(request,id);
  File "D:\资料\GitHub\TourCommentApiPro\TourCommentApi\TourCommentApi\Views\SpotDetailView.py", line 18, in get_spot_detail
    if(datetime.datetime.now() < 4):
TypeError: '<' not supported between instances of 'datetime.datetime' and 'int'
[2018-05-31 15:24:07,245] [ERROR] "GET /api/spotdetail/2 HTTP/1.1" 500 95036
[2018-05-31 15:26:41,813] [INFO] "GET /api/spotdetail/2 HTTP/1.1" 200 442
[2018-03-31 15:27:19,708] [INFO] "GET /api/spotdetail/2 HTTP/1.1" 200 640
[2018-04-01 15:27:57,951] [INFO] "GET /api/spotdetail/2 HTTP/1.1" 200 414
[2018-12-01 15:28:26,241] [INFO] "GET /api/spotdetail/2 HTTP/1.1" 200 628
[2018-12-31 15:31:15,560] [INFO] "GET /api/spotdetail/2 HTTP/1.1" 200 625
[2018-12-31 15:31:30,281] [INFO] "GET /api/spotdetail/18 HTTP/1.1" 200 637
[2018-12-31 15:35:53,760] [INFO] "GET /api/spotdetail/18 HTTP/1.1" 200 625
[2018-12-31 15:36:22,623] [INFO] "GET /api/spotdetail/17 HTTP/1.1" 200 630
[2018-03-31 15:38:49,196] [INFO] "GET /api/spotdetail/7 HTTP/1.1" 200 636
[2018-03-31 15:39:17,334] [INFO] "GET /api/spotdetail/12 HTTP/1.1" 200 631
[2018-12-30 15:40:00,081] [INFO] "GET /api/spotdetail/14 HTTP/1.1" 200 589
[2018-12-30 15:40:37,248] [INFO] "GET /api/spotdetail/2 HTTP/1.1" 200 613
[2018-12-30 15:41:00,301] [INFO] "GET /api/spotdetail/3 HTTP/1.1" 200 603
[2018-12-30 15:57:53,308] [INFO] "POST /api/spotdetailcompared HTTP/1.1" 200 230
[2018-12-30 15:59:08,955] [INFO] "GET /api/spotdetail/3 HTTP/1.1" 200 625
[2018-12-30 16:02:24,979] [INFO] "POST /api/login HTTP/1.1" 200 223
[2018-12-30 16:03:23,122] [INFO] "GET /api/spotlist HTTP/1.1" 200 3193
[2018-12-30 16:03:52,983] [INFO] "GET /api/qdhspotlist HTTP/1.1" 200 3651
[2018-12-30 16:04:28,023] [INFO] "GET /api/qdhstate HTTP/1.1" 200 95
[2018-12-30 16:05:56,064] [INFO] This is an errormsg
[2018-12-30 16:05:56,102] [INFO] "POST /api/spotcompared HTTP/1.1" 200 47
[2018-12-30 16:06:29,425] [INFO] This is an errormsg
[2018-12-30 16:06:29,449] [INFO] "POST /api/spotcompared HTTP/1.1" 200 47
[2018-12-30 16:07:03,089] [INFO] This is an errormsg
[2018-12-30 16:07:03,105] [INFO] "POST /api/spotcompared HTTP/1.1" 200 47
[2018-12-30 16:07:36,418] [INFO] This is an errormsg
[2018-12-30 16:07:36,447] [INFO] "POST /api/spotcompared HTTP/1.1" 200 47
[2018-12-30 16:08:35,444] [INFO] "POST /api/spotcompared HTTP/1.1" 200 214
[2018-12-30 16:13:25,832] [INFO] "GET /api/qdhstate HTTP/1.1" 200 92
[2018-12-30 16:13:39,536] [ERROR] Internal Server Error: /api/spotcompared
Traceback (most recent call last):
  File "E:\Anaconda\envs\en1\lib\site-packages\django\core\handlers\exception.py", line 35, in inner
    response = get_response(request)
  File "E:\Anaconda\envs\en1\lib\site-packages\django\core\handlers\base.py", line 128, in _get_response
    response = self.process_exception_by_middleware(e, request)
  File "E:\Anaconda\envs\en1\lib\site-packages\django\core\handlers\base.py", line 126, in _get_response
    response = wrapped_callback(request, *callback_args, **callback_kwargs)
  File "E:\Anaconda\envs\en1\lib\site-packages\django\views\decorators\csrf.py", line 54, in wrapped_view
    return view_func(*args, **kwargs)
  File "E:\Anaconda\envs\en1\lib\site-packages\django\views\generic\base.py", line 69, in view
    return self.dispatch(request, *args, **kwargs)
  File "E:\Anaconda\envs\en1\lib\site-packages\rest_framework\views.py", line 483, in dispatch
    response = self.handle_exception(exc)
  File "E:\Anaconda\envs\en1\lib\site-packages\rest_framework\views.py", line 443, in handle_exception
    self.raise_uncaught_exception(exc)
  File "E:\Anaconda\envs\en1\lib\site-packages\rest_framework\views.py", line 480, in dispatch
    response = handler(request, *args, **kwargs)
  File "D:\资料\GitHub\TourCommentApiPro\TourCommentApi\TourCommentApi\Views\SpotComparedView.py", line 102, in post
    return post_spot_compard(request);
  File "D:\资料\GitHub\TourCommentApiPro\TourCommentApi\TourCommentApi\Views\SpotComparedView.py", line 75, in post_spot_compard
    time_list = get_time_list(start_time,end_time,time);
  File "D:\资料\GitHub\TourCommentApiPro\TourCommentApi\TourCommentApi\Views\CommonView.py", line 57, in get_time_list
    end_date = int(endTime.split('-')[1]);
IndexError: list index out of range
[2018-12-30 16:13:40,036] [ERROR] "POST /api/spotcompared HTTP/1.1" 500 17053
[2018-12-30 16:15:10,305] [INFO] "POST /api/spotcompared HTTP/1.1" 200 48414
[2018-12-30 16:15:23,193] [INFO] "POST /api/spotcompared HTTP/1.1" 200 18685
[2018-12-30 16:16:24,204] [WARNING] Not Found: /spotdetail/2
[2018-12-30 16:16:24,223] [WARNING] "GET /spotdetail/2 HTTP/1.1" 404 3038
[2018-12-30 16:16:46,920] [INFO] "GET /api/spotdetail/2 HTTP/1.1" 200 635
[2018-12-30 16:17:18,249] [INFO] "GET /api/spotdetail/17 HTTP/1.1" 200 652
[2018-12-30 16:17:46,968] [INFO] "GET /api/spotdetail/18 HTTP/1.1" 200 647
[2018-12-30 16:19:20,130] [INFO] "POST /api/spotdetailcompared HTTP/1.1" 200 240
[2018-12-30 16:20:04,190] [INFO] "GET /api/spotdetail/1 HTTP/1.1" 200 483
[2018-12-30 16:20:17,480] [INFO] "POST /api/spotdetailcompared HTTP/1.1" 200 184
[2018-10-18 18:55:04,629] [INFO] "GET /admin/ HTTP/1.1" 302 0
[2018-10-18 18:55:05,515] [INFO] "GET /admin/login/?next=/admin/ HTTP/1.1" 200 1859
[2018-10-18 18:55:05,821] [INFO] "GET /static/admin/css/base.css HTTP/1.1" 200 16106
[2018-10-18 18:55:06,039] [INFO] "GET /static/admin/css/login.css HTTP/1.1" 200 1203
[2018-10-18 18:55:06,047] [INFO] "GET /static/admin/css/responsive.css HTTP/1.1" 200 17894
[2018-10-18 18:55:06,171] [INFO] "GET /static/admin/css/fonts.css HTTP/1.1" 200 423
[2018-10-18 18:55:06,411] [INFO] "GET /static/admin/fonts/Roboto-Regular-webfont.woff HTTP/1.1" 200 80304
[2018-10-18 18:55:06,411] [INFO] "GET /static/admin/fonts/Roboto-Light-webfont.woff HTTP/1.1" 200 81348
[2018-10-18 18:55:11,752] [INFO] "POST /admin/login/?next=/admin/ HTTP/1.1" 302 0
[2018-10-18 18:55:11,886] [INFO] "GET /admin/ HTTP/1.1" 200 5340
[2018-10-18 18:55:11,965] [INFO] "GET /static/admin/css/dashboard.css HTTP/1.1" 200 412
[2018-10-18 18:55:12,399] [INFO] "GET /static/admin/img/icon-changelink.svg HTTP/1.1" 200 380
[2018-10-18 18:55:12,400] [INFO] "GET /static/admin/fonts/Roboto-Bold-webfont.woff HTTP/1.1" 200 82564
[2018-10-18 18:55:12,442] [INFO] "GET /static/admin/img/icon-addlink.svg HTTP/1.1" 200 331
[2018-10-18 18:55:22,256] [ERROR] Internal Server Error: /admin/djcelery/periodictask/add/
Traceback (most recent call last):
  File "E:\Anaconda\envs\en1\lib\site-packages\django\db\backends\utils.py", line 85, in _execute
    return self.cursor.execute(sql, params)
  File "E:\Anaconda\envs\en1\lib\site-packages\django\db\backends\sqlite3\base.py", line 303, in execute
    return Database.Cursor.execute(self, query, params)
sqlite3.OperationalError: no such table: djcelery_intervalschedule

The above exception was the direct cause of the following exception:

Traceback (most recent call last):
  File "E:\Anaconda\envs\en1\lib\site-packages\django\core\handlers\exception.py", line 35, in inner
    response = get_response(request)
  File "E:\Anaconda\envs\en1\lib\site-packages\django\core\handlers\base.py", line 158, in _get_response
    response = self.process_exception_by_middleware(e, request)
  File "E:\Anaconda\envs\en1\lib\site-packages\django\core\handlers\base.py", line 156, in _get_response
    response = response.render()
  File "E:\Anaconda\envs\en1\lib\site-packages\django\template\response.py", line 106, in render
    self.content = self.rendered_content
  File "E:\Anaconda\envs\en1\lib\site-packages\django\template\response.py", line 83, in rendered_content
    content = template.render(context, self._request)
  File "E:\Anaconda\envs\en1\lib\site-packages\django\template\backends\django.py", line 61, in render
    return self.template.render(context)
  File "E:\Anaconda\envs\en1\lib\site-packages\django\template\base.py", line 175, in render
    return self._render(context)
  File "E:\Anaconda\envs\en1\lib\site-packages\django\template\base.py", line 167, in _render
    return self.nodelist.render(context)
  File "E:\Anaconda\envs\en1\lib\site-packages\django\template\base.py", line 943, in render
    bit = node.render_annotated(context)
  File "E:\Anaconda\envs\en1\lib\site-packages\django\template\base.py", line 910, in render_annotated
    return self.render(context)
  File "E:\Anaconda\envs\en1\lib\site-packages\django\template\loader_tags.py", line 155, in render
    return compiled_parent._render(context)
  File "E:\Anaconda\envs\en1\lib\site-packages\django\template\base.py", line 167, in _render
    return self.nodelist.render(context)
  File "E:\Anaconda\envs\en1\lib\site-packages\django\template\base.py", line 943, in render
    bit = node.render_annotated(context)
  File "E:\Anaconda\envs\en1\lib\site-packages\django\template\base.py", line 910, in render_annotated
    return self.render(context)
  File "E:\Anaconda\envs\en1\lib\site-packages\django\template\loader_tags.py", line 155, in render
    return compiled_parent._render(context)
  File "E:\Anaconda\envs\en1\lib\site-packages\django\template\base.py", line 167, in _render
    return self.nodelist.render(context)
  File "E:\Anaconda\envs\en1\lib\site-packages\django\template\base.py", line 943, in render
    bit = node.render_annotated(context)
  File "E:\Anaconda\envs\en1\lib\site-packages\django\template\base.py", line 910, in render_annotated
    return self.render(context)
  File "E:\Anaconda\envs\en1\lib\site-packages\django\template\loader_tags.py", line 67, in render
    result = block.nodelist.render(context)
  File "E:\Anaconda\envs\en1\lib\site-packages\django\template\base.py", line 943, in render
    bit = node.render_annotated(context)
  File "E:\Anaconda\envs\en1\lib\site-packages\django\template\base.py", line 910, in render_annotated
    return self.render(context)
  File "E:\Anaconda\envs\en1\lib\site-packages\django\template\loader_tags.py", line 67, in render
    result = block.nodelist.render(context)
  File "E:\Anaconda\envs\en1\lib\site-packages\django\template\base.py", line 943, in render
    bit = node.render_annotated(context)
  File "E:\Anaconda\envs\en1\lib\site-packages\django\template\base.py", line 910, in render_annotated
    return self.render(context)
  File "E:\Anaconda\envs\en1\lib\site-packages\django\template\defaulttags.py", line 211, in render
    nodelist.append(node.render_annotated(context))
  File "E:\Anaconda\envs\en1\lib\site-packages\django\template\base.py", line 910, in render_annotated
    return self.render(context)
  File "E:\Anaconda\envs\en1\lib\site-packages\django\template\loader_tags.py", line 194, in render
    return template.render(context)
  File "E:\Anaconda\envs\en1\lib\site-packages\django\template\base.py", line 177, in render
    return self._render(context)
  File "E:\Anaconda\envs\en1\lib\site-packages\django\template\base.py", line 167, in _render
    return self.nodelist.render(context)
  File "E:\Anaconda\envs\en1\lib\site-packages\django\template\base.py", line 943, in render
    bit = node.render_annotated(context)
  File "E:\Anaconda\envs\en1\lib\site-packages\django\template\base.py", line 910, in render_annotated
    return self.render(context)
  File "E:\Anaconda\envs\en1\lib\site-packages\django\template\defaulttags.py", line 211, in render
    nodelist.append(node.render_annotated(context))
  File "E:\Anaconda\envs\en1\lib\site-packages\django\template\base.py", line 910, in render_annotated
    return self.render(context)
  File "E:\Anaconda\envs\en1\lib\site-packages\django\template\defaulttags.py", line 211, in render
    nodelist.append(node.render_annotated(context))
  File "E:\Anaconda\envs\en1\lib\site-packages\django\template\base.py", line 910, in render_annotated
    return self.render(context)
  File "E:\Anaconda\envs\en1\lib\site-packages\django\template\defaulttags.py", line 314, in render
    return nodelist.render(context)
  File "E:\Anaconda\envs\en1\lib\site-packages\django\template\base.py", line 943, in render
    bit = node.render_annotated(context)
  File "E:\Anaconda\envs\en1\lib\site-packages\django\template\base.py", line 910, in render_annotated
    return self.render(context)
  File "E:\Anaconda\envs\en1\lib\site-packages\django\template\defaulttags.py", line 314, in render
    return nodelist.render(context)
  File "E:\Anaconda\envs\en1\lib\site-packages\django\template\base.py", line 943, in render
    bit = node.render_annotated(context)
  File "E:\Anaconda\envs\en1\lib\site-packages\django\template\base.py", line 910, in render_annotated
    return self.render(context)
  File "E:\Anaconda\envs\en1\lib\site-packages\django\template\base.py", line 999, in render
    return render_value_in_context(output, context)
  File "E:\Anaconda\envs\en1\lib\site-packages\django\template\base.py", line 978, in render_value_in_context
    value = str(value)
  File "E:\Anaconda\envs\en1\lib\site-packages\django\utils\html.py", line 380, in <lambda>
    klass.__str__ = lambda self: mark_safe(klass_str(self))
  File "E:\Anaconda\envs\en1\lib\site-packages\django\forms\boundfield.py", line 36, in __str__
    return self.as_widget()
  File "E:\Anaconda\envs\en1\lib\site-packages\django\forms\boundfield.py", line 118, in as_widget
    **kwargs
  File "E:\Anaconda\envs\en1\lib\site-packages\django\forms\widgets.py", line 234, in render
    context = self.get_context(name, value, attrs)
  File "E:\Anaconda\envs\en1\lib\site-packages\django\contrib\admin\widgets.py", line 295, in get_context
    'rendered_widget': self.widget.render(name, value, attrs),
  File "E:\Anaconda\envs\en1\lib\site-packages\django\forms\widgets.py", line 234, in render
    context = self.get_context(name, value, attrs)
  File "E:\Anaconda\envs\en1\lib\site-packages\django\forms\widgets.py", line 677, in get_context
    context = super().get_context(name, value, attrs)
  File "E:\Anaconda\envs\en1\lib\site-packages\django\forms\widgets.py", line 637, in get_context
    context['widget']['optgroups'] = self.optgroups(name, context['widget']['value'], attrs)
  File "E:\Anaconda\envs\en1\lib\site-packages\django\forms\widgets.py", line 585, in optgroups
    for index, (option_value, option_label) in enumerate(self.choices):
  File "E:\Anaconda\envs\en1\lib\site-packages\django\forms\models.py", line 1140, in __iter__
    for obj in queryset:
  File "E:\Anaconda\envs\en1\lib\site-packages\django\db\models\query.py", line 336, in _iterator
    yield from self._iterable_class(self, chunked_fetch=use_chunked_fetch, chunk_size=chunk_size)
  File "E:\Anaconda\envs\en1\lib\site-packages\django\db\models\query.py", line 53, in __iter__
    results = compiler.execute_sql(chunked_fetch=self.chunked_fetch, chunk_size=self.chunk_size)
  File "E:\Anaconda\envs\en1\lib\site-packages\django\db\models\sql\compiler.py", line 1066, in execute_sql
    cursor.execute(sql, params)
  File "E:\Anaconda\envs\en1\lib\site-packages\django\db\backends\utils.py", line 100, in execute
    return super().execute(sql, params)
  File "E:\Anaconda\envs\en1\lib\site-packages\django\db\backends\utils.py", line 68, in execute
    return self._execute_with_wrappers(sql, params, many=False, executor=self._execute)
  File "E:\Anaconda\envs\en1\lib\site-packages\django\db\backends\utils.py", line 77, in _execute_with_wrappers
    return executor(sql, params, many, context)
  File "E:\Anaconda\envs\en1\lib\site-packages\django\db\backends\utils.py", line 85, in _execute
    return self.cursor.execute(sql, params)
  File "E:\Anaconda\envs\en1\lib\site-packages\django\db\utils.py", line 89, in __exit__
    raise dj_exc_value.with_traceback(traceback) from exc_value
  File "E:\Anaconda\envs\en1\lib\site-packages\django\db\backends\utils.py", line 85, in _execute
    return self.cursor.execute(sql, params)
  File "E:\Anaconda\envs\en1\lib\site-packages\django\db\backends\sqlite3\base.py", line 303, in execute
    return Database.Cursor.execute(self, query, params)
django.db.utils.OperationalError: no such table: djcelery_intervalschedule
[2018-10-18 18:55:23,922] [ERROR] "GET /admin/djcelery/periodictask/add/ HTTP/1.1" 500 526588
[2018-10-18 19:07:05,669] [INFO] "GET /admin/ HTTP/1.1" 200 2982
[2018-10-18 19:11:25,414] [INFO] "GET /admin/ HTTP/1.1" 200 5336
[2018-10-18 19:11:28,208] [INFO] "GET /admin/djcelery/periodictask/add/ HTTP/1.1" 200 11707
[2018-10-18 19:11:28,368] [INFO] "GET /static/admin/js/jquery.init.js HTTP/1.1" 200 363
[2018-10-18 19:11:28,374] [INFO] "GET /static/admin/css/forms.css HTTP/1.1" 200 8173
[2018-10-18 19:11:28,383] [INFO] "GET /admin/jsi18n/ HTTP/1.1" 200 3185
[2018-10-18 19:11:28,397] [INFO] "GET /static/admin/js/vendor/jquery/jquery.js HTTP/1.1" 200 258648
[2018-10-18 19:11:28,644] [INFO] "GET /static/admin/js/urlify.js HTTP/1.1" 200 8729
[2018-10-18 19:11:28,657] [INFO] "GET /static/admin/css/widgets.css HTTP/1.1" 200 10340
[2018-10-18 19:11:28,806] [INFO] "GET /static/admin/js/prepopulate.js HTTP/1.1" 200 1538
[2018-10-18 19:11:29,046] [INFO] "GET /static/admin/js/vendor/xregexp/xregexp.js HTTP/1.1" 200 128820
[2018-10-18 19:11:29,050] [INFO] "GET /static/admin/js/calendar.js HTTP/1.1" 200 7777
[2018-10-18 19:11:29,071] [INFO] "GET /static/admin/js/admin/DateTimeShortcuts.js HTTP/1.1" 200 20283
[2018-10-18 19:11:29,073] [INFO] "GET /static/admin/js/collapse.js HTTP/1.1" 200 1151
[2018-10-18 19:11:29,082] [INFO] "GET /static/admin/js/core.js HTTP/1.1" 200 7134
[2018-10-18 19:11:29,268] [INFO] "GET /static/admin/js/admin/RelatedObjectLookups.js HTTP/1.1" 200 6897
[2018-10-18 19:11:29,514] [INFO] "GET /static/admin/js/actions.js HTTP/1.1" 200 6502
[2018-10-18 19:11:29,517] [INFO] "GET /static/admin/js/prepopulate_init.js HTTP/1.1" 200 495
[2018-10-18 19:11:29,522] [INFO] "GET /static/admin/js/change_form.js HTTP/1.1" 200 712
[2018-10-18 19:12:33,939] [INFO] "GET /admin/djcelery/intervalschedule/add/?_to_field=id&_popup=1 HTTP/1.1" 200 3812
[2018-10-18 19:12:34,130] [INFO] "GET /admin/jsi18n/ HTTP/1.1" 200 3185
[2018-10-18 19:12:39,594] [INFO] "POST /admin/djcelery/intervalschedule/add/?_to_field=id&_popup=1 HTTP/1.1" 200 3965
[2018-10-18 19:12:39,784] [INFO] "GET /admin/jsi18n/ HTTP/1.1" 200 3185
[2018-10-18 19:12:46,998] [INFO] "POST /admin/djcelery/intervalschedule/add/?_to_field=id&_popup=1 HTTP/1.1" 200 370
[2018-10-18 19:12:47,350] [INFO] "GET /static/admin/js/popup_response.js HTTP/1.1" 200 569
[2018-10-18 19:16:56,035] [INFO] "POST /admin/djcelery/periodictask/add/ HTTP/1.1" 302 0
[2018-10-18 19:16:56,445] [INFO] "GET /admin/djcelery/periodictask/ HTTP/1.1" 200 6365
[2018-10-18 19:16:56,862] [INFO] "GET /static/admin/img/search.svg HTTP/1.1" 200 458
[2018-10-18 19:16:56,887] [INFO] "GET /static/admin/css/changelists.css HTTP/1.1" 200 6170
[2018-10-18 19:16:56,891] [INFO] "GET /static/admin/img/icon-yes.svg HTTP/1.1" 200 436
[2018-10-18 19:16:56,893] [INFO] "GET /admin/jsi18n/ HTTP/1.1" 200 3185
[2018-10-18 19:16:57,233] [INFO] "GET /static/admin/img/sorting-icons.svg HTTP/1.1" 200 1097
[2018-10-18 19:16:57,515] [INFO] "GET /static/admin/img/tooltag-add.svg HTTP/1.1" 200 331
[2018-10-19 16:53:24,540] [INFO] "GET /api/spotlist HTTP/1.1" 200 3193
[2018-10-19 17:05:06,126] [INFO] "GET /api/spotlist HTTP/1.1" 200 3193
[2018-10-19 17:05:38,482] [INFO] "GET /api/spotlist HTTP/1.1" 200 3193
[2018-10-19 17:08:16,511] [INFO] "GET /api/spotlist HTTP/1.1" 200 3193
[2018-10-19 17:10:53,350] [INFO] "GET /api/spotlist HTTP/1.1" 200 3193
[2018-10-19 17:16:30,655] [INFO] "GET /api/spotlist HTTP/1.1" 200 3193
[2018-10-20 10:25:58,889] [INFO] "POST /api/login HTTP/1.1" 200 223
[2018-10-20 10:26:11,567] [ERROR] Internal Server Error: /api/spotlist
Traceback (most recent call last):
  File "E:\Anaconda\envs\en1\lib\site-packages\pandas\core\indexes\base.py", line 3064, in get_loc
    return self._engine.get_loc(key)
  File "pandas/_libs/index.pyx", line 140, in pandas._libs.index.IndexEngine.get_loc
  File "pandas/_libs/index.pyx", line 162, in pandas._libs.index.IndexEngine.get_loc
  File "pandas/_libs/hashtable_class_helper.pxi", line 1492, in pandas._libs.hashtable.PyObjectHashTable.get_item
  File "pandas/_libs/hashtable_class_helper.pxi", line 1500, in pandas._libs.hashtable.PyObjectHashTable.get_item
KeyError: 'search_key'

During handling of the above exception, another exception occurred:

Traceback (most recent call last):
  File "D:\资料\GitHub\TourCommentApiPro\TourCommentApi\TourCommentApi\Views\SpotListView.py", line 27, in get_spot_list
    list = [get_one_spot(region) for region in regioninfo.objects];
  File "D:\资料\GitHub\TourCommentApiPro\TourCommentApi\TourCommentApi\Views\SpotListView.py", line 27, in <listcomp>
    list = [get_one_spot(region) for region in regioninfo.objects];
  File "D:\资料\GitHub\TourCommentApiPro\TourCommentApi\TourCommentApi\Views\SpotListView.py", line 17, in get_one_spot
    spot_comment_data = comments_data[(comments_data['search_key'] == str(region.search_key))]
  File "E:\Anaconda\envs\en1\lib\site-packages\pandas\core\frame.py", line 2688, in __getitem__
    return self._getitem_column(key)
  File "E:\Anaconda\envs\en1\lib\site-packages\pandas\core\frame.py", line 2695, in _getitem_column
    return self._get_item_cache(key)
  File "E:\Anaconda\envs\en1\lib\site-packages\pandas\core\generic.py", line 2486, in _get_item_cache
    values = self._data.get(item)
  File "E:\Anaconda\envs\en1\lib\site-packages\pandas\core\internals.py", line 4115, in get
    loc = self.items.get_loc(item)
  File "E:\Anaconda\envs\en1\lib\site-packages\pandas\core\indexes\base.py", line 3066, in get_loc
    return self._engine.get_loc(self._maybe_cast_indexer(key))
  File "pandas/_libs/index.pyx", line 140, in pandas._libs.index.IndexEngine.get_loc
  File "pandas/_libs/index.pyx", line 162, in pandas._libs.index.IndexEngine.get_loc
  File "pandas/_libs/hashtable_class_helper.pxi", line 1492, in pandas._libs.hashtable.PyObjectHashTable.get_item
  File "pandas/_libs/hashtable_class_helper.pxi", line 1500, in pandas._libs.hashtable.PyObjectHashTable.get_item
KeyError: 'search_key'

During handling of the above exception, another exception occurred:

Traceback (most recent call last):
  File "E:\Anaconda\envs\en1\lib\site-packages\django\core\handlers\exception.py", line 35, in inner
    response = get_response(request)
  File "E:\Anaconda\envs\en1\lib\site-packages\django\core\handlers\base.py", line 128, in _get_response
    response = self.process_exception_by_middleware(e, request)
  File "E:\Anaconda\envs\en1\lib\site-packages\django\core\handlers\base.py", line 126, in _get_response
    response = wrapped_callback(request, *callback_args, **callback_kwargs)
  File "E:\Anaconda\envs\en1\lib\site-packages\django\views\decorators\csrf.py", line 54, in wrapped_view
    return view_func(*args, **kwargs)
  File "E:\Anaconda\envs\en1\lib\site-packages\django\views\generic\base.py", line 69, in view
    return self.dispatch(request, *args, **kwargs)
  File "E:\Anaconda\envs\en1\lib\site-packages\rest_framework\views.py", line 483, in dispatch
    response = self.handle_exception(exc)
  File "E:\Anaconda\envs\en1\lib\site-packages\rest_framework\views.py", line 443, in handle_exception
    self.raise_uncaught_exception(exc)
  File "E:\Anaconda\envs\en1\lib\site-packages\rest_framework\views.py", line 480, in dispatch
    response = handler(request, *args, **kwargs)
  File "D:\资料\GitHub\TourCommentApiPro\TourCommentApi\TourCommentApi\Views\SpotListView.py", line 41, in get
    return get_spot_list(request);
  File "D:\资料\GitHub\TourCommentApiPro\TourCommentApi\TourCommentApi\Views\SpotListView.py", line 32, in get_spot_list
    return json_error(error_string='查询发生错误',code = 11);
  File "D:\资料\GitHub\TourCommentApiPro\TourCommentApi\TourCommentApi\Views\CommonView.py", line 36, in json_error
    logger.info('时间:' + time + ' 错误信息:' + error_string + " code:" + code + "接口为:" + api);
TypeError: must be str, not int
[2018-10-20 10:26:12,812] [ERROR] "GET /api/spotlist HTTP/1.1" 500 19685
[2018-10-20 10:30:24,701] [ERROR] Internal Server Error: /api/spotlist
Traceback (most recent call last):
  File "E:\Anaconda\envs\en1\lib\site-packages\pandas\core\indexes\base.py", line 3064, in get_loc
    return self._engine.get_loc(key)
  File "pandas/_libs/index.pyx", line 140, in pandas._libs.index.IndexEngine.get_loc
  File "pandas/_libs/index.pyx", line 162, in pandas._libs.index.IndexEngine.get_loc
  File "pandas/_libs/hashtable_class_helper.pxi", line 1492, in pandas._libs.hashtable.PyObjectHashTable.get_item
  File "pandas/_libs/hashtable_class_helper.pxi", line 1500, in pandas._libs.hashtable.PyObjectHashTable.get_item
KeyError: 'search_key'

During handling of the above exception, another exception occurred:

Traceback (most recent call last):
  File "D:\资料\GitHub\TourCommentApiPro\TourCommentApi\TourCommentApi\Views\SpotListView.py", line 27, in get_spot_list
    list = [get_one_spot(region) for region in regioninfo.objects];
  File "D:\资料\GitHub\TourCommentApiPro\TourCommentApi\TourCommentApi\Views\SpotListView.py", line 27, in <listcomp>
    list = [get_one_spot(region) for region in regioninfo.objects];
  File "D:\资料\GitHub\TourCommentApiPro\TourCommentApi\TourCommentApi\Views\SpotListView.py", line 17, in get_one_spot
    spot_comment_data = comments_data[(comments_data['search_key'] == str(region.search_key))]
  File "E:\Anaconda\envs\en1\lib\site-packages\pandas\core\frame.py", line 2688, in __getitem__
    return self._getitem_column(key)
  File "E:\Anaconda\envs\en1\lib\site-packages\pandas\core\frame.py", line 2695, in _getitem_column
    return self._get_item_cache(key)
  File "E:\Anaconda\envs\en1\lib\site-packages\pandas\core\generic.py", line 2486, in _get_item_cache
    values = self._data.get(item)
  File "E:\Anaconda\envs\en1\lib\site-packages\pandas\core\internals.py", line 4115, in get
    loc = self.items.get_loc(item)
  File "E:\Anaconda\envs\en1\lib\site-packages\pandas\core\indexes\base.py", line 3066, in get_loc
    return self._engine.get_loc(self._maybe_cast_indexer(key))
  File "pandas/_libs/index.pyx", line 140, in pandas._libs.index.IndexEngine.get_loc
  File "pandas/_libs/index.pyx", line 162, in pandas._libs.index.IndexEngine.get_loc
  File "pandas/_libs/hashtable_class_helper.pxi", line 1492, in pandas._libs.hashtable.PyObjectHashTable.get_item
  File "pandas/_libs/hashtable_class_helper.pxi", line 1500, in pandas._libs.hashtable.PyObjectHashTable.get_item
KeyError: 'search_key'

During handling of the above exception, another exception occurred:

Traceback (most recent call last):
  File "E:\Anaconda\envs\en1\lib\site-packages\django\core\handlers\exception.py", line 35, in inner
    response = get_response(request)
  File "E:\Anaconda\envs\en1\lib\site-packages\django\core\handlers\base.py", line 128, in _get_response
    response = self.process_exception_by_middleware(e, request)
  File "E:\Anaconda\envs\en1\lib\site-packages\django\core\handlers\base.py", line 126, in _get_response
    response = wrapped_callback(request, *callback_args, **callback_kwargs)
  File "E:\Anaconda\envs\en1\lib\site-packages\django\views\decorators\csrf.py", line 54, in wrapped_view
    return view_func(*args, **kwargs)
  File "E:\Anaconda\envs\en1\lib\site-packages\django\views\generic\base.py", line 69, in view
    return self.dispatch(request, *args, **kwargs)
  File "E:\Anaconda\envs\en1\lib\site-packages\rest_framework\views.py", line 483, in dispatch
    response = self.handle_exception(exc)
  File "E:\Anaconda\envs\en1\lib\site-packages\rest_framework\views.py", line 443, in handle_exception
    self.raise_uncaught_exception(exc)
  File "E:\Anaconda\envs\en1\lib\site-packages\rest_framework\views.py", line 480, in dispatch
    response = handler(request, *args, **kwargs)
  File "D:\资料\GitHub\TourCommentApiPro\TourCommentApi\TourCommentApi\Views\SpotListView.py", line 41, in get
    return get_spot_list(request);
  File "D:\资料\GitHub\TourCommentApiPro\TourCommentApi\TourCommentApi\Views\SpotListView.py", line 32, in get_spot_list
    return json_error(error_string='查询发生错误',code = 11);
  File "D:\资料\GitHub\TourCommentApiPro\TourCommentApi\TourCommentApi\Views\CommonView.py", line 36, in json_error
    logger.info('时间:' + str(time) + ' 错误信息:' + error_string + " code:" + code + "接口为:" + api);
TypeError: must be str, not int
[2018-10-20 10:30:25,151] [ERROR] "GET /api/spotlist HTTP/1.1" 500 19690
[2018-10-20 10:33:00,104] [INFO] 时间:2018-10-20 10:33:00 错误信息:查询发生错误 code:11接口为:
[2018-10-20 10:33:00,111] [INFO] "GET /api/spotlist HTTP/1.1" 200 52
[2018-10-20 10:47:50,239] [INFO] 时间:2018-10-20 10:47:50 错误信息:查询发生错误 code:11接口为:spotlist
[2018-10-20 10:47:50,242] [INFO] "GET /api/spotlist HTTP/1.1" 200 52
[2018-10-20 10:53:39,804] [INFO] 时间:2018-10-20 10:53:39 错误信息:查询发生错误 code:11接口为:spotlist
[2018-10-20 10:53:39,808] [INFO] "GET /api/spotlist HTTP/1.1" 200 52
[2018-10-20 10:58:08,643] [INFO] "GET /api/spotlist HTTP/1.1" 200 3193
[2018-10-20 10:59:18,658] [INFO] "POST /api/spotcompared HTTP/1.1" 200 18685
[2018-10-20 10:59:51,354] [INFO] "GET /api/spotdetail/17 HTTP/1.1" 200 615
[2018-10-20 11:00:15,581] [INFO] "POST /api/spotdetailcompared HTTP/1.1" 200 184
